Workbook
Name ListaRob: #REF!

Sheet Wybór
A1: Wybierz beneficjenta wsparcia
A2: Wybierz rodzaj przedsięwzięcia
A3: Wybierz Inwestora innego niż beneficjent wsparcia****
A4: Rodzaj zasobu | B4: Rodzaj przedsięwzięcia***
A7: Lokale Mieszkalne na Wynajem - art. 5, Lokale mieszkalne z prawem do podnajmowania art. 5a | B7: Budowa budynku
B8: Remont lub przebudowa budynku
B9: Remont lub przebudowa budynku SAN
A10: Lokale Mieszkalne stanowiące mieszkaniowy zasób gminy * art. 3 | B10: Budowa budynku
B11: Kupno lub kupno połączone z remontem
B12: Remont lub przebudowa budynku mieszkalnego
B13: Remont lub przebudowa budynku niemieszkalnego
B14: Zmiana sposobu użytkowania budynku
B15: Remont lub przebudowa lokalu mieszkalnego z premią MZG
A16: * | B16: Budowa budynku
B17: Remont lub przebudowa budynku
A18: Mieszkania Chronione * art. 3 oraz art. 6 | B18: Budowa budynku
B19: Kupno lub kupno połączone z remontem
B20: Remont lub przebudowa budynku mieszkalnego
B21: Remont lub przebudowa budynku niemieszkalnego
B22: Zmiana sposobu użytkowania budynku
B23: Remont lub przebudowa lokalu mieszkalnego z premią MZG
A24: Mieszkania chronione z prawem do podnajmowania art. 5a w związku z art. 6 * | B24: Budowa budynku
B25: Remont lub przebudowa budynku niemieszkalnego lub mieszkalnego
A26: Mieszkania (Powódź) | B26: Budowa budynku
B27: Kupno lub kupno połączone z remontem
B28: Remont lub przebudowa budynku niemieszkalnego lub mieszkalnego
B29: Zmiana sposobu użytkowania budynku
B30: Remont lub przebudowa lokalu mieszkalnego
A31: Ogrzewalnie art. 4 * | B31: Remont lub przebudowa budynku niemieszkalnego lub mieszkalnego
B32: Zmiana sposobu użytkowania budynku
B33: Budowa budynku **
A34: Pomieszczenia tymczasowe art. 3 * | B34: Zmiana sposobu użytkowania budynku
A35: Mieszkania Zakładowe art. 3 | B35: Kupno lub kupno połączone z remontem
A36: Dostosowanie Standardów Noclegowni art. 4 | B36: Remont lub przebudowa istniejącej noclegowni
A37: Dostosowanie Standardów Schronisk dla bezdomnych art. 4 | B37: Remont lub przebudowa istniejącego schroniska dla bezdomnych
A38: Dostosowanie Standardów Ogrzewalni art. 4 | B38: Remont lub przebudowa istniejącej ogrzewalni
A39: Noclegownie art. 4 * | B39: Budowa budynku
B40: Remont lub przebudowa budynku niemieszkalnego lub mieszkalnego
B41: Zmiana sposobu użytkowania budynku
A42: Schroniska dla bezdomnych art. 4* | B42: Budowa budynku
...

Sheet Rozliczenie art. 3 i art. 4
A1: Proszę wybierz odpowiedni arkusz i wypełnij niebieskie pola. Zadbaj o jakość wprowadzanych danych.
A2: Żółte pola wypełnią się automatycznie, na podstawie wprowadzonych wartości. | AM2: Uwagi, komentarze przydatne przy wypełnianiu formularza
A3: Wprowadzone nieprawidłowe wartości w niebieskie pola mogą spowodować niepoprawne wyliczenia.
H5: =TODAY() -> 46058
A6: miejscowość | H6: data
A9: FORMULARZ, NA KTÓRYM DOKONUJE SIĘ ROZLICZENIA FAKTYCZNIE PONIESIONYCH KOSZTÓW PRZEDSIĘWZIĘCIA, Z WYŁĄCZENIEM PRZEDSIĘWZIĘCIA, O KTÓRYM MOWA W ART. 5C USTAWY Z DNIA 8 GRUDNIA 2006 R. O FINANSOWYM WSPARCIU NIEKTÓRYCH PRZEDSIĘWZIĘĆ MIESZKANIOWYCH (DZ. U. Z 2024 R. POZ. 304), ZWANEJ DALEJ „USTAWĄ
A10: 1. Wnioskodawca
A11: 2. Numer umowy:
A12: 2a. Numer aneksu podwyższającego wysokość wsparcia lub data złożenia wniosku o aneks podwyższający wsparcie
A13: 15. Data rozpoczęcia przedsięwzięcia (dzień, miesiąc i rok): | AM13: Dniem rozpoczęcia realizacji przedsięwzięcia jest dzień pierwszego wpisu do dziennika budowy informującego o rozpoczęciu robót a w przypadku gdy dziennik budowy nie jest wymagany dzień protokolarnego wprowadzenia wykonawcy na teren budowy lub przekazania placu budowy albo dzień wskazany w innym stosownym dokumencie. Jeżeli nie przesłali Państwo do tej pory jednego z ww. dokumentów do banku, prosimy o dołączenie go do dokumentacji dotyczącej rozliczenia.
A14: 16. Data zakończenia przedsięwzięcia (dzień, miesiąc i rok) | AM14: Dniem zakończenia realizacji przedsięwzięcia jest dzień, w którym zgodnie z odrębnymi przepisami można przystąpić do użytkowania zasobu utworzonego lub zmodernizowanego z udziałem wsparcia. Do dokumentacji rozliczeniowej należy dołączyć potwierdzoną za zgodność z oryginałem kopię dokumentu potwierdzającego zakończenie realizacji przedsięwzięcia.
A15: 3. Rodzaj przedsięwzięcia (wybrać właściwe)
A17: Czy przedsięwzięcie jest objęte gminnym programem rewitalizacji lub przynajmniej 5% lokali mieszkalnych dedykowanych jest adresatom programu „Za życiem”? [TAK/NIE] | AM17: Prosimy o wybranie TAK, jeżeli w umowie finansowe wsparcie zostało podwyższone finansowe wsparcie o 5 punktów procentowych w związku z realizacją przedsięwzięzia objetęgo rewitalizacją lub dedykowanemu adresatom programu "Za życiem". Podwyższenie o 5 punktów procentowych finansowego wsparcia wynika z art. 13 ust. 4 ww. ustawy. Jeżeli w umowie o finansowe wsparcie nie ma zapisów dotyczących rewitalizacji lub programu "Za życiem" wybierz NIE.
A18: 12. Liczba i powierzchnia użytkowa pozyskanych w ramach przedsięwzięcia lokali mieszkalnych, tymczasowych pomieszczeń / liczba miejsc w pomieszczeniach noclegowych w noclegowni, liczba miejsc w pomieszczeniach mieszkalnych w schroniskach dla osób bezdomnych lub liczba miejsc w ogrzewalniach, lokali/miejsc, w tym także: lokali mieszkalnych dedykowanych seniorom, lokali oraz dedykowanych adresatom programu „Za życiem”
A19: Rodzaj zasobu | N19: Liczba zasobu | AD19: Powierzchnia użytkowa w [m²]
AM20: Wybierz właściwy zasób oraz uzupełnij jego liczbę i powierzchnię użytkową w [m²]
AM21: Wybierz właściwy zasób w przypadku gdy utworzono więcej niż jeden zasób lub wybierz nie dotyczy
A22: w tym także lokale mieszkalne dedykowane seniorom
A23: w tym także lokale mieszkalne dedykowane adresatom programu „Za życiem” | N23: =IF(U17=Słownik!D3,"",0) -> 0 | AD23: =IF(U17=Słownik!D3,"",0) -> 0
A24: 4. Faktyczny koszt przedsięwzięcia | AM24: =IF(U24<>U31+U29+U30,"Czerwony kolor komórki (U24) oznacza, że wartość w nią wprowadzona nie jest równa sumie należnego finansowego wsparcia (U31), środków własnych (U29) i środków innych (U30). Prosimy o korektę celem doprowadzenie do zgodności wprowadzonych wartości.",) -> 0
A25: 6. Kwota finansowego wsparcia wynikająca z umowy (kwota zapisana w umowie lub aneksie) | AM25: Wprowadź kwotę wynikającą z umowy o finansowe wsparcie. Jeżeli zawarto aneks do umowy, wprowadź kwotę z ostatniego aneksu.
A26: Umowny procent dofinansowania [%] | U26: =IF(A20=Słownik!C9,Słownik!H1,IF(U15=Słownik!D6,,IF(OR(U15=Słownik!A5,U15=Słownik!A6,U15=Słownik!A7,U15=Słownik!A8,U15=Słownik!A14),Słownik!D1,Słownik!D2)+IF(U17=Słownik!D3,Słownik!E1,Słownik!E2))) -> 0 | AM26: Jeżeli umowny procent dofinansowania jest inny prosimy wprowadzić wartość odpowiadającą watości z umowy.
A27: 8. Wypłacona kwota finansowego wsparcia
A28: 13. Inne niż wsparcie finansowe źródła sfinansowania przedsięwzięcia, w tym: (rodzaje i kwoty)
A29: środki własne | U29: =U24-U31 -> 0
A30: środki inne | U30: 0
A31: 7. Należne finansowe wsparcie | U31: =IF(ROUNDDOWN(U24*U26,2)>=U25,U25,ROUNDDOWN(U24*U26,2)) -> 0 | AM31: Należne finansowe wsparcie nie może przekroczyć kwoty finansowego wsparcia wynikającej z umowy (aneksu) i zarazem maksymalnego dofinansowania określonego procentowo w art. 13 ww. ustawy.
A32: 9. Kwota finansowego wsparcia do wypłaty | U32: =IF(U31<=U27,0,U31-U27) -> 0 | AM32: Nadwyżka wsparcia należnego nad kwotę wsparcia wypłaconego, jeżeli liczba ujemna, wartość równa się 0,00 zł.
A33: 10. Do zwrotu | U33: =IF(U27>=U31,U27-U31,0) -> 0 | AM33: Nadwyżka wypłaconego wsparcia nad kwotę wsparcia należnego, jeżeli liczba ujemna, wartość równa się 0,00 zł.
A34: 11. Udział należnego wsparcia w faktycznym koszcie przedsięwzięcia | U34: =U31/U24 -> #DIV/0! | AM34: Kwota należnego wsparcia podzielona przez kwotę faktycznych kosztów przedsięwzięcia wyrażona w procentach.
A35: 14. Dane kontaktowe osoby wypełniającej rozliczenie
A36: Jednocześnie potwierdzam za zgodność z oryginałem wszystkie przedłożone do rozliczenia kosztów przedsięwzięcia dokumenty.
A37: W imieniu beneficjenta, udzielam pełnomocnictwa osobie wskazanej w pkt 14 niniejszego dokumentu do uzyskiwania informacji oraz wyjaśnień we wszystkich sprawach dotyczących rozliczenia, obowiązków po rozliczeniu oraz kontroli.
A38: 18. Podpis osoby uprawnionej do składania oświadczeń w imieniu wnioskodawcy (Jeżeli podpis składa inna osoba niż wójt, burmistrz, prezydent miasta, starosta, osoba uprawniona do składania oświadczeń woli przez spółkę lub organizację nie wymieniona w Krajowym Rejestrze Sądowym należy dołączyć dokument potwierdzający uprawnienia do składania oświadczeń w imieniu beneficjenta wsparcia dla tej osoby.)
A39: Podpis beneficjenta wsparcia
A40: Przygotowany formularz rozliczenia prosimy zapisać do formatu PDF i opatrzeć kwalifikowanym podpisem elektronicznym przez osobę lub osoby upoważnione do składania oświadczeń woli przez beneficjenta wsparcia. Krótka instrukcja zapisania formularza do pliku PDF: Kliknij na górnym pasku Pliki -> wybierz Zapisz plik -> wybierz folder docelowy zapisania pliku Formularza -> zmień Zapisz jako typ Skoroszyt programu Excel wybierając z rozwijanej listy plik PDF i kliknij Zapisz. Formularz zapisany w formacie pdf jest gotowy do podpisania. Podpisany formularz należy wysłać za pomocą środków komunikacji elektronicznej przez elektroniczną skrzynkę podawczą banku ePUAP: /BGK/DFM. Na potwierdzenie wysłania wniosku należy pobrać dokument Urzędowego Poświadczenia Przedłożenia (UPP). Po pobraniu UPP należy oczekiwać do 60 dni na korespondencję z banku w przedmiotowej sprawie.

Sheet Rozliczenie art. 5 i art. 5a
A1: Proszę wybierz odpowiedni arkusz i wypełnij niebieskie pola. Zadbaj o jakość wprowadzanych danych.
A2: Żółte pola wypełnią się automatycznie, na podstawie wprowadzonych wartości. | AM2: Uwagi, komentarze przydatne przy wypełnianiu formularza
A3: Wprowadzone nieprawidłowe wartości w niebieskie pola mogą spowodować niepoprawne wyliczenia.
H5: =TODAY() -> 46058
A6: miejscowość | H6: data
A9: FORMULARZ, NA KTÓRYM DOKONUJE SIĘ ROZLICZENIA FAKTYCZNIE PONIESIONYCH KOSZTÓW PRZEDSIĘWZIĘCIA, Z WYŁĄCZENIEM PRZEDSIĘWZIĘCIA, O KTÓRYM MOWA W ART. 5C USTAWY Z DNIA 8 GRUDNIA 2006 R. O FINANSOWYM WSPARCIU NIEKTÓRYCH PRZEDSIĘWZIĘĆ MIESZKANIOWYCH (DZ. U. Z 2024 R. POZ. 304), ZWANEJ DALEJ „USTAWĄ
A10: 1. Wnioskodawca
A11: 2. Numer umowy:
A12: 2a. Numer aneksu podwyższającego wysokość wsparcia lub data złożenia wniosku o aneks podwyższający wsparcie
A13: 15. Data rozpoczęcia przedsięwzięcia (dzień, miesiąc i rok): | AM13: Dniem rozpoczęcia realizacji przedsięwzięcia jest data zawarcia przez Beneficjenta wsparcia i Inwestora umowy przewidującej wysokość udziału Beneficjenta wsparcia w kosztach tworzenia lokali mieszkalnych, prawo Beneficjenta wsparcia do wskazywania najemców tych lokali i określającej szczegółowe kryteria przeznaczania tych lokali najemcom wymienione w art. 5 ust. 3 ww. ustawy.
A14: 16. Data zakończenia przedsięwzięcia (dzień, miesiąc i rok) | AM14: Dniem zakończenia realizacji przedsięwzięcia jest dzień, w którym zgodnie z odrębnymi przepisami można przystąpić do użytkowania zasobu utworzonego lub zmodernizowanego z udziałem wsparcia. Do dokumentacji rozliczeniowej należy dołączyć potwierdzoną za zgodność z oryginałem kopię dokumentu potwierdzającego zakończenie realizacji przedsięwzięcia.
A15: 17. Data spełnienia świadczenia na rzecz inwestora, o którym mowa w art. 18 ust. 1 pkt 2 ustawy | AM15: Data przekazania przez beneficjenta wsprcia do inwestora środków finansowego wsparcia.
A16: 3. Rodzaj przedsięwzięcia (wybrać właściwe)
A18: Czy przedsięwzięcie jest objęte gminnym programem rewitalizacji lub przynajmniej 5% lokali mieszkalnych dedykowanych jest adresatom programu „Za życiem”? [TAK/NIE] | AM18: Prosimy o wybranie TAK, jeżeli w umowie finansowe wsparcie zostało podwyższone finansowe wsparcie o 5 punktów procentowych w związku z realizacją przedsięwzięzia objetęgo rewitalizacją lub dedykowanemu adresatom programu "Za życiem". Podwyższenie o 5 punktów procentowych finansowego wsparcia wynika z art. 13 ust. 4 ww. ustawy. Jeżeli w umowie o finansowe wsparcie nie ma zapisów dotyczących rewitalizacji lub programu "Za życiem" wybierz NIE.
A19: 12. Liczba i powierzchnia użytkowa pozyskanych w ramach przedsięwzięcia lokali mieszkalnych w tym także: lokali mieszkalnych dedykowanych seniorom, lokali oraz dedykowanych adresatom programu „Za życiem”
A20: Rodzaj zasobu | N20: Liczba zasobu | AD20: Powierzchnia użytkowa w [m²]
AM21: Wybierz właściwy zasób oraz uzupełnij jego liczbę i powierzchnię użytkową w [m²]
AM22: Wybierz właściwy zasób w przypadku gdy utworzono więcej niż jeden zasób lub wybierz nie dotyczy
A23: w tym także lokale mieszkalne dedykowane seniorom
A24: w tym także lokale mieszkalne dedykowane adresatom programu „Za życiem” | N24: =IF(U18=Słownik!D3,"",0) -> 0 | AD24: =IF(U18=Słownik!D3,"",0) -> 0
A25: 4. Faktyczny koszt przedsięwzięcia (w przypadku przedsięwzięcia realizowanego przez inwestora, o którym mowa w art. 18 ust. 1 pkt 2 ustawy, uzupełnia się na podstawie jego oświadczenia) | AM25: =IF(U25<>U37+U32+U33+U34+U35,"Czerwony kolor komórki (U23) oznacza, że wartość w nią wprowadzona nie jest równa sumie należnego finansowego wsparcia (U31), środków własnych (U29), środkom RFRM (U31), środkom finansowania zwrotnego (U32) i środków innych (U33). Uzupełnij lub skoryguj.",) -> 0
A26: wartość gruntu stanowiącego własność inwestora, na którym realizowane jest przedsięwzięcie | AM26: W przypadku przedsięwzięć realizowanych na podstawie art. 5, wprowadź wartość gruntu wynikającą z zawartej umowy o finansowe wsparcie.
A27: 5. Udział wnioskodawcy w faktycznym koszcie przedsięwzięcia (w przypadku przedsięwzięcia realizowanego przez inwestora, o którym mowa w art. 18 ust. 1 pkt 2 ustawy – uzupełnia się na podstawie jego oświadczenia) | AM27: Udział wnioskodawcy w faktycznym koszcie przedsięwzięcia to środki finansowe pochodzące m.in. z finansowego wsparcia, finansowego wsparcia w ramach planu rozwojowego, grantu OZE, środków RFRM oraz środków własnych beneficjenta.
A28: 6. Kwota finansowego wsparcia wynikająca z umowy (kwota zapisana w umowie) | AM28: Wprowadź kwotę wynikającą z umowy o finansowe wsparcie. Jeżeli zawarto aneks do umowy, wprowadź kwotę z ostatniego aneksu.
A29: Umowny procent dofinansowania [%] | U29: =IF(U16=Słownik!D6,,IF(OR(U16=Słownik!A17,U16=Słownik!A18,U16=Słownik!A19,U16=Słownik!A20),Słownik!F1,Słownik!F2)+IF(U18=Słownik!D3,Słownik!E1,Słownik!E2)+IF(OR(U16=Słownik!A17,U16=Słownik!A18,U16=Słownik!A19,U16=Słownik!A20),IF(U26/U25<=10%,U26/U25,10%),0)) -> 0 | AM29: Jeżeli umowny procent dofinansowania jest inny prosimy wprowadzić wartość odpowiadającą watości z umowy.
A30: 8. Wypłacona kwota finansowego wsparcia
A31: 13. Inne niż wsparcie finansowe źródła sfinansowania przedsięwzięcia, w tym: (rodzaje i kwoty)
A32: środki własne
A33: środki Rządowego Funduszu Rozwoju Mieszkalnictwa | AM33: Wsparcie ze środków Rządowego Funduszu Rozwoju Mieszkalnictwa, o którym mowa w art. 33l ustawy z dnia 26 października 1995 r. o społecznych formach rozwoju mieszkalnictwa (Dz. U. z 2023 r. poz. 790, 1114, 1463 i 1693).
A34: finansowanie zwrotne | AM34: Finansowanie zwrotne, o którym mowa w art. 15b ustawy, o której mowa w odnośniku wyżej.
A35: środki inne
A36: Oznaczenie umowy kredytu finansowania zwrotnego i data jej zawarcia
A37: 7. Należne finansowe wsparcie | U37: =IF(ROUNDDOWN(U25*U29,2)>=U28,IF(U28>U27,U27,U28),ROUNDDOWN(U25*U29,2)) -> 0 | AM37: [U35=U24*U28 lub U35=U27] Należne finansowe wsparcie nie może przekroczyć kwoty finansowego wsparcia wynikającej z umowy (aneksu) i zarazem maksymalnego dofinansowania określonego procentowo w art. 13 ww. ustawy.
A38: 9. Kwota finansowego wsparcia do wypłaty | U38: =IF(U37<=U30,0,U37-U30) -> 0 | AM38: [U35<U29 jeżeli prawda to U36=U35-U29, jeżeli fałsz to U36=0,00] Nadwyżka wsparcia należnego nad kwotę wsparcia wypłaconego, jeżeli liczba ujemna, wartość równa się 0,00 zł.
A39: 10. Do zwrotu | U39: =IF(U30>=U37,U30-U37,0) -> 0 | AM39: [U29>U35 jeżeli prawda to U37=U29-U35, jeżeli fałsz to U37=0,00] Nadwyżka wypłaconego wsparcia nad kwotę wsparcia należnego, jeżeli liczba ujemna, wartość równa się 0,00 zł.
A40: 11. Udział należnego wsparcia w faktycznym koszcie przedsięwzięcia | U40: =U37/U25 -> #DIV/0! | AM40: [U38=U35/U24] Kwota należnego wsparcia podzielona przez kwotę faktycznych kosztów przedsięwzięcia wyrażona w procentach.
A41: 14. Dane kontaktowe osoby wypełniającej rozliczenie
A42: Jednocześnie potwierdzam za zgodność z oryginałem wszystkie przedłożone do rozliczenia kosztów przedsięwzięcia dokumenty.
A43: W imieniu beneficjenta, udzielam pełnomocnictwa osobie wskazanej w pkt 14 niniejszego dokumentu do uzyskiwania informacji oraz wyjaśnień we wszystkich sprawach dotyczących rozliczenia, obowiązków po rozliczeniu oraz kontroli.
A44: 18. Podpis osoby uprawnionej do składania oświadczeń w imieniu wnioskodawcy (Jeżeli podpis składa inna osoba niż wójt, burmistrz, prezydent miasta, starosta, osoba uprawniona do składania oświadczeń woli przez związek miedzygminny nie wymieniona w Krajowym Rejestrze Sądowym należy dołączyć dokument potwierdzający uprawnienia do składania oświadczeń w imieniu beneficjenta wsparcia dla tej osoby.)
...

Sheet Rozliczenie art. 5c beneficjent
A1: Proszę wybierz odpowiedni arkusz i wypełnij niebieskie pola. Zadbaj o jakość wprowadzanych danych.
A2: Żółte pola wypełnią się automatycznie, na podstawie wprowadzonych wartości. | AM2: Uwagi, komentarze przydatne przy wypełnianiu formularza
A3: Wprowadzone nieprawidłowe wartości w niebieskie pola mogą spowodować niepoprawne wyliczenia.
H5: =TODAY() -> 46058
A6: miejscowość | H6: data
A9: FORMULARZ, NA KTÓRYM DOKONUJE SIĘ ROZLICZENIA FAKTYCZNIE PONIESIONYCH KOSZTÓW PRZEDSIĘWZIĘCIA, O KTÓRYM MOWA W ART. 5C USTAWY Z DNIA 8 GRUDNIA 2006 R. O FINANSOWYM WSPARCIU NIEKTÓRYCH PRZEDSIĘWZIĘĆ MIESZKANIO WYCH (DZ. U. Z 2024 R. POZ. 304), ZWANEJ DALEJ USTAWĄ - przedsięwzięcia infrastrukturalne realizowane przez beneficjenta wsparcia
A10: 1. Wnioskodawca
A11: 2. Numer umowy:
A12: 2a. Numer aneksu podwyższającego wysokość wsparcia lub data złożenia wniosku o aneks podwyższający wsparcie
A13: 15. Data rozpoczęcia przedsięwzięcia (dzień, miesiąc i rok): | AM13: Dniem rozpoczęcia realizacji przedsięwzięcia jest data zawarcia przez Beneficjenta wsparcia i Inwestora umowy przewidującej wysokość udziału Beneficjenta wsparcia w kosztach tworzenia lokali mieszkalnych, prawo Beneficjenta wsparcia do wskazywania najemców tych lokali i określającej szczegółowe kryteria przeznaczania tych lokali najemcom wymienione w art. 5 ust. 3 ww. ustawy.
A14: 16. Data zakończenia przedsięwzięcia (dzień, miesiąc i rok) | AM14: Dniem zakończenia realizacji przedsięwzięcia jest dzień, w którym zgodnie z odrębnymi przepisami można przystąpić do użytkowania zasobu utworzonego lub zmodernizowanego z udziałem wsparcia. Do dokumentacji rozliczeniowej należy dołączyć potwierdzoną za zgodność z oryginałem kopię dokumentu potwierdzającego zakończenie realizacji przedsięwzięcia.
A15: 3. Rodzaj przedsięwzięcia (wybrać właściwe)
A16: 12. Wskazanie, które z zadań własnych gminy, wymienionych w art. 7 ust. 1 pkt 2, 3–6, 8–10 lub 12 ustawy z dnia 8 marca 1990 r. o samorządzie gminnym (Dz. U. z 2023 r. poz. 40, 572, 1463 i 1688), lub wymienionych w art. 4 ust. 1 pkt 1–3, 6–8 i 12 ustawy z dnia 5 czerwca 1998 r. o samorządzie powiatowym (Dz. U. z 2024 r. poz. 107), zostało zrealizowane w ramach przedsięwzięcia
AM17: Należy wskazać odpowiedni punkt z art. 7 ust. 1 ustawy z dnia 8 marca 1990 r. o samorządzie gminnym lub art. 4 ust. 1 ustawy z dnia 5 czerwca 1998 r. o samorządzie powiatowym.
A19: 4. Faktyczny koszt przedsięwzięcia (w przypadku przedsięwzięcia realizowanego przez inwestora, o którym mowa w art. 18 ust. 1 pkt 2 ustawy, uzupełnia się na podstawie jego oświadczenia) | AM19: =IF(U19<>U26+U24+U25,"Czerwony kolor komórki (U19) oznacza, że wartość w nią wprowadzona nie jest równa sumie należnego finansowego wsparcia (U28), środków własnych (U26) i środków innych (U27). Prosimy o korektę.",) -> 0
A20: 6. Kwota finansowego wsparcia wynikająca z umowy (kwota zapisana w umowie) | AM20: Wprowadź kwotę wynikającą z umowy o finansowe wsparcie. Jeżeli zawarto aneks do umowy, wprowadź kwotę z ostatniego aneksu.
A21: Umowny procent dofinansowania [%] | AM21: Jeżeli umowny procent dofinansowania jest inny prosimy wprowadzić wartość odpowiadającą watości z umowy.
A22: 8. Wypłacona kwota finansowego wsparcia
A23: 13. Inne niż wsparcie finansowe źródła sfinansowania przedsięwzięcia, w tym: (rodzaje i kwoty)
A24: środki własne
A25: środki inne | U25: 0
A26: 7. Należne finansowe wsparcie | U26: =IF(ROUNDDOWN(U19*U21,2)>=U20,U20,ROUNDDOWN(U19*U21,2)) -> 0 | AM26: Należne finansowe wsparcie nie może przekroczyć kwoty finansowego wsparcia wynikającej z umowy (aneksu) i zarazem maksymalnego dofinansowania określonego procentowo w art. 13 ww. ustawy.
A27: 9. Kwota finansowego wsparcia do wypłaty | U27: =IF(U26<=U22,0,U26-U22) -> 0 | AM27: Nadwyżka wsparcia należnego nad kwotę wsparcia wypłaconego, jeżeli liczba ujemna, wartość równa się 0,00 zł.
A28: 10. Do zwrotu | U28: =IF(U22>=U26,U22-U26,0) -> 0 | AM28: Nadwyżka wypłaconego wsparcia nad kwotę wsparcia należnego, jeżeli liczba ujemna, wartość równa się 0,00 zł.
A29: 11. Udział należnego wsparcia w faktycznym koszcie przedsięwzięcia | U29: =U26/U19 -> #DIV/0! | AM29: Kwota należnego wsparcia podzielona przez kwotę faktycznych kosztów przedsięwzięcia wyrażona w procentach.
A30: 14. Dane kontaktowe osoby wypełniającej rozliczenie
A31: Jednocześnie potwierdzam za zgodność z oryginałem wszystkie przedłożone do rozliczenia kosztów przedsięwzięcia dokumenty.
A32: W imieniu beneficjenta, udzielam pełnomocnictwa osobie wskazanej w pkt 14 niniejszego dokumentu do uzyskiwania informacji oraz wyjaśnień we wszystkich sprawach dotyczących rozliczenia, obowiązków po rozliczeniu oraz kontroli.
A33: 18. Podpis osoby uprawnionej do składania oświadczeń w imieniu wnioskodawcy (Jeżeli podpis składa inna osoba niż wójt, burmistrz, prezydent miasta, starosta, osoba uprawniona do składania oświadczeń woli przez spółkę nie wymieniona w Krajowym Rejestrze Sądowym należy dołączyć dokument potwierdzający uprawnienia do składania oświadczeń w imieniu beneficjenta wsparcia dla tej osoby.)
A34: Podpis beneficjenta wsparcia
A35: Przygotowany formularz rozliczenia prosimy zapisać do formatu PDF i opatrzeć kwalifikowanym podpisem elektronicznym przez osobę lub osoby upoważnione do składania oświadczeń woli przez beneficjenta wsparcia. Krótka instrukcja zapisania formularza do pliku PDF: Kliknij na górnym pasku Pliki -> wybierz Zapisz plik -> wybierz folder docelowy zapisania pliku Formularza -> zmień Zapisz jako typ Skoroszyt programu Excel wybierając z rozwijanej listy plik PDF i kliknij Zapisz. Formularz zapisany w formacie pdf jest gotowy do podpisania. Podpisany formularz należy wysłać za pomocą środków komunikacji elektronicznej przez elektroniczną skrzynkę podawczą banku ePUAP: /BGK/DFM. Na potwierdzenie wysłania wniosku należy pobrać dokument Urzędowego Poświadczenia Przedłożenia (UPP). Po pobraniu UPP należy oczekiwać do 60 dni na korespondencję z banku w przedmiotowej sprawie.

Sheet Rozliczenie art. 5c inwestor
A1: Proszę wybierz odpowiedni arkusz i wypełnij niebieskie pola. Zadbaj o jakość wprowadzanych danych.
A2: Żółte pola wypełnią się automatycznie, na podstawie wprowadzonych wartości. | AM2: Uwagi, komentarze przydatne przy wypełnianiu formularza
A3: Wprowadzone nieprawidłowe wartości w niebieskie pola mogą spowodować niepoprawne wyliczenia.
H5: =TODAY() -> 46058
A6: miejscowość | H6: data
A9: FORMULARZ, NA KTÓRYM DOKONUJE SIĘ ROZLICZENIA FAKTYCZNIE PONIESIONYCH KOSZTÓW PRZEDSIĘWZIĘCIA, O KTÓRYM MOWA W ART. 5C USTAWY Z DNIA 8 GRUDNIA 2006 R. O FINANSOWYM WSPARCIU NIEKTÓRYCH PRZEDSIĘWZIĘĆ MIESZKANIO WYCH (DZ. U. Z 2024 R. POZ. 304), ZWANEJ DALEJ USTAWĄ - przedsięwzięcia infrastrukturalne realizowane przez beneficjenta wsparcia
A10: 1. Wnioskodawca
A11: 2. Numer umowy:
A12: 2a. Numer aneksu podwyższającego wysokość wsparcia lub data złożenia wniosku o aneks podwyższający wsparcie
A13: 15. Data rozpoczęcia przedsięwzięcia (dzień, miesiąc i rok): | AM13: Dniem rozpoczęcia realizacji przedsięwzięcia jest data zawarcia przez Beneficjenta wsparcia i Inwestora umowy przewidującej wysokość udziału Beneficjenta wsparcia w kosztach tworzenia lokali mieszkalnych, prawo Beneficjenta wsparcia do wskazywania najemców tych lokali i określającej szczegółowe kryteria przeznaczania tych lokali najemcom wymienione w art. 5 ust. 3 ww. ustawy.
A14: 16. Data zakończenia przedsięwzięcia (dzień, miesiąc i rok) | AM14: Dniem zakończenia realizacji przedsięwzięcia jest dzień, w którym zgodnie z odrębnymi przepisami można przystąpić do użytkowania zasobu utworzonego lub zmodernizowanego z udziałem wsparcia. Do dokumentacji rozliczeniowej należy dołączyć potwierdzoną za zgodność z oryginałem kopię dokumentu potwierdzającego zakończenie realizacji przedsięwzięcia.
A15: 17. Data spełnienia świadczenia na rzecz inwestora, o którym mowa w art. 18 ust. 1 pkt 2 ustawy | AM15: Data przekazania przez beneficjenta wsprcia do inwestora środków finansowego wsparcia. Jeżeli nie dotyczy wpisz nie dotyczy
A16: 3. Rodzaj przedsięwzięcia (wybrać właściwe)
A17: 12. Wskazanie, które z zadań własnych gminy, wymienionych w art. 7 ust. 1 pkt 2, 3–6, 8–10 lub 12 ustawy z dnia 8 marca 1990 r. o samorządzie gminnym (Dz. U. z 2023 r. poz. 40, 572, 1463 i 1688), lub wymienionych w art. 4 ust. 1 pkt 1–3, 6–8 i 12 ustawy z dnia 5 czerwca 1998 r. o samorządzie powiatowym (Dz. U. z 2024 r. poz. 107), zostało zrealizowane w ramach przedsięwzięcia
AM18: Należy wskazać odpowiedni punkt z art. 7 ust. 1 ustawy z dnia 8 marca 1990 r. o samorządzie gminnym lub art. 4 ust. 1 ustawy z dnia 5 czerwca 1998 r. o samorządzie powiatowym.
A20: 4. Faktyczny koszt przedsięwzięcia (w przypadku przedsięwzięcia realizowanego przez inwestora, o którym mowa w art. 18 ust. 1 pkt 2 ustawy, uzupełnia się na podstawie jego oświadczenia) | AM20: =IF(U20<>U28+U26+U27,"Czerwony kolor komórki (U19) oznacza, że wartość w nią wprowadzona nie jest równa sumie należnego finansowego wsparcia (U28), środków własnych (U26) i środków innych (U27). Prosimy o korektę.",) -> 0
A21: 5. Udział wnioskodawcy w faktycznym koszcie przedsięwzięcia (w przypadku przedsięwzięcia realizowanego przez inwestora, o którym mowa w art. 18 ust. 1 pkt 2 ustawy – uzupełnia się na podstawie jego oświadczenia)
A22: 6. Kwota finansowego wsparcia wynikająca z umowy (kwota zapisana w umowie) | AM22: Wprowadź kwotę wynikającą z umowy o finansowe wsparcie. Jeżeli zawarto aneks do umowy, wprowadź kwotę z ostatniego aneksu.
A23: Umowny procent dofinansowania [%] | AM23: Jeżeli umowny procent dofinansowania jest inny prosimy wprowadzić wartość odpowiadającą watości z umowy.
A24: 8. Wypłacona kwota finansowego wsparcia
A25: 13. Inne niż wsparcie finansowe źródła sfinansowania przedsięwzięcia, w tym: (rodzaje i kwoty)
A26: środki własne
A27: środki inne | U27: 0
A28: 7. Należne finansowe wsparcie | U28: =IF(ROUNDDOWN(U20*U23,2)>=U22,IF(U22>U21,U21,U22),ROUNDDOWN(U20*U23,2)) -> 0 | AM28: Należne finansowe wsparcie nie może przekroczyć kwoty finansowego wsparcia wynikającej z umowy (aneksu) i zarazem maksymalnego dofinansowania określonego procentowo w art. 13 ww. ustawy.
A29: 9. Kwota finansowego wsparcia do wypłaty | U29: =IF(U28<=U24,0,U28-U24) -> 0 | AM29: Nadwyżka wsparcia należnego nad kwotę wsparcia wypłaconego, jeżeli liczba ujemna, wartość równa się 0,00 zł.
A30: 10. Do zwrotu | U30: =IF(U24>=U28,U24-U28,0) -> 0 | AM30: Nadwyżka wypłaconego wsparcia nad kwotę wsparcia należnego, jeżeli liczba ujemna, wartość równa się 0,00 zł.
A31: 11. Udział należnego wsparcia w faktycznym koszcie przedsięwzięcia | U31: =U28/U20 -> #DIV/0! | AM31: Kwota należnego wsparcia podzielona przez kwotę faktycznych kosztów przedsięwzięcia wyrażona w procentach.
A32: 14. Dane kontaktowe osoby wypełniającej rozliczenie
A33: Jednocześnie potwierdzam za zgodność z oryginałem wszystkie przedłożone do rozliczenia kosztów przedsięwzięcia dokumenty.
A34: W imieniu beneficjenta, udzielam pełnomocnictwa osobie wskazanej w pkt 14 niniejszego dokumentu do uzyskiwania informacji oraz wyjaśnień we wszystkich sprawach dotyczących rozliczenia, obowiązków po rozliczeniu oraz kontroli.
A35: 18. Podpis osoby uprawnionej do składania oświadczeń w imieniu wnioskodawcy (Jeżeli podpis składa inna osoba niż wójt, burmistrz, prezydent miasta, starosta, osoba uprawniona do składania oświadczeń woli przez spółkę nie wymieniona w Krajowym Rejestrze Sądowym należy dołączyć dokument potwierdzający uprawnienia do składania oświadczeń w imieniu beneficjenta wsparcia dla tej osoby.)
A36: Podpis beneficjenta wsparcia
A37: Przygotowany formularz rozliczenia prosimy zapisać do formatu PDF i opatrzeć kwalifikowanym podpisem elektronicznym przez osobę lub osoby upoważnione do składania oświadczeń woli przez beneficjenta wsparcia. Krótka instrukcja zapisania formularza do pliku PDF: Kliknij na górnym pasku Pliki -> wybierz Zapisz plik -> wybierz folder docelowy zapisania pliku Formularza -> zmień Zapisz jako typ Skoroszyt programu Excel wybierając z rozwijanej listy plik PDF i kliknij Zapisz. Formularz zapisany w formacie pdf jest gotowy do podpisania. Podpisany formularz należy wysłać za pomocą środków komunikacji elektronicznej przez elektroniczną skrzynkę podawczą banku ePUAP: /BGK/DFM. Na potwierdzenie wysłania wniosku należy pobrać dokument Urzędowego Poświadczenia Przedłożenia (UPP). Po pobraniu UPP należy oczekiwać do 60 dni na korespondencję z banku w przedmiotowej sprawie.

Sheet Rozliczenie art. 4a akademiki
A1: Proszę wybierz odpowiedni arkusz i wypełnij niebieskie pola. Zadbaj o jakość wprowadzanych danych.
A2: Żółte pola wypełnią się automatycznie, na podstawie wprowadzonych wartości. | AM2: Uwagi, komentarze przydatne przy wypełnianiu formularza
A3: Wprowadzone nieprawidłowe wartości w niebieskie pola mogą spowodować niepoprawne wyliczenia.
H5: =TODAY() -> 46058
A6: miejscowość | H6: data
A9: FORMULARZ, NA KTÓRYM DOKONUJE SIĘ ROZLICZENIA FAKTYCZNIE PONIESIONYCH KOSZTÓW PRZEDSIĘWZIĘCIA, Z WYŁĄCZENIEM PRZEDSIĘWZIĘCIA, O KTÓRYM MOWA W ART. 5C USTAWY Z DNIA 8 GRUDNIA 2006 R. O FINANSOWYM WSPARCIU NIEKTÓRYCH PRZEDSIĘWZIĘĆ MIESZKANIOWYCH (DZ. U. Z 2024 R. POZ. 304), ZWANEJ DALEJ „USTAWĄ
A10: 1. Wnioskodawca
A11: 2. Numer umowy:
A12: 2a. Numer aneksu podwyższającego wysokość wsparcia lub data złożenia wniosku o aneks podwyższający wsparcie
A13: 15. Data rozpoczęcia przedsięwzięcia (dzień, miesiąc i rok): | AM13: Dniem rozpoczęcia realizacji przedsięwzięcia jest dzień pierwszego wpisu do dziennika budowy informującego o rozpoczęciu robót a w przypadku gdy dziennik budowy nie jest wymagany dzień protokolarnego wprowadzenia wykonawcy na teren budowy lub przekazania placu budowy albo dzień wskazany w innym stosownym dokumencie. Jeżeli nie przesłali Państwo do tej pory jednego z ww. dokumentów do banku, prosimy o dołączenie go do dokumentacji dotyczącej rozliczenia.
A14: 16. Data zakończenia przedsięwzięcia (dzień, miesiąc i rok) | AM14: Dniem zakończenia realizacji przedsięwzięcia jest dzień, w którym zgodnie z odrębnymi przepisami można przystąpić do użytkowania zasobu utworzonego lub zmodernizowanego z udziałem wsparcia. Do dokumentacji rozliczeniowej należy dołączyć potwierdzoną za zgodność z oryginałem kopię dokumentu potwierdzającego zakończenie realizacji przedsięwzięcia.
A15: 3. Rodzaj przedsięwzięcia (wybrać właściwe) | U15: A. Budowa budynku.
A17: 12. Liczba i powierzchnia użytkowa pozyskanych w ramach przedsięwzięcia lokali mieszkalnych, tymczasowych pomieszczeń / liczba miejsc w pomieszczeniach noclegowych w noclegowni, liczba miejsc w pomieszczeniach mieszkalnych w schroniskach dla osób bezdomnych lub liczba miejsc w ogrzewalniach, lokali/miejsc, liczba pomieszczeń służących zaspokajaniu potrzeb mieszkaniowych studentów i doktorantów oraz liczba miejsc znajdujących się w tych pomieszczeniach
A18: Rodzaj zasobu | N18: Liczba pomieszczeń służących zaspokajaniu potrzeb mieszkaniowych studentów i doktorantów | AB18: Liczba miejsc znajdujacych się w tych pomieszczeniach | AK18: Powierzchnia użytkowa w [m²]
A19: pomieszczenia służące zaspokajaniu potrzeb mieszkaniowych studentów i doktorantów | AM19: Wybierz właściwy zasób oraz uzupełnij jego liczbę i powierzchnię użytkową w [m²]
A20: 4. Faktyczny koszt przedsięwzięcia | AM20: =IF(U20<>U27+U25+U26,"Czerwony kolor komórki (U24) oznacza, że wartość w nią wprowadzona nie jest równa sumie należnego finansowego wsparcia (U31), środków własnych (U29) i środków innych (U30). Prosimy o korektę celem doprowadzenie do zgodności wprowadzonych wartości.",) -> 0
A21: 6. Kwota finansowego wsparcia wynikająca z umowy (kwota zapisana w umowie lub aneksie) | AM21: Wprowadź kwotę wynikającą z umowy o finansowe wsparcie. Jeżeli zawarto aneks do umowy, wprowadź kwotę z ostatniego aneksu.
A22: Umowny procent dofinansowania [%] | U22: =IF(OR(U15=Słownik!A55,U15=Słownik!A56,U15=Słownik!A57,U15=Słownik!A58),Słownik!D1,Słownik!D1) -> 0.8 | AM22: Jeżeli umowny procent dofinansowania jest inny prosimy wprowadzić wartość odpowiadającą watości z umowy.
A23: 8. Wypłacona kwota finansowego wsparcia
A24: 13. Inne niż wsparcie finansowe źródła sfinansowania przedsięwzięcia, w tym: (rodzaje i kwoty)
A25: środki własne | U25: =U20-U27 -> 0
A26: środki inne | U26: 0
A27: 7. Należne finansowe wsparcie | U27: =IF(ROUNDDOWN(U20*U22,2)>=U21,U21,ROUNDDOWN(U20*U22,2)) -> 0 | AM27: Należne finansowe wsparcie nie może przekroczyć kwoty finansowego wsparcia wynikającej z umowy (aneksu) i zarazem maksymalnego dofinansowania określonego procentowo w art. 13 ww. ustawy.
A28: 9. Kwota finansowego wsparcia do wypłaty | U28: =IF(U27<=U23,0,U27-U23) -> 0 | AM28: Nadwyżka wsparcia należnego nad kwotę wsparcia wypłaconego, jeżeli liczba ujemna, wartość równa się 0,00 zł.
A29: 10. Do zwrotu | U29: =IF(U23>=U27,U23-U27,0) -> 0 | AM29: Nadwyżka wypłaconego wsparcia nad kwotę wsparcia należnego, jeżeli liczba ujemna, wartość równa się 0,00 zł.
A30: 11. Udział należnego wsparcia w faktycznym koszcie przedsięwzięcia | U30: =U27/U20 -> #DIV/0! | AM30: Kwota należnego wsparcia podzielona przez kwotę faktycznych kosztów przedsięwzięcia wyrażona w procentach.
A31: 14. Dane kontaktowe osoby wypełniającej rozliczenie
A32: Jednocześnie potwierdzam za zgodność z oryginałem wszystkie przedłożone do rozliczenia kosztów przedsięwzięcia dokumenty.
A33: W imieniu beneficjenta, udzielam pełnomocnictwa osobie wskazanej w pkt 14 niniejszego dokumentu do uzyskiwania informacji oraz wyjaśnień we wszystkich sprawach dotyczących rozliczenia, obowiązków po rozliczeniu oraz kontroli.
A34: 18. Podpis osoby uprawnionej do składania oświadczeń w imieniu wnioskodawcy (Jeżeli podpis składa inna osoba niż rektor należy dołączyć dokument potwierdzający uprawnienia do składania oświadczeń w imieniu beneficjenta wsparcia dla tej osoby.)
A35: Podpis beneficjenta wsparcia
A36: Przygotowany formularz rozliczenia prosimy zapisać do formatu PDF i opatrzeć kwalifikowanym podpisem elektronicznym przez osobę lub osoby upoważnione do składania oświadczeń woli przez beneficjenta wsparcia. Krótka instrukcja zapisania formularza do pliku PDF: Kliknij na górnym pasku Pliki -> wybierz Zapisz plik -> wybierz folder docelowy zapisania pliku Formularza -> zmień Zapisz jako typ Skoroszyt programu Excel wybierając z rozwijanej listy plik PDF i kliknij Zapisz. Formularz zapisany w formacie pdf jest gotowy do podpisania. Podpisany formularz należy wysłać za pomocą środków komunikacji elektronicznej przez elektroniczną skrzynkę podawczą banku ePUAP: /BGK/DFM. Na potwierdzenie wysłania wniosku należy pobrać dokument Urzędowego Poświadczenia Przedłożenia (UPP). Po pobraniu UPP należy oczekiwać do 60 dni na korespondencję z banku w przedmiotowej sprawie.

Sheet Słownik
A1: Objaśnienia: | C1: Rodzaj zasobu | D1: 0.8 | E1: 0.05 | F1: 0.25 | G1: 0.15 | H1: 0.95
A2: * Rodzaje przedsięwzięć: | C2: lokale mieszkalne | D2: 0.5 | E2: 0 | F2: 0.8 | G2: 0.25
C3: mieszkania wspomagane | D3: TAK
C4: mieszkania treningowe | D4: NIE
A5: A. Budowa budynku. | C5: tymczasowe pomieszczenia
A6: B. Remont budynku albo jego części. | C6: liczba miejsc w pomieszczeniach noclegowych w noclegowni
A7: C. Przebudowa budynku albo jego części. | C7: liczba miejsc w pomieszczeniach mieszkalnych w schroniskach dla osób bezdomnych
A8: D. Zmiana sposobu użytkowania budynku albo jego części. | C8: liczba miejsc w ogrzewalniach
A9: E. Kupno lokalu mieszkalnego, budynku mieszkalnego albo udziału we współwłasności budynku mieszkalnego. | C9: lokale mieszkalne -byłe mieszkania zakładowe
A10: F. Kupno lokalu mieszkalnego, budynku mieszkalnego albo udziału we współwłasności budynku mieszkalnego po_x0002_łączone z remontem tego lokalu lub budynku mieszkalnego. | C10: nie dotyczy
A11: nie dotyczy
A12: G. Budowa infrastruktury technicznej lub infrastruktury społecznej. | C12: w tym także lokale mieszkalne dedykowane seniorom
A13: H. Przebudowa infrastruktury technicznej lub infrastruktury społecznej. | C13: w tym także lokale mieszkalne dedykowane adresatom programu „Za życiem”
A17: A. Budowa budynku - art. 5. | B17: A. Budowa budynku - art. 5. | C17: lokale mieszkalne
A18: B. Remont budynku albo jego części - art. 5. | B18: B. Remont budynku albo jego części - art. 5. | C18: mieszkania wspomagane
A19: C. Przebudowa budynku albo jego części - art. 5. | B19: C. Przebudowa budynku albo jego części - art. 5. | C19: mieszkania treningowe
A20: D. Zmiana sposobu użytkowania budynku albo jego części - art. 5. | B20: D. Zmiana sposobu użytkowania budynku albo jego części - art. 5. | C20: nie dotyczy
A21: A. Budowa budynku - art. 5a. | B21: A. Budowa budynku - art. 5a.
A22: B. Remont budynku albo jego części - art. 5a. | B22: B. Remont budynku albo jego części - art. 5a.
A23: C. Przebudowa budynku albo jego części - art. 5a. | B23: C. Przebudowa budynku albo jego części - art. 5a.
A24: D. Zmiana sposobu użytkowania budynku albo jego części - art. 5a. | B24: D. Zmiana sposobu użytkowania budynku albo jego części - art. 5a. | C24: pomieszczenia służące zaspokajaniu potrzeb mieszkaniowych studentów i doktorantów
A26: A. Budowa budynku - art. 5. | B26: A. Budowa budynku - art. 5.
A27: B. Remont budynku albo jego części - art. 5. | B27: B. Remont budynku albo jego części - art. 5.
A28: C. Przebudowa budynku albo jego części - art. 5. | B28: C. Przebudowa budynku albo jego części - art. 5.
A29: D. Zmiana sposobu użytkowania budynku albo jego części - art. 5. | B29: D. Zmiana sposobu użytkowania budynku albo jego części - art. 5.
A30: A. Budowa budynku - art. 5a. | B30: A. Budowa budynku - art. 3.
A31: B. Remont budynku albo jego części - art. 5a. | B31: B. Remont budynku albo jego części - art. 3.
A32: C. Przebudowa budynku albo jego części - art. 5a. | B32: C. Przebudowa budynku albo jego części - art. 3.
A33: D. Zmiana sposobu użytkowania budynku albo jego części - art. 5a. | B33: D. Zmiana sposobu użytkowania budynku albo jego części - art. 3.
A34: nie dotyczy | B34: nie dotyczy
A35: Art. 7. 1. pkt 2 ustawy z dnia 8 marca 1990 r. o samorządzie gminnym - gminnych dróg, ulic, mostów, placów oraz organizacji ruchu drogowego.
A36: Art. 7. 1. pkt 3 ustawy z dnia 8 marca 1990 r. o samorządzie gminnym - wodociągów i zaopatrzenia w wodę, kanalizacji, usuwania i oczyszczania ścieków komunalnych, utrzymania czystości i porządku oraz urządzeń sanitarnych, wysypisk i unieszkodliwiania odpadów komunalnych, zaopatrzenia w energię elektryczną i cieplną oraz gaz.
A37: Art. 7. 1. pkt 4 ustawy z dnia 8 marca 1990 r. o samorządzie gminnym - lokalnego transportu zbiorowego.
A38: Art. 7. 1. pkt 5 ustawy z dnia 8 marca 1990 r. o samorządzie gminnym - ochrony zdrowia.
A39: Art. 7. 1. pkt 6 ustawy z dnia 8 marca 1990 r. o samorządzie gminnym - pomocy społecznej, w tym ośrodków i zakładów opiekuńczych.
A40: Art. 7. 1. pkt 8 ustawy z dnia 8 marca 1990 r. o samorządzie gminnym - edukacji publicznej.
A41: Art. 7. 1. pkt 9 ustawy z dnia 8 marca 1990 r. o samorządzie gminnym - kultury, w tym bibliotek gminnych i innych instytucji kultury oraz ochrony zabytków i opieki nad zabytkami.
A42: Art. 7. 1. pkt 10 ustawy z dnia 8 marca 1990 r. o samorządzie gminnym - kultury fizycznej i turystyki, w tym terenów rekreacyjnych i urządzeń sportowych.
A43: Art. 7. 1. pkt 12 ustawy z dnia 8 marca 1990 r. o samorządzie gminnym - zieleni gminnej i zadrzewień.
A44: Art. 4 ust. 1 pkt 1 ustawy z dnia 5 czerwca 1998 r. o samorządzie powiatowym - edukacji publicznej
...

Sheet pierwowzór
A1: Proszę wypełnić niebieskie pola.
A2: Żółte pola wypełnią się automatycznie.
A3: Zielone pola wypełnia pracownik Banku. | AM3: Uwagi, komentarze przydatne przy wypełnianiu wniosku
H5: =TODAY() -> 46058 | AA5: 1
A6: miejscowość | H6: data wniosku
A9: FORMULARZ, NA KTÓRYM DOKONUJE SIĘ ROZLICZENIA FAKTYCZNIE PONIESIONYCH KOSZTÓW PRZEDSIĘWZIĘCIA, Z WYŁĄCZENIEM PRZEDSIĘWZIĘCIA, O KTÓRYM MOWA W ART. 5C USTAWY Z DNIA 8 GRUDNIA 2006 R. O FINANSOWYM WSPARCIU NIEKTÓRYCH PRZEDSIĘWZIĘĆ MIESZKANIO WYCH (DZ. U. Z 2024 R. POZ. 304), ZWANEJ DALEJ „USTAWĄ
A10: 1. Wnioskodawca
A11: 2. Numer umowy:
A12: 2a. Numer aneksu podwyższającego wysokość wsparcia lub data złożenia wniosku o aneks podwyższający wsparcie
A13: 3. Rodzaj przedsięwzięcia (wybrać właściwe)
A15: 4. Faktyczny koszt przedsięwzięcia (w przypadku przedsięwzięcia realizowanego przez inwestora, o którym mowa w art. 18 ust. 1 pkt 2 ustawy, uzupełnia się na podstawie jego oświadczenia) | U15: 103 | AM15: Jak wybrać że to art. 5 a nie art. 5a - nowa wiersz czy nowy formularz? Najlepiej nowy wiersz obsługujący całość
A16: wartość gruntu stanowiącego własność inwestora, na którym realizowane jest przedsięwzięcie
A17: 5. Udział wnioskodawcy w faktycznym koszcie przedsięwzięcia (w przypadku przedsięwzięcia realizowanego przez inwestora, o którym mowa w art. 18 ust. 1 pkt 2 ustawy – uzupełnia się na podstawie jego oświadczenia)
A18: 6. Kwota finansowego wsparcia wynikająca z umowy (kwota zapisana w umowie) | U18: 80
A19: Czy przedsięwzięcie jest objęte gminnym programem rewitalizacji lub przynajmniej 5% lokali mieszkalnych dedykowanych jest adresatom programu „Za życiem”? [TAK/NIE] | U19: TAK
A20: Umowny procent dofinansowania [%] | U20: =IF(OR(U13=Słownik!A5,U13=Słownik!A6,U13=Słownik!A7,U13=Słownik!A8,U13=Słownik!A14),Słownik!D1,Słownik!D2)+IF(U19=Słownik!D3,Słownik!E1,Słownik!E2) -> 0.85 | AM20: Procent dofinansowania
A21: 7. Należne finansowe wsparcie | U21: =IF(U15*U20>=U18,U18,U15*U20) -> 80
A22: 8. Wypłacona kwota finansowego wsparcia | U22: 67
A23: 9. Kwota finansowego wsparcia do wypłaty (nadwyżka wsparcia należnego nad kwotę wsparcia wypłaconego; jeżeli liczba ujemna, wpisać 0,00 zł) | U23: =IF(U21<=U22,0,U21-U22) -> 13
A24: 10. Do zwrotu (nadwyżka wypłaconego wsparcia nad kwotę wsparcia należnego; jeżeli liczba ujemna, wpisać 0,00 zł) | U24: =IF(U22>=U21,U22-U21,0) -> 0
A25: 11. Udział należnego wsparcia w faktycznym koszcie przedsięwzięcia | U25: =U21/U15 -> 0.77669903
A26: 12. Liczba i powierzchnia użytkowa pozyskanych w ramach przedsięwzięcia lokali mieszkalnych, tymczasowych pomieszczeń / liczba miejsc w pomieszczeniach noclegowych w noclegowni, liczba miejsc w pomieszczeniach mieszkalnych w schroniskach dla osób bezdomnych lub liczba miejsc w ogrzewalniach, lokali/miejsc, w tym także: lokali mieszkalnych dedykowanych seniorom, lokali oraz dedykowanych adresatom programu „Za życiem”
A27: Rodzaj zasobu | N27: Liczba zasobu | AD27: Powierzchnia użytkowa w [m²]
A28: lokale mieszkalne | AM28: Wybierz właściwy zasób
AM29: Wybierz właściwy zasób w przypadku gdy utworzono więcej niż jeden zasób lub wybierz nie dotyczy
A30: w tym także lokale mieszkalne dedykowane seniorom
A31: w tym także lokale mieszkalne dedykowane adresatom programu „Za życiem”
A32: 13. Inne niż wsparcie finansowe źródła sfinansowania przedsięwzięcia, w tym: (rodzaje i kwoty)
A33: środki własne
A34: środki Rządowego Funduszu Rozwoju Mieszkalnictwa | AM34: Wsparcie ze środków Rządowego Funduszu Rozwoju Mieszkalnictwa, o którym mowa w art. 33l ustawy z dnia 26 października 1995 r. o społecznych formach rozwoju mieszkalnictwa (Dz. U. z 2023 r. poz. 790, 1114, 1463 i 1693).
A35: finansowanie zwrotne | AM35: Finansowanie zwrotne, o którym mowa w art. 15b ustawy, o której mowa w odnośniku wyżej.
A36: środki inne
A37: 15. Data rozpoczęcia przedsięwzięcia (dzień, miesiąc i rok):
A38: 16. Data zakończenia przedsięwzięcia (dzień, miesiąc i rok)
A39: 14. Dane kontaktowe osoby wypełniającej rozliczenie
A40: 18. Podpis osoby uprawnionej do składania oświadczeń w imieniu wnioskodawcy
A41: Podpis beneficjenta wsparcia
A42: Przygotowany wniosek prosimy zapisać do formatu PDF i opatrzeć kwalifikowanym podpisem elektronicznym przez osobę lub osoby upoważnione do składania oświadczeń woli przez wnioskodawcę. Krótka instrukcja zapisania wniosku do pliku PDF: Kliknij na górnym pasku Pliki -> wybierz Zapisz plik -> wybierz folder docelowy zapisania pliku Wniosku -> zmień Zapisz jako typ Skoroszyt programu Excel wybierając z rozwijanej listy plik PDF i kliknij Zapisz. Wniosek zapisany w formacie pdf jest gotowy do podpisania. Wniosek podpisany należy wysłać za pomocą środków komunikacji elektronicznej przez elektroniczną skrzynkę podawczą banku ePUAP: /BGK/DFM. Na potwierdzenie wysłania wniosku należy pobrać dokument Urzędowego Poświadczenia Przedłożenia (UPP). Po pobraniu UPP należy oczekiwać do 14 dni na korespondencję z banku w przedmiotowej sprawie. Przez ten czas nie należy przesyłać wniosku ponownie lub zmian do niego.
