Workbook
Name _edn1: Słowniki!$H$5
Name _edn10: Słowniki!$J$43
Name _edn11: Słowniki!$J$44
Name _edn12: Słowniki!$J$45
Name _edn2: Słowniki!$J$35
Name _edn3: Słowniki!$J$36
Name _edn4: Słowniki!$J$37
Name _edn5: Słowniki!$J$38
Name _edn6: Słowniki!$J$39
Name _edn7: Słowniki!$J$40
Name _edn8: Słowniki!$J$41
Name _edn9: Słowniki!$J$42
Name _ednref1: Słowniki!$H$2
Name _ednref10: Słowniki!#REF!
Name _ednref11: Słowniki!#REF!
Name _ednref12: Słowniki!#REF!
Name _ednref2: Słowniki!#REF!
Name _ednref3: Słowniki!#REF!
Name _ednref4: Słowniki!#REF!
Name _ednref5: Słowniki!#REF!
Name _ednref6: Słowniki!#REF!
Name _ednref7: Słowniki!#REF!
Name _ednref8: Słowniki!#REF!
Name _ednref9: Słowniki!#REF!
Name _ftn1: Słowniki!$D$33
Name _ftnref1: Słowniki!$D$16
Name _Hlk108901557: Słowniki!$D$30
Name _Hlk146545562: 'Wniosek art 5 budowa'!$AM$59
Name _Hlk53499634: Słowniki!$D$22
Name _Hlk59545887: Słowniki!$E$18
Name _Hlk63413254: Słowniki!$D$5
Name ListaRob: 'Słownik woj_powiaty'!$E$3:$F$381

Sheet Wybór
A1: Wybierz beneficjenta wsparcia
A2: Wybierz rodzaj przedsięwzięcia
A3: Wybierz Inwestora innego niż beneficjent wsparcia****
A4: Rodzaj zasobu | B4: Rodzaj przedsięwzięcia*** | C4: Beneficjent wsparcia
C5: Gmina | D5: Jednoosobowa Spółka Gminna | E5: Związek Międzygminny | F5: Powiat | G5: Organizacja pozarządowa albo podmiot, o których mowa w art. 3 ust. 2 i 3 ustawy z dnia 24 kwietnia 2003 r. o działalności pożytku publicznego i o wolontariacie
C6: Wysokość finansowego wsparcia
A7: Lokale Mieszkalne na Wynajem art. 5 | B7: Budowa budynku | C7: 25%/35% | E7: 25%/35%
B8: Remont lub przebudowa budynku | C8: 25%/35% | E8: 25%/35%
B9: Remont lub przebudowa budynku SAN | C9: 80/60/40% | E9: 80/60/40%
A10: Lokale Mieszkalne stanowiące mieszkaniowy zasób gminy * art. 3 | B10: Budowa budynku | C10: 0.8 | D10: 0.8
B11: Kupno lub kupno połączone z remontem | C11: 0.5 | D11: 0.5
B12: Remont lub przebudowa budynku mieszkalnego | C12: 0.8 | D12: 0.8
B13: Remont lub przebudowa budynku niemieszkalnego | C13: 0.8 | D13: 0.8
B14: Zmiana sposobu użytkowania budynku | C14: 0.8 | D14: 0.8
A15: Lokale Mieszkalne stanowiące mieszkaniowy zasób gminy ***** art. 3 | B15: Remont lub przebudowa lokalu mieszkalnego z premią MZG | C15: 0.5 | D15: 0.5
A16: Lokale mieszkalne z prawem do podnajmowania art. 5a * | B16: Budowa budynku | C16: 0.8 | E16: 0.8
B17: Remont lub przebudowa budynku | C17: 0.8 | E17: 0.8
A18: Mieszkania treningowe i wspomagane * art. 3 oraz art. 6 | B18: Budowa budynku | C18: 0.8 | D18: 0.8 | F18: 0.8 | G18: 0.8
B19: Kupno lub kupno połączone z remontem | C19: 0.5 | D19: 0.5 | F19: 0.5 | G19: 0.5
B20: Remont lub przebudowa budynku mieszkalnego | C20: 0.8 | D20: 0.8 | F20: 0.8 | G20: 0.8
B21: Remont lub przebudowa budynku niemieszkalnego | C21: 0.8 | D21: 0.8 | F21: 0.8 | G21: 0.8
B22: Zmiana sposobu użytkowania budynku | C22: 0.8 | D22: 0.8 | F22: 0.8 | G22: 0.8
A23: Mieszkania treningowe i wspomagane ***** art. 3 oraz art. 6 | B23: Remont lub przebudowa lokalu mieszkalnego z premią MZG | C23: 0.5 | D23: 0.5
A24: Mieszkania treningowe i wspomagane z prawem do podnajmowania art. 5a w związku z art. 6 * | B24: Budowa budynku | C24: 0.8 | E24: 0.8 | F24: 0.8
B25: Remont lub przebudowa budynku niemieszkalnego lub mieszkalnego | C25: 0.8 | E25: 0.8 | F25: 0.8
A26: Mieszkania (Powódź) | B26: Budowa budynku | C26: 0.9 | D26: 0.9
B27: Kupno lub kupno połączone z remontem | C27: 0.6 | D27: 0.6
B28: Remont lub przebudowa budynku niemieszkalnego lub mieszkalnego | C28: 0.9 | D28: 0.9
B29: Zmiana sposobu użytkowania budynku | C29: 0.9 | D29: 0.9
B30: Remont lub przebudowa lokalu mieszkalnego | C30: 0.6 | D30: 0.6
A31: Ogrzewalnie art. 4 * | B31: Remont lub przebudowa budynku niemieszkalnego lub mieszkalnego | C31: 0.8 | D31: 0.8 | E31: 0.8 | G31: 0.8
B32: Zmiana sposobu użytkowania budynku | C32: 0.8 | D32: 0.8 | E32: 0.8 | G32: 0.8
B33: Budowa budynku ** | C33: 0.8 | D33: 0.8 | E33: 0.8 | G33: 0.8
A34: Pomieszczenia tymczasowe art. 3 * | B34: Zmiana sposobu użytkowania budynku | C34: 0.8 | D34: 0.8
A35: Byłe Mieszkania Zakładowe art. 3 | B35: Kupno lub kupno połączone z remontem | C35: 0.95 | D35: 0.95
A36: Dostosowanie Standardów Noclegowni art. 4 | B36: Remont lub przebudowa istniejącej noclegowni | C36: 0.8 | D36: 0.8 | E36: 0.8 | G36: 0.8
A37: Dostosowanie Standardów Schronisk dla osób bezdomnych art. 4 | B37: Remont lub przebudowa istniejącego schroniska dla bezdomnych | C37: 0.8 | D37: 0.8 | E37: 0.8 | G37: 0.8
A38: Dostosowanie Standardów Ogrzewalni art. 4 | B38: Remont lub przebudowa istniejącej ogrzewalni | C38: 0.8 | D38: 0.8 | E38: 0.8 | G38: 0.8
A39: Noclegownie art. 4 * | B39: Budowa budynku | C39: 0.8 | D39: 0.8 | E39: 0.8 | G39: 0.8
B40: Remont lub przebudowa budynku niemieszkalnego lub mieszkalnego | C40: 0.8 | D40: 0.8 | E40: 0.8 | G40: 0.8
...

Sheet Wniosek art 3 budowa
A1: Proszę wypełnić niebieskie pola, brak wypełnienia niebieskich pól może spowodować wezwanie do uzupełnienia wniosku, co wydłuży okres rozpatrzenia wniosku.
A2: Żółte pola wypełnią się automatycznie.
AM3: Uwagi, komentarze przydatne przy wypełnianiu wniosku
H4: =TODAY() -> 46184
A5: miejscowość | H5: data wniosku
A7: Wybierz właściwe | G7: Nowy wniosek | R7: Korekta wniosku
A8: Jeżeli składasz korektę wniosku wpisz numer pisma z wezwania do uzupełnienia | AM8: Wpisz nie dotyczy jeżeli skąłdasz nowy wniosek
A9: Szanowni Państwo, przesyłając nowy wniosek w tytule sprawy (w piśmie przewodnim lub technicznym przesyłanym poprzez ePUAP/e-doręczenia wraz z wnioskiem) proszę wpisywać treść „nowy wniosek”, a jeśli przesyłana jest korekta wniosku proszę wpisać „korekta wniosku dla sprawy numer (…)”. Numer sprawy to znak pisma – wezwania do uzupełnienia. Przesyłana korespondencja do banku poprzez ePUAP lub przez e-doręczenia powinna dotyczyć jednej sprawy. Taki sposób oznakowania korespondencji pozwoli nam usprawnić obsługę Państwa wniosków. Dziękujemy za stosowanie się do powyższego.
A11: Wniosek o udzielenie wsparcia finansowego z Funduszu Dopłat w ramach realizacji przez
A12: Bank Gospodarstwa Krajowego rządowego programu budownictwa komunalnego
A13: zgodnie z przepisami ustawy z dnia 8 grudnia 2006 r. o finansowym wsparciu niektórych przedsięwzięć mieszkaniowych (t.j. Dz.U. 2024 poz. 304 z późn. zm.)
A15: I. Dane Wnioskodawcy
A16: A. | B16: Beneficjent wsparcia
A18: B. | B18: Nazwa | AM18: Nazwa wnioskodawcy powinna być zgodna z bazą REGON
A20: C. | B20: Adres wnioskodawcy [kod pocztowy, nazwa miejscowości, nazwa ulicy, numer porządkowy budynku, numer lokalu] zgodnie z nazwami miejscowości i ulicy w Rejestrze TERYT | AM20: Weryfikacji poprawności adresu można dokonać na stronie internetowej -> https://eteryt.stat.gov.pl/eTeryt/rejestr_teryt/udostepnianie_danych/baza_teryt/uzytkownicy_indywidualni/wyszukiwanie/wyszukiwanie.aspx?contrast=default
B22: Adres do doręczeń elektronicznych, o których mowa w ustawie z dnia 18 listopada 2020 r. o doręczeniach elektronicznych (Dz. U. z 2024 r. poz. 1045 i 1841). Adres do doręczeń można sprawdzić klikając w link. | AM22: Najczęściej zadawane pytania i odpowiedzi o e-Doręczeniach
A24: D. | B24: Numer identyfikacji podatkowej NIP | W24: Numer identyfikacyjny REGON | AM24: Numer NIP i numer REGON powinny być zgodne z bazą regon przypisaną do nazwy wnioskodacy
B26: Numer KRS - dla podmiotów innych niż gmina, powiat lub związek międzygminny | AM26: Numer KRS powinien być zgodny z bazą KRS dla wnioskodawcy
A28: E. | B28: Dane służbowe osoby bezpośrednio prowadzącej sprawę
B29: Imię i nazwisko/ nr telefonu
B31: Adres poczty elektronicznej
B33: Imię i nazwisko/ nr telefonu (opcjonalnie)
AM34: Wybierz nie dotyczy jeżeli, sprawę prowadzi jedna osoba
B35: Adres poczty elektronicznej (opcjonalnie)
AM36: Wybierz nie dotyczy jeżeli, sprawę prowadzi jedna osoba
A37: G. | B37: Numer rachunku bankowego lub rachunku prowadzonego przez spółdzielczą kasę oszczędnościowo-kredytową beneficjenta wsparcia, na który zostanie przekazane finansowe wsparcie.
T38: {=LEFT(B38,2)&" "&_xlfn.TEXTJOIN(" ",,MID(B38,{3,7,11,15,19,23},4))}
A39: II. | B39: Dane dotyczące realizowanego przedsięwzięcia
A40: A. | B40: Wnioskowana kwota finansowego wsparcia [zł]
B41: =T152 -> #DIV/0! | AM41: Kliknij "tutaj" i przejdź do wypełnienia zestawienia kosztów
A42: C. | B42: Przewidywana data rozpoczęcia realizacji przedsięwzięcia /Data rozpoczęcia realizacji przedsięwzięcia (dzień, miesiąc (słownie) i rok).
AM43: Data rozpoczęcia realizacji przedsięwzięcia nie może być późniejsza niż okres ważności pozwolenia na budowę
A44: D. | B44: Przewidywana data zakończenia realizacji przedsięwzięcia (dzień, miesiąc (słownie) i rok).
AM45: Data zakończenie realizacji nie może być dłuższa niż 36 miesiący od przewidywanej daty rozpoczęcia przedsięwzięcia
A46: E. | B46: Przewidywana struktura finansowania przedsięwzięcia, z podziałem na
B47: Wyszczególnienie | Z47: Ogółem (brutto) | AK47: Udział [%]
B48: Środki własne beneficjenta wsparcia | AK48: =ROUND(Z48/Z$51,5) -> #DIV/0! | AM48: Maksymalne finansowe wsparcie jest uzależnione od rodzaju przedsięwzięcia i wynosi dla budowy 80% lub 90% mieszkania dla powodzian
B49: Wsparcie finansowe na podstawie ustawy | Z49: =B$41 -> #DIV/0! | AK49: =ROUND(Z49/Z$51,5) -> #DIV/0! | AM49: oraz dodatkowo 5 %, w przypadku przedsięwzięć, w których nie mniej niż 5% lokali mieszkalnych przeznaczonych będzie dla rodzin wg ustawy o wsparciu kobiet i rodzin "za życiem" lub w przypadku przedsięwzięcia, o którym mowa w art. 15 ust. 1 pkt 5 lit. a ustawy o rewitalizacji
B50: Inne źródła | AK50: =ROUND(Z50/Z$51,5) -> #DIV/0!
B51: Łącznie | Z51: =SUM(Z48:AJ50) -> #DIV/0! | AK51: =SUM(AK48:AL50) -> #DIV/0! | AM51: Łącznie powinno zsumować się na kwalifikowany koszt przedsięwzięcia
...

Sheet Wniosek art 3 remontlubprzebudo
A1: Proszę wypełnić niebieskie pola, brak wypełnienia niebieskich pól może spowodować wezwanie do uzupełnienia wniosku, co wydłuży okres rozpatrzenia wniosku.
A2: Żółte pola wypełnią się automatycznie.
AM3: Uwagi, komentarze przydatne przy wypełnianiu wniosku
H4: =TODAY() -> 46184
A5: miejscowość | H5: data wniosku
A7: Wybierz właściwe | G7: Nowy wniosek | Q7: Korekta wniosku
A8: Jeżeli składasz korektę wniosku wpisz numer pisma z wezwania do uzupełnienia | AM8: Wpisz nie dotyczy jeżeli skąłdasz nowy wniosek
A9: Szanowni Państwo, przesyłając nowy wniosek w tytule sprawy (w piśmie przewodnim lub technicznym przesyłanym poprzez ePUAP/e-doręczenia wraz z wnioskiem) proszę wpisywać treść „nowy wniosek”, a jeśli przesyłana jest korekta wniosku proszę wpisać „korekta wniosku dla sprawy numer (…)”. Numer sprawy to znak pisma – wezwania do uzupełnienia. Przesyłana korespondencja do banku poprzez ePUAP lub przez e-doręczenia powinna dotyczyć jednej sprawy. Taki sposób oznakowania korespondencji pozwoli nam usprawnić obsługę Państwa wniosków. Dziękujemy za stosowanie się do powyższego.
A11: Wniosek o udzielenie wsparcia finansowego z Funduszu Dopłat w ramach realizacji przez
A12: Bank Gospodarstwa Krajowego rządowego programu budownictwa komunalnego
A13: zgodnie z przepisami ustawy z dnia 8 grudnia 2006 r. o finansowym wsparciu niektórych przedsięwzięć mieszkaniowych (t.j. Dz.U. 2024 poz. 304 z późn. zm.)
A15: I. Dane Wnioskodawcy
A16: A. | B16: Beneficjent wsparcia
A18: B. | B18: Nazwa | AM18: Nazwa wnioskodawcy powinna być zgodna z bazą REGON
A20: C. | B20: Adres wnioskodawcy [kod pocztowy, nazwa miejscowości, nazwa ulicy, numer porządkowy budynku, numer lokalu] zgodnie z nazwami miejscowości i ulicy w Rejestrze TERYT | AM20: Weryfikacji poprawności adresu można dokonać na stronie internetowej -> https://eteryt.stat.gov.pl/eTeryt/rejestr_teryt/udostepnianie_danych/baza_teryt/uzytkownicy_indywidualni/wyszukiwanie/wyszukiwanie.aspx?contrast=default
B22: Adres do doręczeń elektronicznych, o których mowa w ustawie z dnia 18 listopada 2020 r. o doręczeniach elektronicznych (Dz. U. z 2024 r. poz. 1045 i 1841). Adres do doręczeń można sprawdzić klikając w link. | AM22: Najczęściej zadawane pytania i odpowiedzi o e-Doręczeniach
A24: D. | B24: Numer identyfikacji podatkowej NIP | W24: Numer identyfikacyjny REGON | AM24: Numer NIP i numer REGON powinny być zgodne z bazą regon przypisaną do nazwy wnioskodacy
B26: Numer KRS - dla podmiotów innych niż gmina, powiat lub związek międzygminny | AM26: Numer KRS powinien być zgodny z bazą KRS dla wnioskodawcy
A28: E. | B28: Dane służbowe osoby bezpośrednio prowadzącej sprawę
B29: Imię i nazwisko/ nr telefonu
B31: Adres poczty elektronicznej
AM32: Wybierz nie dotyczy jeżeli, sprawę prowadzi jedna osoba
B33: Imię i nazwisko/ nr telefonu (opcjonalnie)
AM34: Wybierz nie dotyczy jeżeli, sprawę prowadzi jedna osoba
B35: Adres poczty elektronicznej (opcjonalnie)
A37: G. | B37: Numer rachunku bankowego lub rachunku prowadzonego przez spółdzielczą kasę oszczędnościowo-kredytową beneficjenta wsparcia, na który zostanie przekazane finansowe wsparcie.
T38: {=LEFT(B38,2)&" "&_xlfn.TEXTJOIN(" ",,MID(B38,{3,7,11,15,19,23},4))}
A39: II. | B39: Dane dotyczące realizowanego przedsięwzięcia
A40: A. | B40: Wnioskowana kwota finansowego wsparcia [zł]
B41: =T174 -> 0 | AM41: Kliknij "tutaj" i przejdź do wypełnienia zestawienia kosztów
A42: C. | B42: Przewidywana data rozpoczęcia realizacji przedsięwzięcia /Data rozpoczęcia realizacji przedsięwzięcia (dzień, miesiąc (słownie) i rok).
A44: D. | B44: Przewidywana data zakończenia realizacji przedsięwzięcia, a w przypadku przedsięwzięcia obejmującego remont lub przebudowę części budynku w rozbiciu na poszczególne lokale mieszkalne (dzień, miesiąc (słownie) i rok) - data dla lokalu którego remont zakończy się jako ostatni.
AM45: Data zakończenie realizacji nie może być dłuższa niż 36 miesiący od przewidywanej daty rozpoczęcia przedsięwzięcia
A46: E. | B46: Przewidywana struktura finansowania przedsięwzięcia, z podziałem na
B47: Wyszczególnienie | Z47: Ogółem (brutto) | AK47: Udział [%] | AM47: Maksymalne finansowe wsparcie jest uzależnione od rodzaju przedsięwzięcia i wynosi 80% lub 90% mieszkania dla powodzian
B48: Środki własne beneficjenta wsparcia | AK48: =ROUND(Z48/Z$51,5) -> #DIV/0! | AM48: oraz dodatkowo 5 %, w przypadku przedsięwzięć, w których nie mniej niż 5 % lokali mieszkalnych przeznaczonych będzie dla rodzin wg ustawy o wsparciu kobiet i rodzin "za życiem" lub w przypadku przedsięwzięcia, o którym mowa w art. 15 ust. 1 pkt 5 lit. a ustawy o rewitalizacji
B49: Wsparcie finansowe na podstawie ustawy | Z49: =B$41 -> 0 | AK49: =ROUND(Z49/Z$51,5) -> #DIV/0!
B50: Inne źródła | AK50: =ROUND(Z50/Z$51,5) -> #DIV/0!
B51: Łącznie | Z51: =SUM(Z48:AJ50) -> 0 | AK51: =SUM(AK48:AL50) -> #DIV/0! | AM51: Łącznie powinno zsumować się na kwalifikowany koszt przedsięwzięcia
A52: III. | B52: Rodzaj przedsięwzięcia (należy wskazać właściwe)
...

Sheet Wniosek inne 
A1: Proszę wypełnić niebieskie pola, brak wypełnienia niebieskich pól może spowodować wezwanie do uzupełnienia wniosku, co wydłuży okres rozpatrzenia wniosku.
A2: Żółte pola wypełnią się automatycznie.
AM3: Uwagi, komentarze przydatne przy wypełnianiu wniosku
H4: =TODAY() -> 46184
A5: miejscowość | H5: data wniosku
A7: Wybierz właściwe | G7: Nowy wniosek | Q7: Korekta wniosku
A8: Jeżeli składasz korektę wniosku wpisz numer pisma z wezwania do uzupełnienia | AM8: Wpisz nie dotyczy jeżeli skąłdasz nowy wniosek
A9: Szanowni Państwo, przesyłając nowy wniosek w tytule sprawy (w piśmie przewodnim lub technicznym przesyłanym poprzez ePUAP/e-doręczenia wraz z wnioskiem) proszę wpisywać treść „nowy wniosek”, a jeśli przesyłana jest korekta wniosku proszę wpisać „korekta wniosku dla sprawy numer (…)”. Numer sprawy to znak pisma – wezwania do uzupełnienia. Przesyłana korespondencja do banku poprzez ePUAP lub przez e-doręczenia powinna dotyczyć jednej sprawy. Taki sposób oznakowania korespondencji pozwoli nam usprawnić obsługę Państwa wniosków. Dziękujemy za stosowanie się do powyższego.
A11: Wniosek o udzielenie wsparcia finansowego z Funduszu Dopłat w ramach realizacji przez
A12: Bank Gospodarstwa Krajowego rządowego programu budownictwa komunalnego
A13: zgodnie z przepisami ustawy z dnia 8 grudnia 2006 r. o finansowym wsparciu niektórych przedsięwzięć mieszkaniowych (t.j. Dz.U. 2024 poz. 304 z późn. zm.)
A15: I. Dane Wnioskodawcy
A16: A. | B16: Beneficjent wsparcia
A18: B. | B18: Nazwa | AM18: Nazwa wnioskodawcy powinna być zgodna z bazą REGON
A20: C. | B20: Adres wnioskodawcy [kod pocztowy, nazwa miejscowości, nazwa ulicy, numer porządkowy budynku, numer lokalu] zgodnie z nazwami miejscowości i ulicy w Rejestrze TERYT | AM20: Weryfikacji poprawności adresu można dokonać na stronie internetowej -> https://eteryt.stat.gov.pl/eTeryt/rejestr_teryt/udostepnianie_danych/baza_teryt/uzytkownicy_indywidualni/wyszukiwanie/wyszukiwanie.aspx?contrast=default
B22: Adres do doręczeń elektronicznych, o których mowa w ustawie z dnia 18 listopada 2020 r. o doręczeniach elektronicznych (Dz. U. z 2024 r. poz. 1045 i 1841). Adres do doręczeń można sprawdzić klikając w link. | AM22: Najczęściej zadawane pytania i odpowiedzi o e-Doręczeniach
A24: D. | B24: Numer identyfikacji podatkowej NIP | W24: Numer identyfikacyjny REGON | AM24: Numer NIP i numer REGON powinny być zgodne z bazą regon przypisaną do nazwy wnioskodacy
B26: Numer KRS - dla podmiotów innych niż gmina, powiat lub związek międzygminny | AM26: Numer KRS powinien być zgodny z bazą KRS dla wnioskodawcy
A28: E. | B28: Dane służbowe osoby bezpośrednio prowadzącej sprawę
B29: Imię i nazwisko/ nr telefonu
B31: Adres poczty elektronicznej
AM32: Wybierz nie dotyczy jeżeli, sprawę prowadzi jedna osoba
B33: Imię i nazwisko/ nr telefonu (opcjonalnie)
AM34: Wybierz nie dotyczy jeżeli, sprawę prowadzi jedna osoba
B35: Adres poczty elektronicznej (opcjonalnie)
A37: G. | B37: Numer rachunku bankowego lub rachunku prowadzonego przez spółdzielczą kasę oszczędnościowo-kredytową beneficjenta wsparcia, na który zostanie przekazane finansowe wsparcie.
T38: {=LEFT(B38,2)&" "&_xlfn.TEXTJOIN(" ",,MID(B38,{3,7,11,15,19,23},4))}
A39: II. | B39: Dane dotyczące realizowanego przedsięwzięcia
A40: A. | B40: Wnioskowana kwota finansowego wsparcia [zł]
B41: =T125 -> #DIV/0! | AM41: Kliknij "tutaj" i przejdź do wypełnienia zestawienia kosztów
A42: C. | B42: Przewidywana data rozpoczęcia realizacji przedsięwzięcia /Data rozpoczęcia realizacji przedsięwzięcia (dzień, miesiąc (słownie) i rok).
AM43: Data rozpoczęcia realizacji przedsięwzięcia nie może być późniejsza niż okres ważności pozwolenia na budowę
A44: D. | B44: Przewidywana data zakończenia realizacji przedsięwzięcia (dzień, miesiąc (słownie) i rok).
AM45: Data zakończenie realizacji nie może być dłuższa niż 36 miesiący od przewidywanej daty rozpoczęcia przedsięwzięcia
A46: E. | B46: Przewidywana struktura finansowania przedsięwzięcia, z podziałem na
B47: Wyszczególnienie | Z47: Ogółem (brutto) | AK47: Udział [%]
B48: Środki własne beneficjenta wsparcia | AK48: =ROUND(Z48/Z$51,5) -> #DIV/0! | AM48: Maksymalne finansowe wsparcie jest uzależnione od rodzaju przedsięwzięcia i wynosi dla budowy 80% lub 90% mieszkania dla powodzian
B49: Wsparcie finansowe na podstawie ustawy | Z49: =B$41 -> #DIV/0! | AK49: =ROUND(Z49/Z$51,5) -> #DIV/0! | AM49: oraz dodatkowo 5 %, w przypadku przedsięwzięć, w których nie mniej niż 5% lokali mieszkalnych przeznaczonych będzie dla rodzin wg ustawy o wsparciu kobiet i rodzin "za życiem" lub w przypadku przedsięwzięcia, o którym mowa w art. 15 ust. 1 pkt 5 lit. a ustawy o rewitalizacji
B50: Inne źródła | AK50: =ROUND(Z50/Z$51,5) -> #DIV/0!
B51: Łącznie | Z51: =SUM(Z48:AJ50) -> #DIV/0! | AK51: =SUM(AK48:AL50) -> #DIV/0! | AM51: Łącznie powinno zsumować się na kwalifikowany koszt przedsięwzięcia
...

Sheet Wniosek kupno
A1: Proszę wypełnić niebieskie pola, brak wypełnienia niebieskich pól może spowodować wezwanie do uzupełnienia wniosku, co wydłuży okres rozpatrzenia wniosku.
AM2: Uwagi, komentarze przydatne przy wypełnianiu wniosku
H3: =TODAY() -> 46184
A4: miejscowość | H4: data wniosku
A6: Wybierz właściwe | G6: Nowy wniosek | Q6: Korekta wniosku
A7: Jeżeli składasz korektę wniosku wpisz numer pisma z wezwania do uzupełnienia | AM7: Wpisz nie dotyczy jeżeli skąłdasz nowy wniosek
A8: Szanowni Państwo, przesyłając nowy wniosek w tytule sprawy (w piśmie przewodnim lub technicznym przesyłanym poprzez ePUAP/e-doręczenia wraz z wnioskiem) proszę wpisywać treść „nowy wniosek”, a jeśli przesyłana jest korekta wniosku proszę wpisać „korekta wniosku dla sprawy numer (…)”. Numer sprawy to znak pisma – wezwania do uzupełnienia. Przesyłana korespondencja do banku poprzez ePUAP lub przez e-doręczenia powinna dotyczyć jednej sprawy. Taki sposób oznakowania korespondencji pozwoli nam usprawnić obsługę Państwa wniosków. Dziękujemy za stosowanie się do powyższego.
A10: Wniosek o udzielenie wsparcia finansowego z Funduszu Dopłat w ramach realizacji przez
A11: Bank Gospodarstwa Krajowego rządowego programu budownictwa komunalnego
A12: zgodnie z przepisami ustawy z dnia 8 grudnia 2006 r. o finansowym wsparciu niektórych przedsięwzięć mieszkaniowych (t.j. Dz.U. 2024 poz. 304 z późn. zm.)
A14: I. Dane Wnioskodawcy
A15: A. | B15: Beneficjent wsparcia
A17: B. | B17: Nazwa | AM17: Nazwa wnioskodawcy powinna być zgodna z bazą REGON
A19: C. | B19: Adres wnioskodawcy [kod pocztowy, nazwa miejscowości, nazwa ulicy, numer porządkowy budynku, numer lokalu] zgodnie z nazwami miejscowości i ulicy w Rejestrze TERYT | AM19: Weryfikacji poprawności adresu można dokonać na stronie internetowej -> https://eteryt.stat.gov.pl/eTeryt/rejestr_teryt/udostepnianie_danych/baza_teryt/uzytkownicy_indywidualni/wyszukiwanie/wyszukiwanie.aspx?contrast=default
B21: Adres do doręczeń elektronicznych, o których mowa w ustawie z dnia 18 listopada 2020 r. o doręczeniach elektronicznych (Dz. U. z 2024 r. poz. 1045 i 1841). Adres do doręczeń można sprawdzić klikając w link. | AM21: Najczęściej zadawane pytania i odpowiedzi o e-Doręczeniach
A23: D. | B23: Numer identyfikacji podatkowej NIP | W23: Numer identyfikacyjny REGON | AM23: Numer NIP i numer REGON powinny być zgodne z bazą regon przypisaną do nazwy wnioskodacy
B25: Numer KRS - dla podmiotów innych niż gmina, powiat lub związek międzygminny | AM25: Numer KRS powinien być zgodny z bazą KRS dla wnioskodawcy
A27: E. | B27: Dane służbowe osoby bezpośrednio prowadzącej sprawę
B28: Imię i nazwisko/ nr telefonu
B30: Adres poczty elektronicznej
AM31: Wybierz nie dotyczy jeżeli, sprawę prowadzi jedna osoba
B32: Imię i nazwisko/ nr telefonu (opcjonalnie)
AM33: Wybierz nie dotyczy jeżeli, sprawę prowadzi jedna osoba
B34: Adres poczty elektronicznej (opcjonalnie)
A36: G. | B36: Numer rachunku bankowego lub rachunku prowadzonego przez spółdzielczą kasę oszczędnościowo-kredytową beneficjenta wsparcia, na który zostanie przekazane finansowe wsparcie.
T37: {=LEFT(B37,2)&" "&_xlfn.TEXTJOIN(" ",,MID(B37,{3,7,11,15,19,23},4))}
A38: II. | B38: Dane dotyczące realizowanego przedsięwzięcia
A39: A. | B39: Wnioskowana kwota finansowego wsparcia [zł]
B40: =T117 -> 0 | AM40: Kliknij "tutaj" i przejdź do wypełnienia zestawienia kosztów
A41: C. | B41: Przewidywana data rozpoczęcia realizacji przedsięwzięcia /Data rozpoczęcia realizacji przedsięwzięcia (dzień, miesiąc (słownie) i rok). | AM41: Finansowe wsparcie może być udzielone na realizację przedsięwzięcia rozpoczętego przed dniem zawarcia umowy, o której mowa w art. 12, jeżeli wniosek o finansowe wsparcie, o którym mowa w art. 8, został złożony przez beneficjenta wsparcia przed upływem 12 miesięcy od dnia rozpoczęcia przedsięwzięcia
A43: D. | B43: Przewidywana data zakończenia realizacji przedsięwzięcia / Data zakończenia realizacji przedsięwzięcia (dzień, miesiąc (słownie) i rok). | AM43: Data zakończenie realizacji nie może być dłuższa niż 36 miesiący od przewidywanej daty rozpoczęcia przedsięwzięcia
AM44: Maksymalne finansowe wsparcie nie może przekroczyć:
A45: E. | B45: Przewidywana struktura finansowania przedsięwzięcia, z podziałem na | AM45: Lokale Mieszkalne (stanowiące mieszkaniowy zasobu gminy)* | AN45: 0.5
B46: Wyszczególnienie | Z46: Ogółem (brutto) | AK46: Udział [%]
B47: Środki własne beneficjenta wsparcia | AK47: =ROUND(Z47/Z$50,5) -> #DIV/0! | AM47: Mieszkania wspomagane i treningowe * | AN47: 0.5
B48: Wsparcie finansowe na podstawie ustawy | Z48: =B$40 -> 0 | AK48: =ROUND(Z48/Z$50,5) -> #DIV/0! | AM48: Mieszkania (Powódź) | AN48: 0.6
B49: Inne źródła | AK49: =ROUND(Z49/Z$50,5) -> #DIV/0! | AM49: Mieszkania Zakładowe | AN49: 0.5
B50: Łącznie | Z50: =SUM(Z47:AJ49) -> 0 | AK50: =SUM(AK47:AL49) -> #DIV/0! | AM50: Łącznie powinno zsumować się na kwalifikowany koszt przedsięwzięcia
A51: H. | B51: W przypadku przedsięwzięć, o których mowa w art. 3 ust. 1 pkt 5 i 6 i art. 4a ust. 1 pkt 3 ustawy, informacja o: 1) przewidywanej cenie sprzedaży, a jeżeli przedsięwzięcie zostało rozpoczęte przed dniem złożenia wniosku o finansowe wsparcie – informacja o dacie sporządzenia umowy sprzedaży i cenie sprzedaży; 2) wartości gruntu, wynikającej z aktualnego operatu szacunkowego, sporządzonego zgodnie z przepisami ustawy z dnia 21 sierpnia 1997 r. o gospodarce nieruchomościami (Dz. U. z 2024 r. poz. 1145, 1222, 1717 i 1881 oraz z 2025 r. poz. 1077 i 1080).
B52: Przewidywana cena sprzedaży/Cena ssprzedaży
...

Sheet Wniosek art 5 budowa
A1: Proszę wypełnić niebieskie pola, brak wypełnienia niebieskich pól może spowodować wezwanie do uzupełnienia wniosku, co wydłuży okres rozpatrzenia wniosku.
A2: Żółte pola wypełnią się automatycznie.
AM3: Uwagi, komentarze przydatne przy wypełnianiu wniosku
H4: =TODAY() -> 46184
A5: miejscowość | H5: data wniosku
A7: Wybierz właściwe | G7: Nowy wniosek | Q7: Korekta wniosku
A8: Jeżeli składasz korektę wniosku wpisz numer pisma z wezwania do uzupełnienia | AM8: Wpisz nie dotyczy jeżeli skałdasz nowy wniosek
A9: Szanowni Państwo, przesyłając nowy wniosek w tytule sprawy (w piśmie przewodnim lub technicznym przesyłanym poprzez ePUAP/e-doręczenia wraz z wnioskiem) proszę wpisywać treść „nowy wniosek”, a jeśli przesyłana jest korekta wniosku proszę wpisać „korekta wniosku dla sprawy numer (…)”. Numer sprawy to znak pisma – wezwania do uzupełnienia. Przesyłana korespondencja do banku poprzez ePUAP lub przez e-doręczenia powinna dotyczyć jednej sprawy. Taki sposób oznakowania korespondencji pozwoli nam usprawnić obsługę Państwa wniosków. Dziękujemy za stosowanie się do powyższego.
A12: Wniosek o udzielenie wsparcia finansowego z Funduszu Dopłat w ramach realizacji przez
A13: Bank Gospodarstwa Krajowego rządowego programu budownictwa komunalnego
A14: zgodnie z przepisami ustawy z dnia 8 grudnia 2006 r. o finansowym wsparciu niektórych przedsięwzięć mieszkaniowych (t.j. Dz.U. 2024 poz. 304 z późn. zm.)
A16: I. Dane Wnioskodawcy
A17: A. | B17: Beneficjent wsparcia
A19: B. | B19: Nazwa | AM19: Nazwa wnioskodawcy powinna być zgodna z bazą REGON
A21: C. | B21: Adres wnioskodawcy [kod pocztowy, nazwa miejscowości, nazwa ulicy, numer porządkowy budynku, numer lokalu] zgodnie z nazwami miejscowości i ulicy w Rejestrze TERYT | AM21: Weryfikacji poprawności adresu można dokonać na stronie internetowej -> https://eteryt.stat.gov.pl/eTeryt/rejestr_teryt/udostepnianie_danych/baza_teryt/uzytkownicy_indywidualni/wyszukiwanie/wyszukiwanie.aspx?contrast=default
B23: Adres do doręczeń elektronicznych, o których mowa w ustawie z dnia 18 listopada 2020 r. o doręczeniach elektronicznych (Dz. U. z 2024 r. poz. 1045 i 1841). Adres do doręczeń można sprawdzić klikając w link. | AM23: Najczęściej zadawane pytania i odpowiedzi o e-Doręczeniach
A25: D. | B25: Numer identyfikacji podatkowej NIP | W25: Numer identyfikacyjny REGON | AM25: Numer NIP i numer REGON powinny być zgodne z bazą regon przypisaną do nazwy wnioskodacy
A27: E. | B27: Dane służbowe osoby bezpośrednio prowadzącej sprawę
B28: Imię i nazwisko/ nr telefonu
B30: Adres poczty elektronicznej/nr faksu
B32: Imię i nazwisko/ nr telefonu (opcjonalnie)
AM33: Wybierz nie dotyczy jeżeli, sprawę prowadzi jedna osoba
B34: Adres poczty elektronicznej/nr faksu (opcjonalnie)
AM35: Wybierz nie dotyczy jeżeli, sprawę prowadzi jedna osoba
A36: F. | B36: Nazwa inwestora
B38: Adres inwestora | Y38: Adres inwestora do doręczeń elektronicznych, o których mowa w ustawie z dnia 18 listopada 2020 r. o doręczeniach elektronicznych.
B40: Numer identyfikacji podatkowej NIP inwestora | W40: Numer identyfikacyjny REGON inwestora
B42: Numer KRS - dla podmiotów innych niż gmina, powiat lub związek międzygminny inwestora | AM42: Numer KRS powinien być zgodny z bazą KRS dla inwestora
A44: G. | B44: Numer rachunku bankowego lub rachunku prowadzonego przez spółdzielczą kasę oszczędnościowo-kredytową beneficjenta wsparcia, na który zostanie przekazane finansowe wsparcie.
T45: {=LEFT(B45,2)&" "&_xlfn.TEXTJOIN(" ",,MID(B45,{3,7,11,15,19,23},4))}
A46: II. | B46: Dane dotyczące realizowanego przedsięwzięcia
A47: A. | B47: Wnioskowana kwota finansowego wsparcia (zł)
B48: =IF(T166+Z59>ROUNDDOWN(45%*AK160,2),ROUNDDOWN(45%*AK160-Z59,2),T166) -> #DIV/0! | AM48: Kliknij "tutaj" i przejdź do wypełnienia zestawienia kosztów
A49: C. | B49: Przewidywana data rozpoczęcia realizacji przedsięwzięcia /Data rozpoczęcia realizacji przedsięwzięcia (dzień, miesiąc (słownie) i rok). Dla przedsięwzięć, o których mowa w art. 5 ust. 1 pkt 1 i pkt 2 lit. a poprzez rozpoczęcie realizacji przedsięwzięcia rozumie się datę zawarcia umowy, o której mowa w art. 5 ust. 2 pkt 1. Data ta jest zbieżna z datą wskazywaną w pkt VI.ZC.
AM50: Przez rozpoczęcie realizacji przedsięwzięcia rozumie się zawarcie, umowy o której mowa w art. 5 ust. 2, przy czym rozpoczęcie przedsięwzięcia może nastąpić przed lub po podpisaniu Umowy o finansowe wsparcie pomiędzy Gminą z BGK, której zawarcie następuje po pozytywnym rozpatrzeniu wniosku o finansowe wsparcie
A51: D. | B51: Przewidywana data zakończenia realizacji przedsięwzięcia (dzień, miesiąc (słownie) i rok).
AM52: Przez zakończenie realizacji przedsięwzięcia rozumie się sytuację, w której, zgodnie z odrębnymi przepisami, można przystąpić do użytkowania lokali mieszkalnych lub budynków pozyskanych w wyniku przedsięwzięcia
A53: E. | B53: Przewidywana struktura finansowania przedsięwzięcia, z podziałem na | AM53: Maksymalne finansowe wsparcie nie może przekroczyć:
B54: Wyszczególnienie | Z54: Ogółem | AK54: Udział [%] | AM54: do 25 lub 45% w przypadku BB/RPBn lokali mieszkalnych przeznaczonych na wynajem art. 5
B55: Środki własne inwestora | AK55: =Z55/Z$61 -> #DIV/0!
...

Sheet Wniosek art 5a budowa
A1: Proszę wypełnić niebieskie pola, brak wypełnienia niebieskich pól może spowodować wezwanie do uzupełnienia wniosku, co wydłuży okres rozpatrzenia wniosku.
A2: Żółte pola wypełnią się automatycznie.
AM3: Uwagi, komentarze przydatne przy wypełnianiu wniosku
H4: =TODAY() -> 46184
A5: miejscowość | H5: data wniosku
A7: Wybierz właściwe | G7: Nowy wniosek | Q7: Korekta wniosku
A8: Jeżeli składasz korektę wniosku wpisz numer pisma z wezwania do uzupełnienia | AM8: Wpisz nie dotyczy jeżeli skąłdasz nowy wniosek
A9: Szanowni Państwo, przesyłając nowy wniosek w tytule sprawy (w piśmie przewodnim lub technicznym przesyłanym poprzez ePUAP/e-doręczenia wraz z wnioskiem) proszę wpisywać treść „nowy wniosek”, a jeśli przesyłana jest korekta wniosku proszę wpisać „korekta wniosku dla sprawy numer (…)”. Numer sprawy to znak pisma – wezwania do uzupełnienia. Przesyłana korespondencja do banku poprzez ePUAP lub przez e-doręczenia powinna dotyczyć jednej sprawy. Taki sposób oznakowania korespondencji pozwoli nam usprawnić obsługę Państwa wniosków. Dziękujemy za stosowanie się do powyższego.
A12: Wniosek o udzielenie wsparcia finansowego z Funduszu Dopłat w ramach realizacji przez
A13: Bank Gospodarstwa Krajowego rządowego programu budownictwa komunalnego
A14: zgodnie z przepisami ustawy z dnia 8 grudnia 2006 r. o finansowym wsparciu niektórych przedsięwzięć mieszkaniowych (t.j. Dz.U. 2024 poz. 304 z późn. zm.)
A16: I. Dane Wnioskodawcy
A17: A. | B17: Beneficjent wsparcia
A19: B. | B19: Nazwa | AM19: Nazwa wnioskodawcy powinna być zgodna z bazą REGON
A21: C. | B21: Adres wnioskodawcy [kod pocztowy, nazwa miejscowości, nazwa ulicy, numer porządkowy budynku, numer lokalu] zgodnie z nazwami miejscowości i ulicy w Rejestrze TERYT | AM21: Weryfikacji poprawności adresu można dokonać na stronie internetowej -> https://eteryt.stat.gov.pl/eTeryt/rejestr_teryt/udostepnianie_danych/baza_teryt/uzytkownicy_indywidualni/wyszukiwanie/wyszukiwanie.aspx?contrast=default
B23: Adres do doręczeń elektronicznych, o których mowa w ustawie z dnia 18 listopada 2020 r. o doręczeniach elektronicznych (Dz. U. z 2024 r. poz. 1045 i 1841). Adres do doręczeń można sprawdzić klikając w link. | AM23: Najczęściej zadawane pytania i odpowiedzi o e-Doręczeniach
A25: D. | B25: Numer identyfikacji podatkowej NIP | W25: Numer identyfikacyjny REGON | AM25: Numer NIP i numer REGON powinny być zgodne z bazą regon przypisaną do nazwy wnioskodacy
A27: E. | B27: Dane służbowe osoby bezpośrednio prowadzącej sprawę
B28: Imię i nazwisko/ nr telefonu
B30: Adres poczty elektronicznej/nr faksu
B32: Imię i nazwisko/ nr telefonu (opcjonalnie)
AM33: Wybierz nie dotyczy jeżeli, sprawę prowadzi jedna osoba
B34: Adres poczty elektronicznej/nr faksu (opcjonalnie)
AM35: Wybierz nie dotyczy jeżeli, sprawę prowadzi jedna osoba
A36: F. | B36: Nazwa inwestora
B38: Adres inwestora | Y38: Adres inwestora do doręczeń elektronicznych, o których mowa w ustawie z dnia 18 listopada 2020 r. o doręczeniach elektronicznych.
B40: Numer identyfikacji podatkowej NIP inwestora | W40: Numer identyfikacyjny REGON inwestora
B42: Numer KRS - dla podmiotów innych niż gmina, powiat lub związek międzygminny inwestora | AM42: Numer KRS powinien być zgodny z bazą KRS dla inwestora
A44: G. | B44: Numer rachunku bankowego lub rachunku prowadzonego przez spółdzielczą kasę oszczędnościowo-kredytową beneficjenta wsparcia, na który zostanie przekazane finansowe wsparcie.
T45: {=LEFT(B45,2)&" "&_xlfn.TEXTJOIN(" ",,MID(B45,{3,7,11,15,19,23},4))}
A46: II. | B46: Dane dotyczące realizowanego przedsięwzięcia
A47: A. | B47: Wnioskowana kwota finansowego wsparcia (zł)
B48: =T162 -> #DIV/0! | AM48: Kliknij "tutaj" i przejdź do wypełnienia zestawienia kosztów
A49: B. | B49: Przewidywana data rozpoczęcia realizacji przedsięwzięcia /Data rozpoczęcia realizacji przedsięwzięcia (dzień, miesiąc (słownie) i rok). Dla przedsięwzięć, o których mowa w art. 5 ust. 1 pkt 1 i pkt 2 lit. a poprzez rozpoczęcie realizacji przedsięwzięcia rozumie się datę zawarcia umowy, o której mowa w art. 5 ust. 2 pkt 1. Data ta jest zbieżna z datą wskazywaną w pkt VI.ZC.
AM50: Przez rozpoczęcie realizacji przedsięwzięcia rozumie się zawarcie, umowy o której mowa w art. 5 ust. 2, przy czym rozpoczęcie przedsięwzięcia może nastąpić przed lub po podpisaniu Umowy o finansowe wsparcie pomiędzy Gminą z BGK, której zawarcie następuje po pozytywnym rozpatrzeniu wniosku o finansowe wsparcie
A51: C. | B51: Przewidywana data zakończenia realizacji przedsięwzięcia (dzień, miesiąc (słownie) i rok).
AM52: Przez zakończenie realizacji przedsięwzięcia rozumie się sytuację, w której, zgodnie z odrębnymi przepisami, można przystąpić do użytkowania lokali mieszkalnych lub budynków pozyskanych w wyniku przedsięwzięcia
A53: E. | B53: Przewidywana struktura finansowania przedsięwzięcia, z podziałem na | AM53: Maksymalne finansowe wsparcie nie może przekroczyć:
B54: Wyszczególnienie | Z54: Ogółem (brutto) | AK54: Udział [%] | AM54: do 80% w przypadku BB lokali mieszkalnych z prawem gminy do podnajmowania art. 5a
B55: Środki własne inwestora | AK55: =Z55/Z$60 -> #DIV/0!
...

Sheet Wnioski art 5 inne
A1: Proszę wypełnić niebieskie pola, brak wypełnienia niebieskich pól może spowodować wezwanie do uzupełnienia wniosku, co wydłuży okres rozpatrzenia wniosku.
A2: Żółte pola wypełnią się automatycznie.
AM3: Uwagi, komentarze przydatne przy wypełnianiu wniosku
H4: =TODAY() -> 46184
A5: miejscowość | H5: data wniosku
A7: Wybierz właściwe | G7: Nowy wniosek | Q7: Korekta wniosku
A8: Jeżeli składasz korektę wniosku wpisz numer pisma z wezwania do uzupełnienia | AM8: Wpisz nie dotyczy jeżeli skąłdasz nowy wniosek
A9: Szanowni Państwo, przesyłając nowy wniosek w tytule sprawy (w piśmie przewodnim lub technicznym przesyłanym poprzez ePUAP/e-doręczenia wraz z wnioskiem) proszę wpisywać treść „nowy wniosek”, a jeśli przesyłana jest korekta wniosku proszę wpisać „korekta wniosku dla sprawy numer (…)”. Numer sprawy to znak pisma – wezwania do uzupełnienia. Przesyłana korespondencja do banku poprzez ePUAP lub przez e-doręczenia powinna dotyczyć jednej sprawy. Taki sposób oznakowania korespondencji pozwoli nam usprawnić obsługę Państwa wniosków. Dziękujemy za stosowanie się do powyższego.
A11: Wniosek o udzielenie wsparcia finansowego z Funduszu Dopłat w ramach realizacji przez
A12: Bank Gospodarstwa Krajowego rządowego programu budownictwa komunalnego
A13: zgodnie z przepisami ustawy z dnia 8 grudnia 2006 r. o finansowym wsparciu niektórych przedsięwzięć mieszkaniowych (t.j. Dz.U. 2024 poz. 304 z późn. zm.)
A15: I. Dane Wnioskodawcy
A16: A. | B16: Beneficjent wsparcia
A18: B. | B18: Nazwa | AM18: Nazwa wnioskodawcy powinna być zgodna z bazą REGON
A20: C. | B20: Adres wnioskodawcy [kod pocztowy, nazwa miejscowości, nazwa ulicy, numer porządkowy budynku, numer lokalu] zgodnie z nazwami miejscowości i ulicy w Rejestrze TERYT | AM20: Weryfikacji poprawności adresu można dokonać na stronie internetowej -> https://eteryt.stat.gov.pl/eTeryt/rejestr_teryt/udostepnianie_danych/baza_teryt/uzytkownicy_indywidualni/wyszukiwanie/wyszukiwanie.aspx?contrast=default
B22: Adres do doręczeń elektronicznych, o których mowa w ustawie z dnia 18 listopada 2020 r. o doręczeniach elektronicznych (Dz. U. z 2024 r. poz. 1045 i 1841). Adres do doręczeń można sprawdzić klikając w link. | AM22: Najczęściej zadawane pytania i odpowiedzi o e-Doręczeniach
A24: D. | B24: Numer identyfikacji podatkowej NIP | W24: Numer identyfikacyjny REGON | AM24: Numer NIP i numer REGON powinny być zgodne z bazą regon przypisaną do nazwy wnioskodacy
A26: E. | B26: Dane służbowe osoby bezpośrednio prowadzącej sprawę
B27: Imię i nazwisko/ nr telefonu
B29: Adres poczty elektronicznej/nr faksu
B31: Imię i nazwisko/ nr telefonu (opcjonalnie)
AM32: Wybierz nie dotyczy jeżeli, sprawę prowadzi jedna osoba
B33: Adres poczty elektronicznej/nr faksu (opcjonalnie)
AM34: Wybierz nie dotyczy jeżeli, sprawę prowadzi jedna osoba
A35: F. | B35: Nazwa inwestora
B37: Adres inwestora | Y37: Adres inwestora do doręczeń elektronicznych, o których mowa w ustawie z dnia 18 listopada 2020 r. o doręczeniach elektronicznych.
B39: Numer identyfikacji podatkowej NIP inwestora | W39: Numer identyfikacyjny REGON inwestora
B41: Numer KRS - dla podmiotów innych niż gmina, powiat lub związek międzygminny inwestora | AM41: Numer KRS powinien być zgodny z bazą KRS dla inwestora
A43: G. | B43: Numer rachunku bankowego lub rachunku prowadzonego przez spółdzielczą kasę oszczędnościowo-kredytową beneficjenta wsparcia, na który zostanie przekazane finansowe wsparcie.
T44: {=LEFT(B44,2)&" "&_xlfn.TEXTJOIN(" ",,MID(B44,{3,7,11,15,19,23},4))}
A45: II. | B45: Dane dotyczące realizowanego przedsięwzięcia
A46: A. | B46: Wnioskowana kwota finansowego wsparcia (zł)
B47: =IF(T156+Z58>ROUNDDOWN(45%*AK150,2),ROUNDDOWN(45%*AK150-Z58,2),T156) -> #DIV/0! | AM47: Kliknij "tutaj" i przejdź do wypełnienia zestawienia kosztów
A48: C. | B48: Przewidywana data rozpoczęcia realizacji przedsięwzięcia /Data rozpoczęcia realizacji przedsięwzięcia (dzień, miesiąc (słownie) i rok). Dla przedsięwzięć, o których mowa w art. 5 ust. 1 pkt 1 i pkt 2 lit. a poprzez rozpoczęcie realizacji przedsięwzięcia rozumie się datę zawarcia umowy, o której mowa w art. 5 ust. 2 pkt 1. Data ta jest zbieżna z datą wskazywaną w pkt VI.ZC.
AM49: Przez rozpoczęcie realizacji przedsięwzięcia rozumie się zawarcie, umowy o której mowa w art. 5 ust. 2, przy czym rozpoczęcie przedsięwzięcia może nastąpić przed lub po podpisaniu Umowy o finansowe wsparcie pomiędzy Gminą z BGK, której zawarcie następuje po pozytywnym rozpatrzeniu wniosku o finansowe wsparcie
A50: D. | B50: Przewidywana data zakończenia realizacji przedsięwzięcia (dzień, miesiąc (słownie) i rok).
AM51: Przez zakończenie realizacji przedsięwzięcia rozumie się sytuację, w której, zgodnie z odrębnymi przepisami, można przystąpić do użytkowania lokali mieszkalnych lub budynków pozyskanych w wyniku przedsięwzięcia
A52: E. | B52: Przewidywana struktura finansowania przedsięwzięcia, z podziałem na | AM52: Maksymalne finansowe wsparcie nie może przekroczyć:
B53: Wyszczególnienie | Z53: Ogółem | AK53: Udział [%] | AM53: do 25% lub 35% w przypadku BB/RPBn/ZSUB lokali mieszkalnych przeznaczonych na wynajem art. 5
B54: Środki własne inwestora | AK54: =Z54/Z$60 -> #DIV/0!
...

Sheet Wnioski art 5a inne
A1: Proszę wypełnić niebieskie pola, brak wypełnienia niebieskich pól może spowodować wezwanie do uzupełnienia wniosku, co wydłuży okres rozpatrzenia wniosku.
A2: Żółte pola wypełnią się automatycznie. | AM2: Uwagi, komentarze przydatne przy wypełnianiu wniosku
H4: =TODAY() -> 46184
A5: miejscowość | H5: data wniosku
A7: Wybierz właściwe | G7: Nowy wniosek | Q7: Korekta wniosku
A8: Jeżeli składasz korektę wniosku wpisz numer pisma z wezwania do uzupełnienia | AM8: Wpisz nie dotyczy jeżeli skąłdasz nowy wniosek
A9: Szanowni Państwo, przesyłając nowy wniosek w tytule sprawy (w piśmie przewodnim lub technicznym przesyłanym poprzez ePUAP/e-doręczenia wraz z wnioskiem) proszę wpisywać treść „nowy wniosek”, a jeśli przesyłana jest korekta wniosku proszę wpisać „korekta wniosku dla sprawy numer (…)”. Numer sprawy to znak pisma – wezwania do uzupełnienia. Przesyłana korespondencja do banku poprzez ePUAP lub przez e-doręczenia powinna dotyczyć jednej sprawy. Taki sposób oznakowania korespondencji pozwoli nam usprawnić obsługę Państwa wniosków. Dziękujemy za stosowanie się do powyższego.
A11: Wniosek o udzielenie wsparcia finansowego z Funduszu Dopłat w ramach realizacji przez
A12: Bank Gospodarstwa Krajowego rządowego programu budownictwa komunalnego
A13: zgodnie z przepisami ustawy z dnia 8 grudnia 2006 r. o finansowym wsparciu niektórych przedsięwzięć mieszkaniowych (t.j. Dz.U. 2024 poz. 304 z późn. zm.)
A15: I. Dane Wnioskodawcy
A16: A. | B16: Beneficjent wsparcia
A18: B. | B18: Nazwa | AM18: Nazwa wnioskodawcy powinna być zgodna z bazą REGON
A20: C. | B20: Adres wnioskodawcy [kod pocztowy, nazwa miejscowości, nazwa ulicy, numer porządkowy budynku, numer lokalu] zgodnie z nazwami miejscowości i ulicy w Rejestrze TERYT | AM20: Weryfikacji poprawności adresu można dokonać na stronie internetowej -> https://eteryt.stat.gov.pl/eTeryt/rejestr_teryt/udostepnianie_danych/baza_teryt/uzytkownicy_indywidualni/wyszukiwanie/wyszukiwanie.aspx?contrast=default
B22: Adres do doręczeń elektronicznych, o których mowa w ustawie z dnia 18 listopada 2020 r. o doręczeniach elektronicznych (Dz. U. z 2024 r. poz. 1045 i 1841). Adres do doręczeń można sprawdzić klikając w link. | AM22: Najczęściej zadawane pytania i odpowiedzi o e-Doręczeniach
A24: D. | B24: Numer identyfikacji podatkowej NIP | W24: Numer identyfikacyjny REGON | AM24: Numer NIP i numer REGON powinny być zgodne z bazą regon przypisaną do nazwy wnioskodacy
A26: E. | B26: Dane służbowe osoby bezpośrednio prowadzącej sprawę
B27: Imię i nazwisko/ nr telefonu
B29: Adres poczty elektronicznej/nr faksu
B31: Imię i nazwisko/ nr telefonu (opcjonalnie)
AM32: Wybierz nie dotyczy jeżeli, sprawę prowadzi jedna osoba
B33: Adres poczty elektronicznej/nr faksu (opcjonalnie)
AM34: Wybierz nie dotyczy jeżeli, sprawę prowadzi jedna osoba
A35: F. | B35: Nazwa inwestora
B37: Adres inwestora | Y37: Adres inwestora do doręczeń elektronicznych, o których mowa w ustawie z dnia 18 listopada 2020 r. o doręczeniach elektronicznych.
B39: Numer identyfikacji podatkowej NIP inwestora | W39: Numer identyfikacyjny REGON inwestora
B41: Numer KRS - dla podmiotów innych niż gmina, powiat lub związek międzygminny inwestora | AM41: Numer KRS powinien być zgodny z bazą KRS dla inwestora
A43: G. | B43: Numer rachunku bankowego lub rachunku prowadzonego przez spółdzielczą kasę oszczędnościowo-kredytową beneficjenta wsparcia, na który zostanie przekazane finansowe wsparcie.
T44: {=LEFT(B44,2)&" "&_xlfn.TEXTJOIN(" ",,MID(B44,{3,7,11,15,19,23},4))}
A45: II. | B45: Dane dotyczące realizowanego przedsięwzięcia
A46: A. | B46: Wnioskowana kwota finansowego wsparcia (zł)
B47: =T154 -> 0 | AM47: Kliknij "tutaj" i przejdź do wypełnienia zestawienia kosztów
A48: C. | B48: Przewidywana data rozpoczęcia realizacji przedsięwzięcia /Data rozpoczęcia realizacji przedsięwzięcia (dzień, miesiąc (słownie) i rok). Dla przedsięwzięć, o których mowa w art. 5 ust. 1 pkt 1 i pkt 2 lit. a poprzez rozpoczęcie realizacji przedsięwzięcia rozumie się datę zawarcia umowy, o której mowa w art. 5 ust. 2 pkt 1. Data ta jest zbieżna z datą wskazywaną w pkt VI.ZC.
AM49: Przez rozpoczęcie realizacji przedsięwzięcia rozumie się zawarcie, umowy o której mowa w art. 5 ust. 2, przy czym rozpoczęcie przedsięwzięcia może nastąpić przed lub po podpisaniu Umowy o finansowe wsparcie pomiędzy Gminą z BGK, której zawarcie następuje po pozytywnym rozpatrzeniu wniosku o finansowe wsparcie
A50: D. | B50: Przewidywana data zakończenia realizacji przedsięwzięcia (dzień, miesiąc (słownie) i rok).
AM51: Przez zakończenie realizacji przedsięwzięcia rozumie się sytuację, w której, zgodnie z odrębnymi przepisami, można przystąpić do użytkowania lokali mieszkalnych lub budynków pozyskanych w wyniku przedsięwzięcia
A52: E. | B52: Przewidywana struktura finansowania przedsięwzięcia, z podziałem na | AM52: Maksymalne finansowe wsparcie nie może przekroczyć:
B53: Wyszczególnienie | Z53: Ogółem | AK53: Udział [%] | AM53: do 25% lub 35% w przypadku BB/RPBn/ZSUB lokali mieszkalnych przeznaczonych na wynajem art. 5
B54: Środki własne inwestora | AK54: =Z54/Z$59 -> #DIV/0!
B55: Środki własne beneficjenta wsparcia | AK55: =Z55/Z$59 -> #DIV/0! | AM55: do 80% w przypadku BB/RPBn/ZSUB lokali mieszkalnych z prawem gminy do podnajmowania art. 5a
...

Sheet Wniosek SAN
A1: Proszę wypełnić niebieskie pola, brak wypełnienia niebieskich pól może spowodować wezwanie do uzupełnienia wniosku, co wydłuży okres rozpatrzenia wniosku.
A2: Żółte pola wypełnią się automatycznie. | AM2: Uwagi, komentarze przydatne przy wypełnianiu wniosku
H4: =TODAY() -> 46184
A5: miejscowość | H5: data wniosku
A7: Wybierz właściwe | G7: Nowy wniosek | Q7: Korekta wniosku
A8: Jeżeli składasz korektę wniosku wpisz numer pisma z wezwania do uzupełnienia | AM8: Wpisz nie dotyczy jeżeli skąłdasz nowy wniosek
A9: Szanowni Państwo, przesyłając nowy wniosek w tytule sprawy (w piśmie przewodnim lub technicznym przesyłanym poprzez ePUAP/e-doręczenia wraz z wnioskiem) proszę wpisywać treść „nowy wniosek”, a jeśli przesyłana jest korekta wniosku proszę wpisać „korekta wniosku dla sprawy numer (…)”. Numer sprawy to znak pisma – wezwania do uzupełnienia. Przesyłana korespondencja do banku poprzez ePUAP lub przez e-doręczenia powinna dotyczyć jednej sprawy. Taki sposób oznakowania korespondencji pozwoli nam usprawnić obsługę Państwa wniosków. Dziękujemy za stosowanie się do powyższego.
A11: Wniosek o udzielenie wsparcia finansowego z Funduszu Dopłat w ramach realizacji przez
A12: Bank Gospodarstwa Krajowego rządowego programu budownictwa komunalnego
A13: zgodnie z przepisami ustawy z dnia 8 grudnia 2006 r. o finansowym wsparciu niektórych przedsięwzięć mieszkaniowych (t.j. Dz.U. 2024 poz. 304 z późn. zm.)
A15: I. Dane Wnioskodawcy
A16: A. | B16: Beneficjent wsparcia
A18: B. | B18: Nazwa | AM18: Nazwa wnioskodawcy powinna być zgodna z bazą REGON
A20: C. | B20: Adres wnioskodawcy [kod pocztowy, nazwa miejscowości, nazwa ulicy, numer porządkowy budynku, numer lokalu] zgodnie z nazwami miejscowości i ulicy w Rejestrze TERYT | AM20: Weryfikacji poprawności adresu można dokonać na stronie internetowej -> https://eteryt.stat.gov.pl/eTeryt/rejestr_teryt/udostepnianie_danych/baza_teryt/uzytkownicy_indywidualni/wyszukiwanie/wyszukiwanie.aspx?contrast=default
B22: Adres do doręczeń elektronicznych, o których mowa w ustawie z dnia 18 listopada 2020 r. o doręczeniach elektronicznych (Dz. U. z 2024 r. poz. 1045 i 1841). Adres do doręczeń można sprawdzić klikając w link. | AM22: Najczęściej zadawane pytania i odpowiedzi o e-Doręczeniach
A24: D. | B24: Numer identyfikacji podatkowej NIP | W24: Numer identyfikacyjny REGON | AM24: Numer NIP i numer REGON powinny być zgodne z bazą regon przypisaną do nazwy wnioskodacy
A26: E. | B26: Dane służbowe osoby bezpośrednio prowadzącej sprawę
B27: Imię i nazwisko/ nr telefonu
B29: Adres poczty elektronicznej/nr faksu
B31: Imię i nazwisko/ nr telefonu (opcjonalnie)
AM32: Wybierz nie dotyczy jeżeli, sprawę prowadzi jedna osoba
B33: Adres poczty elektronicznej/nr faksu (opcjonalnie)
AM34: Wybierz nie dotyczy jeżeli, sprawę prowadzi jedna osoba
A35: F. | B35: Nazwa inwestora
B37: Adres inwestora | Y37: Adres inwestora do doręczeń elektronicznych, o których mowa w ustawie z dnia 18 listopada 2020 r. o doręczeniach elektronicznych.
B39: Numer identyfikacji podatkowej NIP inwestora | W39: Numer identyfikacyjny REGON inwestora
B41: Numer KRS - dla podmiotów innych niż gmina, powiat lub związek międzygminny inwestora | AM41: Numer KRS powinien być zgodny z bazą KRS dla inwestora
A43: G. | B43: Numer rachunku bankowego lub rachunku prowadzonego przez spółdzielczą kasę oszczędnościowo-kredytową beneficjenta wsparcia, na który zostanie przekazane finansowe wsparcie.
T44: {=LEFT(B44,2)&" "&_xlfn.TEXTJOIN(" ",,MID(B44,{3,7,11,15,19,23},4))}
A45: II. | B45: Dane dotyczące realizowanego przedsięwzięcia
A46: A. | B46: Wnioskowana kwota finansowego wsparcia (zł)
B47: =T141 -> 0 | AM47: Kliknij "tutaj" i przejdź do wypełnienia zestawienia kosztów
A48: C. | B48: Przewidywana data rozpoczęcia realizacji przedsięwzięcia / Data rozpoczęcia realizacji przedsięwzięcia (dzień, miesiąc (słownie) i rok).
AM49: Przez rozpoczęcie realizacji przedsięwzięcia rozumie się zawarcie, umowy o której mowa w art. 5 ust. 2, przy czym rozpoczęcie przedsięwzięcia może nastąpić przed lub po podpisaniu Umowy o finansowe wsparcie pomiędzy Gminą z BGK, której zawarcie następuje po pozytywnym rozpatrzeniu wniosku o finansowe wsparcie
A50: D. | B50: Przewidywana data zakończenia realizacji przedsięwzięcia, a w przypadku przedsięwzięcia obejmującego remont lub przebudowę części budynku w rozbiciu na poszczególne lokale mieszkalne (dzień, miesiąc (słownie) i rok) - data dla lokalu którego remont zakończy się jako ostatni.
AM51: Przez zakończenie realizacji przedsięwzięcia rozumie się sytuację, w której, zgodnie z odrębnymi przepisami, można przystąpić do użytkowania lokali mieszkalnych lub budynków pozyskanych w wyniku przedsięwzięcia
A52: E. | B52: Przewidywana struktura finansowania przedsięwzięcia, z podziałem na
B53: Wyszczególnienie | Z53: Ogółem (brutto) | AK53: Udział [%]
B54: Środki własne inwestora | AK54: =Z54/Z$58 -> #DIV/0!
B55: Środki własne beneficjenta wsparcia | AK55: =Z55/Z$58 -> #DIV/0!
...

Sheet Noclegownia
A1: Proszę wypełnić niebieskie pola, brak wypełnienia niebieskich pól może spowodować wezwanie do uzupełnienia wniosku, co wydłuży okres rozpatrzenia wniosku.
A2: Żółte pola wypełnią się automatycznie.
AM3: Uwagi, komentarze przydatne przy wypełnianiu wniosku
H4: =TODAY() -> 46184
A5: miejscowość | H5: data wniosku
A7: Wybierz właściwe | G7: Nowy wniosek | Q7: Korekta wniosku
A8: Jeżeli składasz korektę wniosku wpisz numer pisma z wezwania do uzupełnienia | AM8: Wpisz nie dotyczy jeżeli skąłdasz nowy wniosek
A9: Szanowni Państwo, przesyłając nowy wniosek w tytule sprawy (w piśmie przewodnim lub technicznym przesyłanym poprzez ePUAP/e-doręczenia wraz z wnioskiem) proszę wpisywać treść „nowy wniosek”, a jeśli przesyłana jest korekta wniosku proszę wpisać „korekta wniosku dla sprawy numer (…)”. Numer sprawy to znak pisma – wezwania do uzupełnienia. Przesyłana korespondencja do banku poprzez ePUAP lub przez e-doręczenia powinna dotyczyć jednej sprawy. Taki sposób oznakowania korespondencji pozwoli nam usprawnić obsługę Państwa wniosków. Dziękujemy za stosowanie się do powyższego.
A11: Wniosek o udzielenie wsparcia finansowego z Funduszu Dopłat w ramach realizacji przez
A12: Bank Gospodarstwa Krajowego rządowego programu budownictwa komunalnego
A13: zgodnie z przepisami ustawy z dnia 8 grudnia 2006 r. o finansowym wsparciu niektórych przedsięwzięć mieszkaniowych (t.j. Dz.U. 2024 poz. 304 z późn. zm.)
A15: I. Dane Wnioskodawcy
A16: A. | B16: Beneficjent wsparcia
A18: B. | B18: Nazwa | AM18: Nazwa wnioskodawcy powinna być zgodna z bazą REGON
A20: C. | B20: Adres wnioskodawcy [kod pocztowy, nazwa miejscowości, nazwa ulicy, numer porządkowy budynku, numer lokalu] zgodnie z nazwami miejscowości i ulicy w Rejestrze TERYT | AM20: Weryfikacji poprawności adresu można dokonać na stronie internetowej -> https://eteryt.stat.gov.pl/eTeryt/rejestr_teryt/udostepnianie_danych/baza_teryt/uzytkownicy_indywidualni/wyszukiwanie/wyszukiwanie.aspx?contrast=default
B22: Adres do doręczeń elektronicznych, o których mowa w ustawie z dnia 18 listopada 2020 r. o doręczeniach elektronicznych (Dz. U. z 2024 r. poz. 1045 i 1841). Adres do doręczeń można sprawdzić klikając w link. | AM22: Najczęściej zadawane pytania i odpowiedzi o e-Doręczeniach
A24: D. | B24: Numer identyfikacji podatkowej NIP | W24: Numer identyfikacyjny REGON | AM24: Numer NIP i numer REGON powinny być zgodne z bazą regon przypisaną do nazwy wnioskodacy
B26: Numer KRS - dla podmiotów innych niż gmina, powiat lub związek międzygminny | AM26: Numer KRS powinien być zgodny z bazą KRS dla wnioskodawcy
A28: E. | B28: Dane służbowe osoby bezpośrednio prowadzącej sprawę
B29: Imię i nazwisko/ nr telefonu
B31: Adres poczty elektronicznej
B33: Imię i nazwisko/ nr telefonu (opcjonalnie)
AM34: Wybierz nie dotyczy jeżeli, sprawę prowadzi jedna osoba
B35: Adres poczty elektronicznej (opcjonalnie)
AM36: Wybierz nie dotyczy jeżeli, sprawę prowadzi jedna osoba
A37: G. | B37: Numer rachunku bankowego lub rachunku prowadzonego przez spółdzielczą kasę oszczędnościowo-kredytową beneficjenta wsparcia, na który zostanie przekazane finansowe wsparcie.
T38: {=LEFT(B38,2)&" "&_xlfn.TEXTJOIN(" ",,MID(B38,{3,7,11,15,19,23},4))}
A39: II. | B39: Dane dotyczące realizowanego przedsięwzięcia
A40: A. | B40: Wnioskowana kwota finansowego wsparcia (zł)
B41: =T141 -> #DIV/0! | AM41: Kliknij "tutaj" i przejdź do wypełnienia zestawienia kosztów
A42: C. | B42: Przewidywana data rozpoczęcia realizacji przedsięwzięcia / Data rozpoczęcia realizacji przedsięwzięcia (dzień, miesiąc (słownie) i rok).
AM43: Data rozpoczęcia realizacji przedsięwzięcia nie może być późniejsza niż okres ważności pozwolenia na budowę
A44: D. | B44: Przewidywana data zakończenia realizacji przedsięwzięcia (dzień, miesiąc (słownie) i rok).
AM45: Data zakończenie realizacji nie może być dłuższa niż 36 miesiący od przewidywanej daty rozpoczęcia przedsięwzięcia
A46: E. | B46: Przewidywana struktura finansowania przedsięwzięcia, z podziałem na
B47: Wyszczególnienie | Z47: Ogółem (brutto) | AK47: Udział [%]
B48: Środki własne beneficjenta wsparcia | AK48: =ROUND(Z48/Z$51,5) -> #DIV/0!
B49: Wsparcie finansowe na podstawie ustawy | Z49: =B$41 -> #DIV/0! | AK49: =ROUND(Z49/Z$51,5) -> #DIV/0! | AM49: Maksymalne finansowe wsparcie wynosi do 80%
B50: Inne źródła | AK50: =ROUND(Z50/Z$51,5) -> #DIV/0! | AM50: oraz dodatkowo 5 % w przypadku przedsięwzięcia, o którym mowa w art. 15 ust. 1 pkt 5 lit. a ustawy o rewitalizacji
B51: Łącznie | Z51: =SUM(Z48:AJ50) -> #DIV/0! | AK51: =SUM(AK48:AL50) -> #DIV/0! | AM51: Łącznie powinno zsumować się na kwalifikowany koszt przedsięwzięcia
...

Sheet Schronisko
A1: Proszę wypełnić niebieskie pola, brak wypełnienia niebieskich pól może spowodować wezwanie do uzupełnienia wniosku, co wydłuży okres rozpatrzenia wniosku.
A2: Żółte pola wypełnią się automatycznie.
AM3: Uwagi, komentarze przydatne przy wypełnianiu wniosku
H4: =TODAY() -> 46184
A5: miejscowość | H5: data wniosku
A7: Wybierz właściwe | G7: Nowy wniosek | Q7: Korekta wniosku
A8: Jeżeli składasz korektę wniosku wpisz numer pisma z wezwania do uzupełnienia | AM8: Wpisz nie dotyczy jeżeli skąłdasz nowy wniosek
A9: Szanowni Państwo, przesyłając nowy wniosek w tytule sprawy (w piśmie przewodnim lub technicznym przesyłanym poprzez ePUAP/e-doręczenia wraz z wnioskiem) proszę wpisywać treść „nowy wniosek”, a jeśli przesyłana jest korekta wniosku proszę wpisać „korekta wniosku dla sprawy numer (…)”. Numer sprawy to znak pisma – wezwania do uzupełnienia. Przesyłana korespondencja do banku poprzez ePUAP lub przez e-doręczenia powinna dotyczyć jednej sprawy. Taki sposób oznakowania korespondencji pozwoli nam usprawnić obsługę Państwa wniosków. Dziękujemy za stosowanie się do powyższego.
A11: Wniosek o udzielenie wsparcia finansowego z Funduszu Dopłat w ramach realizacji przez
A12: Bank Gospodarstwa Krajowego rządowego programu budownictwa komunalnego
A13: zgodnie z przepisami ustawy z dnia 8 grudnia 2006 r. o finansowym wsparciu niektórych przedsięwzięć mieszkaniowych (t.j. Dz.U. 2024 poz. 304 z późn. zm.)
A15: I. Dane Wnioskodawcy
A16: A. | B16: Beneficjent wsparcia
A18: B. | B18: Nazwa | AM18: Nazwa wnioskodawcy powinna być zgodna z bazą REGON
A20: C. | B20: Adres wnioskodawcy [kod pocztowy, nazwa miejscowości, nazwa ulicy, numer porządkowy budynku, numer lokalu] zgodnie z nazwami miejscowości i ulicy w Rejestrze TERYT | AM20: Weryfikacji poprawności adresu można dokonać na stronie internetowej -> https://eteryt.stat.gov.pl/eTeryt/rejestr_teryt/udostepnianie_danych/baza_teryt/uzytkownicy_indywidualni/wyszukiwanie/wyszukiwanie.aspx?contrast=default
B22: Adres do doręczeń elektronicznych, o których mowa w ustawie z dnia 18 listopada 2020 r. o doręczeniach elektronicznych (Dz. U. z 2024 r. poz. 1045 i 1841). Adres do doręczeń można sprawdzić klikając w link. | AM22: Najczęściej zadawane pytania i odpowiedzi o e-Doręczeniach
A24: D. | B24: Numer identyfikacji podatkowej NIP | W24: Numer identyfikacyjny REGON | AM24: Numer NIP i numer REGON powinny być zgodne z bazą regon przypisaną do nazwy wnioskodacy
B26: Numer KRS - dla podmiotów innych niż gmina, powiat lub związek międzygminny | AM26: Numer KRS powinien być zgodny z bazą KRS dla wnioskodawcy
A28: E. | B28: Dane służbowe osoby bezpośrednio prowadzącej sprawę
B29: Imię i nazwisko/ nr telefonu
B31: Adres poczty elektronicznej
B33: Imię i nazwisko/ nr telefonu (opcjonalnie)
AM34: Wybierz nie dotyczy jeżeli, sprawę prowadzi jedna osoba
B35: Adres poczty elektronicznej (opcjonalnie)
AM36: Wybierz nie dotyczy jeżeli, sprawę prowadzi jedna osoba
A37: G. | B37: Numer rachunku bankowego lub rachunku prowadzonego przez spółdzielczą kasę oszczędnościowo-kredytową beneficjenta wsparcia, na który zostanie przekazane finansowe wsparcie.
T38: {=LEFT(B38,2)&" "&_xlfn.TEXTJOIN(" ",,MID(B38,{3,7,11,15,19,23},4))}
A39: II. | B39: Dane dotyczące realizowanego przedsięwzięcia
A40: A. | B40: Wnioskowana kwota finansowego wsparcia (zł)
B41: =T141 -> #DIV/0! | AM41: Kliknij "tutaj" i przejdź do wypełnienia zestawienia kosztów
A42: B. | B42: Przewidywana data rozpoczęcia realizacji przedsięwzięcia / Data rozpoczęcia realizacji przedsięwzięcia (dzień, miesiąc (słownie) i rok).
AM43: Data rozpoczęcia realizacji przedsięwzięcia nie może być późniejsza niż okres ważności pozwolenia na budowę
A44: C. | B44: Przewidywana data zakończenia realizacji przedsięwzięcia (dzień, miesiąc (słownie) i rok).
AM45: Data zakończenie realizacji nie może być dłuższa niż 36 miesiący od przewidywanej daty rozpoczęcia przedsięwzięcia
A46: E. | B46: Przewidywana struktura finansowania przedsięwzięcia, z podziałem na
B47: Wyszczególnienie | Z47: Ogółem (brutto) | AK47: Udział [%]
B48: Środki własne beneficjenta wsparcia | AK48: =ROUND(Z48/Z$51,5) -> #DIV/0!
B49: Wsparcie finansowe na podstawie ustawy | Z49: =B$41 -> #DIV/0! | AK49: =ROUND(Z49/Z$51,5) -> #DIV/0! | AM49: Maksymalne finansowe wsparcie wynosi do 80%
