Workbook
Name _edn1: Słowniki!$H$5
Name _edn10: Słowniki!$J$43
Name _edn11: Słowniki!$J$44
Name _edn12: Słowniki!$J$45
Name _edn2: Słowniki!$J$35
Name _edn3: Słowniki!$J$36
Name _edn4: Słowniki!$J$37
Name _edn5: Słowniki!$J$38
Name _edn6: Słowniki!$J$39
Name _edn7: Słowniki!$J$40
Name _edn8: Słowniki!$J$41
Name _edn9: Słowniki!$J$42
Name _ednref1: Słowniki!$H$2
Name _ednref10: Słowniki!#REF!
Name _ednref11: Słowniki!#REF!
Name _ednref12: Słowniki!#REF!
Name _ednref2: Słowniki!#REF!
Name _ednref3: Słowniki!#REF!
Name _ednref4: Słowniki!#REF!
Name _ednref5: Słowniki!#REF!
Name _ednref6: Słowniki!#REF!
Name _ednref7: Słowniki!#REF!
Name _ednref8: Słowniki!#REF!
Name _ednref9: Słowniki!#REF!
Name _ftn1: Słowniki!$D$33
Name _ftnref1: Słowniki!$D$16
Name _Hlk108901557: Słowniki!$D$30
Name _Hlk53499634: Słowniki!$D$22
Name _Hlk59545887: Słowniki!$E$18
Name _Hlk63413254: Słowniki!$D$5
Name ListaRob: 'Słownik woj_powiaty'!$E$3:$F$381

Sheet Wybór
A1: Rodzaj zasobu | B1: Rodzaj przedsięwzięcia*** | C1: Beneficjent wsparcia
C2: Uczelnia publiczna
C3: Wysokość finansowego wsparcia
A4: pomieszczenia służące zaspokajaniu potrzeb mieszkaniowych studentów i doktorantów | B4: Budowa budynku | C4: 0.8
B5: Remont lub przebudowa budynku | C5: 80%*
B6: Kupnie budynku mieszkalnego albo udziału we własności budynku mieszkalnego | C6: 0.8
A8: Objaśnienia do tabeli:
A9: * 10% wysokość finansowego wsparcia podwyższa się o 10 punktów procentowych, jeżeli budynek jest wpisany do rejestru zabytków lub znajduje się na obszarze wpisanym do rejestru zabytków

Sheet Wniosek art 4a budowa
A1: Proszę wypełnić niebieskie pola, brak wypełnienia niebieskich pól może spowodować wezwanie do uzupełnienia wniosku, co wydłuży okres rozpatrzenia wniosku.
A2: Żółte pola wypełnią się automatycznie.
AM3: Uwagi, komentarze przydatne przy wypełnianiu wniosku
H4: =TODAY() -> 46059
A5: miejscowość | H5: data wniosku
A7: Wybierz właściwe | G7: Nowy wniosek | R7: Korekta wniosku
A8: Jeżeli składasz korektę wniosku wpisz numer pisma z wezwania do uzupełnienia | AM8: Wpisz nie dotyczy jeżeli skąłdasz nowy wniosek
A9: Szanowni Państwo, przesyłając nowy wniosek w tytule sprawy (w piśmie przewodnim lub technicznym przesyłanym poprzez ePUAP/e-doręczenia wraz z wnioskiem) proszę wpisywać treść „nowy wniosek”, a jeśli przesyłana jest korekta wniosku proszę wpisać „korekta wniosku dla sprawy numer (…)”. Numer sprawy to znak pisma – wezwania do uzupełnienia. Przesyłana korespondencja do banku poprzez ePUAP/e-doręczenia powinna dotyczyć jednej sprawy. Taki sposób oznakowania korespondencji pozwoli nam usprawnić obsługę Państwa wniosków. Dziękujemy za stosowanie się do powyższego.
A11: Wniosek o udzielenie wsparcia finansowego z Funduszu Dopłat w ramach realizacji przez
A12: Bank Gospodarstwa Krajowego rządowego programu budownictwa komunalnego
A13: zgodnie z przepisami ustawy z dnia 8 grudnia 2006 r. o finansowym wsparciu niektórych przedsięwzięć mieszkaniowych (t.j. Dz.U. 2024 poz. 304 z późn. zm.)
A15: I. Dane Wnioskodawcy
A16: A. | B16: Beneficjent wsparcia
B17: Uczelnia publiczna
A18: B. | B18: Nazwa | AM18: Nazwa wnioskodawcy powinna być zgodna z bazą REGON
A20: C. | B20: Adres wnioskodawcy [kod pocztowy, nazwa miejscowości, nazwa ulicy, numer porządkowy budynku, numer lokalu] zgodnie z nazwami miejscowości i ulicy w Rejestrze TERYT | AM20: Weryfikacji poprawności adresu można dokonać na stronie internetowej -> https://eteryt.stat.gov.pl/eTeryt/rejestr_teryt/udostepnianie_danych/baza_teryt/uzytkownicy_indywidualni/wyszukiwanie/wyszukiwanie.aspx?contrast=default
B22: Adres do doręczeń elektronicznych, o których mowa w ustawie z dnia 18 listopada 2020 r. o doręczeniach elektronicznych (Dz. U. z 2024 r. poz. 1045 i 1841). Adres do doręczeń można sprawdzić klikając w link. | AM22: Najczęściej zadawane pytania i odpowiedzi o e-Doręczeniach
A24: D. | B24: Numer identyfikacji podatkowej NIP | W24: Numer identyfikacyjny REGON | AM24: Numer NIP i numer REGON powinny być zgodne z bazą regon przypisaną do nazwy wnioskodacy
A26: E. | B26: Dane służbowe osoby bezpośrednio prowadzącej sprawę
B27: Imię i nazwisko/ nr telefonu
B29: Adres poczty elektronicznej
B31: Imię i nazwisko/ nr telefonu (opcjonalnie)
AM32: Wybierz nie dotyczy jeżeli, sprawę prowadzi jedna osoba
B33: Adres poczty elektronicznej (opcjonalnie)
AM34: Wybierz nie dotyczy jeżeli, sprawę prowadzi jedna osoba
A35: G. | B35: Numer rachunku bankowego lub rachunku prowadzonego przez spółdzielczą kasę oszczędnościowo-kredytową beneficjenta wsparcia, na który zostanie przekazane finansowe wsparcie.
T36: {=LEFT(B36,2)&" "&_xlfn.TEXTJOIN(" ",,MID(B36,{3,7,11,15,19,23},4))}
A37: II. | B37: Dane dotyczące realizowanego przedsięwzięcia
A38: A. | B38: Wnioskowana kwota finansowego wsparcia [zł]
B39: =T136 -> #DIV/0! | AM39: Kliknij "tutaj" i przejdź do wypełnienia zestawienia kosztów
A40: C. | B40: Przewidywana data rozpoczęcia realizacji przedsięwzięcia /Data rozpoczęcia realizacji przedsięwzięcia (dzień, miesiąc (słownie) i rok).
AM41: Data rozpoczęcia realizacji przedsięwzięcia nie może być późniejsza niż okres ważności pozwolenia na budowę
A42: D. | B42: Przewidywana data zakończenia realizacji przedsięwzięcia (dzień, miesiąc (słownie) i rok).
AM43: Data zakończenie realizacji nie może być dłuższa niż 36 miesiący od przewidywanej daty rozpoczęcia przedsięwzięcia
A44: E. | B44: Przewidywana struktura finansowania przedsięwzięcia, z podziałem na
B45: Wyszczególnienie | Z45: Ogółem (brutto) | AK45: Udział [%]
B46: Środki własne beneficjenta wsparcia | AK46: =ROUND(Z46/Z$49,5) -> #DIV/0! | AM46: Maksymalne finansowe wsparcie jest uzależnione od rodzaju przedsięwzięcia i wynosi dla budowy 80%
B47: Wsparcie finansowe na podstawie ustawy | Z47: =B$39 -> #DIV/0! | AK47: =ROUND(Z47/Z$49,5) -> #DIV/0!
B48: Inne źródła | AK48: =ROUND(Z48/Z$49,5) -> #DIV/0!
B49: Łącznie | Z49: =SUM(Z46:AJ48) -> #DIV/0! | AK49: =SUM(AK46:AL48) -> #DIV/0! | AM49: Łącznie powinno zsumować się na kwalifikowany koszt przedsięwzięcia
...

Sheet Wniosek art. 4a remont_przebudo
A1: Proszę wypełnić niebieskie pola, brak wypełnienia niebieskich pól może spowodować wezwanie do uzupełnienia wniosku, co wydłuży okres rozpatrzenia wniosku.
A2: Żółte pola wypełnią się automatycznie.
AM3: Uwagi, komentarze przydatne przy wypełnianiu wniosku
H4: =TODAY() -> 46059
A5: miejscowość | H5: data wniosku
A7: Wybierz właściwe | G7: Nowy wniosek | Q7: Korekta wniosku
A8: Jeżeli składasz korektę wniosku wpisz numer pisma z wezwania do uzupełnienia | AM8: Wpisz nie dotyczy jeżeli skąłdasz nowy wniosek
A9: Szanowni Państwo, przesyłając nowy wniosek w tytule sprawy (w piśmie przewodnim lub technicznym przesyłanym poprzez ePUAP/e-doręczenia wraz z wnioskiem) proszę wpisywać treść „nowy wniosek”, a jeśli przesyłana jest korekta wniosku proszę wpisać „korekta wniosku dla sprawy numer (…)”. Numer sprawy to znak pisma – wezwania do uzupełnienia. Przesyłana korespondencja do banku poprzez ePUAP/e-doręczenia powinna dotyczyć jednej sprawy. Taki sposób oznakowania korespondencji pozwoli nam usprawnić obsługę Państwa wniosków. Dziękujemy za stosowanie się do powyższego.
A11: Wniosek o udzielenie wsparcia finansowego z Funduszu Dopłat w ramach realizacji przez
A12: Bank Gospodarstwa Krajowego rządowego programu budownictwa komunalnego
A13: zgodnie z przepisami ustawy z dnia 8 grudnia 2006 r. o finansowym wsparciu niektórych przedsięwzięć mieszkaniowych (t.j. Dz.U. 2024 poz. 304 z późn. zm.)
A15: I. Dane Wnioskodawcy
A16: A. | B16: Beneficjent wsparcia
B17: Uczelnia publiczna
A18: B. | B18: Nazwa | AM18: Nazwa wnioskodawcy powinna być zgodna z bazą REGON
A20: C. | B20: Adres wnioskodawcy [kod pocztowy, nazwa miejscowości, nazwa ulicy, numer porządkowy budynku, numer lokalu] zgodnie z nazwami miejscowości i ulicy w Rejestrze TERYT | AM20: Weryfikacji poprawności adresu można dokonać na stronie internetowej -> https://eteryt.stat.gov.pl/eTeryt/rejestr_teryt/udostepnianie_danych/baza_teryt/uzytkownicy_indywidualni/wyszukiwanie/wyszukiwanie.aspx?contrast=default
B22: Adres do doręczeń elektronicznych, o których mowa w ustawie z dnia 18 listopada 2020 r. o doręczeniach elektronicznych (Dz. U. z 2024 r. poz. 1045 i 1841). Adres do doręczeń można sprawdzić klikając w link. | AM22: Najczęściej zadawane pytania i odpowiedzi o e-Doręczeniach
A24: D. | B24: Numer identyfikacji podatkowej NIP | W24: Numer identyfikacyjny REGON | AM24: Numer NIP i numer REGON powinny być zgodne z bazą regon przypisaną do nazwy wnioskodacy
A26: E. | B26: Dane służbowe osoby bezpośrednio prowadzącej sprawę
B27: Imię i nazwisko/ nr telefonu
B29: Adres poczty elektronicznej
AM30: Wybierz nie dotyczy jeżeli, sprawę prowadzi jedna osoba
B31: Imię i nazwisko/ nr telefonu (opcjonalnie)
AM32: Wybierz nie dotyczy jeżeli, sprawę prowadzi jedna osoba
B33: Adres poczty elektronicznej (opcjonalnie)
A35: G. | B35: Numer rachunku bankowego lub rachunku prowadzonego przez spółdzielczą kasę oszczędnościowo-kredytową beneficjenta wsparcia, na który zostanie przekazane finansowe wsparcie.
T36: {=LEFT(B36,2)&" "&_xlfn.TEXTJOIN(" ",,MID(B36,{3,7,11,15,19,23},4))}
A37: II. | B37: Dane dotyczące realizowanego przedsięwzięcia
A38: A. | B38: Wnioskowana kwota finansowego wsparcia [zł]
B39: =T114 -> 0 | AM39: Kliknij "tutaj" i przejdź do wypełnienia zestawienia kosztów
A40: C. | B40: Przewidywana data rozpoczęcia realizacji przedsięwzięcia /Data rozpoczęcia realizacji przedsięwzięcia (dzień, miesiąc (słownie) i rok).
A42: D. | B42: Przewidywana data zakończenia realizacji przedsięwzięcia, a w przypadku przedsięwzięcia obejmującego remont lub przebudowę części budynku w rozbiciu na poszczególne lokale mieszkalne (dzień, miesiąc (słownie) i rok) - data dla lokalu którego remont zakończy się jako ostatni.
AM43: Data zakończenie realizacji nie może być dłuższa niż 36 miesiący od przewidywanej daty rozpoczęcia przedsięwzięcia
A44: E. | B44: Przewidywana struktura finansowania przedsięwzięcia, z podziałem na
B45: Wyszczególnienie | Z45: Ogółem (brutto) | AK45: Udział [%]
B46: Środki własne beneficjenta wsparcia | AK46: =ROUND(Z46/Z$49,5) -> #DIV/0!
B47: Wsparcie finansowe na podstawie ustawy | Z47: =B$39 -> 0 | AK47: =ROUND(Z47/Z$49,5) -> #DIV/0!
B48: Inne źródła | AK48: =ROUND(Z48/Z$49,5) -> #DIV/0!
B49: Łącznie | Z49: =SUM(Z46:AJ48) -> 0 | AK49: =SUM(AK46:AL48) -> #DIV/0! | AM49: Łącznie powinno zsumować się na kwalifikowany koszt przedsięwzięcia
A50: K. | B50: W przypadku, o którym mowa w art. 13 ust. 5 ustawy, informacja o wpisie budynku lub obszaru, na którym się znajduje, do rejestru zabytków, w tym o dacie wydania decyzji, dacie prawomocności, numerze decyzji i organie, który wydał decyzję.
...

Sheet Wniosek art. 4a kupno
A1: Proszę wypełnić niebieskie pola, brak wypełnienia niebieskich pól może spowodować wezwanie do uzupełnienia wniosku, co wydłuży okres rozpatrzenia wniosku.
A2: Żółte pola wypełnią się automatycznie.
AM3: Uwagi, komentarze przydatne przy wypełnianiu wniosku
H4: =TODAY() -> 46059
A5: miejscowość | H5: data wniosku
A7: Wybierz właściwe | G7: Nowy wniosek | Q7: Korekta wniosku
A8: Jeżeli składasz korektę wniosku wpisz numer pisma z wezwania do uzupełnienia | AM8: Wpisz nie dotyczy jeżeli skąłdasz nowy wniosek
A9: Szanowni Państwo, przesyłając nowy wniosek w tytule sprawy (w piśmie przewodnim lub technicznym przesyłanym poprzez ePUAP/e-doręczenia wraz z wnioskiem) proszę wpisywać treść „nowy wniosek”, a jeśli przesyłana jest korekta wniosku proszę wpisać „korekta wniosku dla sprawy numer (…)”. Numer sprawy to znak pisma – wezwania do uzupełnienia. Przesyłana korespondencja do banku poprzez ePUAP/e-doręczenia powinna dotyczyć jednej sprawy. Taki sposób oznakowania korespondencji pozwoli nam usprawnić obsługę Państwa wniosków. Dziękujemy za stosowanie się do powyższego.
A11: Wniosek o udzielenie wsparcia finansowego z Funduszu Dopłat w ramach realizacji przez
A12: Bank Gospodarstwa Krajowego rządowego programu budownictwa komunalnego
A13: zgodnie z przepisami ustawy z dnia 8 grudnia 2006 r. o finansowym wsparciu niektórych przedsięwzięć mieszkaniowych (t.j. Dz.U. 2024 poz. 304 z późn. zm.)
A15: I. Dane Wnioskodawcy
A16: A. | B16: Beneficjent wsparcia
B17: Uczelnia publiczna
A18: B. | B18: Nazwa | AM18: Nazwa wnioskodawcy powinna być zgodna z bazą REGON
A20: C. | B20: Adres wnioskodawcy [kod pocztowy, nazwa miejscowości, nazwa ulicy, numer porządkowy budynku, numer lokalu] zgodnie z nazwami miejscowości i ulicy w Rejestrze TERYT | AM20: Weryfikacji poprawności adresu można dokonać na stronie internetowej -> https://eteryt.stat.gov.pl/eTeryt/rejestr_teryt/udostepnianie_danych/baza_teryt/uzytkownicy_indywidualni/wyszukiwanie/wyszukiwanie.aspx?contrast=default
B22: Adres do doręczeń elektronicznych, o których mowa w ustawie z dnia 18 listopada 2020 r. o doręczeniach elektronicznych (Dz. U. z 2024 r. poz. 1045 i 1841). Adres do doręczeń można sprawdzić klikając w link. | AM22: Najczęściej zadawane pytania i odpowiedzi o e-Doręczeniach
A24: D. | B24: Numer identyfikacji podatkowej NIP | W24: Numer identyfikacyjny w krajowym rejestrze urzędowym podmiotów gospodarki narodowej REGON | AM24: Numer NIP i numer REGON powinny być zgodne z bazą regon przypisaną do nazwy wnioskodacy
A26: E. | B26: Dane służbowe osoby bezpośrednio prowadzącej sprawę
B27: Imię i nazwisko/ nr telefonu
B29: Adres poczty elektronicznej
AM30: Wybierz nie dotyczy jeżeli, sprawę prowadzi jedna osoba
B31: Imię i nazwisko/ nr telefonu (opcjonalnie)
AM32: Wybierz nie dotyczy jeżeli, sprawę prowadzi jedna osoba
B33: Adres poczty elektronicznej (opcjonalnie)
A35: G. | B35: Numer rachunku bankowego lub rachunku prowadzonego przez spółdzielczą kasę oszczędnościowo-kredytową beneficjenta wsparcia, na który zostanie przekazane finansowe wsparcie.
T36: {=LEFT(B36,2)&" "&_xlfn.TEXTJOIN(" ",,MID(B36,{3,7,11,15,19,23},4))}
A37: II. | B37: Dane dotyczące realizowanego przedsięwzięcia
A38: A. | B38: Wnioskowana kwota finansowego wsparcia [zł]
B39: =T98 -> #DIV/0! | AM39: Kliknij "tutaj" i przejdź do wypełnienia zestawienia kosztów
A40: C. | B40: Przewidywana data rozpoczęcia realizacji przedsięwzięcia /Data rozpoczęcia realizacji przedsięwzięcia (dzień, miesiąc (słownie) i rok). | AM40: Finansowe wsparcie może być udzielone na realizację przedsięwzięcia rozpoczętego przed dniem zawarcia umowy, o której mowa w art. 12, jeżeli wniosek o finansowe wsparcie, o którym mowa w art. 8, został złożony przez beneficjenta wsparcia przed upływem 12 miesięcy od dnia rozpoczęcia przedsięwzięcia
A42: D. | B42: Przewidywana data zakończenia realizacji przedsięwzięcia / Data zakończenia realizacji przedsięwzięcia (dzień, miesiąc (słownie) i rok). | AM42: Data zakończenie realizacji nie może być dłuższa niż 36 miesiący od przewidywanej daty rozpoczęcia przedsięwzięcia
A44: E. | B44: Przewidywana struktura finansowania przedsięwzięcia, z podziałem na
B45: Wyszczególnienie | Z45: Ogółem (brutto) | AK45: Udział [%]
B46: Środki własne beneficjenta wsparcia | AK46: =ROUND(Z46/Z$49,5) -> #DIV/0!
B47: Wsparcie finansowe na podstawie ustawy | Z47: =B$39 -> #DIV/0! | AK47: =ROUND(Z47/Z$49,5) -> #DIV/0!
B48: Inne źródła | AK48: =ROUND(Z48/Z$49,5) -> #DIV/0!
B49: Łącznie | Z49: =SUM(Z46:AJ48) -> #DIV/0! | AK49: =SUM(AK46:AL48) -> #DIV/0! | AM49: Łącznie powinno zsumować się na kwalifikowany koszt przedsięwzięcia
A50: H. | B50: W przypadku przedsięwzięć, o których mowa w art. 3 ust. 1 pkt 5 i 6 i art. 4a ust. 1 pkt 3 ustawy, informacja o: 1) przewidywanej cenie sprzedaży, a jeżeli przedsięwzięcie zostało rozpoczęte przed dniem złożenia wniosku o finansowe wsparcie – informacja o dacie sporządzenia umowy sprzedaży i cenie sprzedaży; 2) wartości gruntu, wynikającej z aktualnego operatu szacunkowego, sporządzonego zgodnie z przepisami ustawy z dnia 21 sierpnia 1997 r. o gospodarce nieruchomościami (Dz. U. z 2024 r. poz. 1145, 1222, 1717 i 1881 oraz z 2025 r. poz. 1077 i 1080).
B51: Przewidywana cena sprzedaży/Cena ssprzedaży
...

Sheet Słowniki
A1: Beneficjent wsparcia | B1: Doprecyzowanie beneficjenta wsparcia | C1: jak wyżej | D1: Rodzaj przedsięwzięcia (należy wskazać właściwe) | F1: IV. Rodzaj i wielkość zasobu powstającego lub zmodernizowanego w wyniku przedsięwzięcia | H1: Przedsięwzięcie | I1: Przedsięwzięcie | J1: V. A. Charakterystyka przedsięwzięcia określonego w art. 3 i art. 5 ustawy | N1: 41640 | O1: VII. Oświadczenie o prawdziwości danych zawartych we wniosku, podpisane przez | P1: Pieczęć i podpis beneficjenta wsparcia | Q1: Pieczęć i podpis Wójta, Burmistrza, Prezydenta Miasta | U1: Przedsięwzięcie jest realizowane zgodnie z zasadami określonymi w art. 7 ustawy. | W1: Beneficjentowi wsparcia nie przysługuje prawo do obniżenia kwoty podatku należnego o kwotę podatku naliczonego związanego z tym przedsięwzięciem lub zwrot tego podatku. | X1: Inwestorowi nie przysługuje prawo do obniżenia kwoty podatku należnego o kwotę podatku naliczonego związanego z tym przedsięwzięciem lub zwrot tego podatku | Y1: Informuję, że pomieszczenia służące zaspokajaniu potrzeb mieszkaniowych studentów i doktorantów, pozyskanych przy udziale finansowego wsparcia na podstawie ustawy, będą wyposażone w oświetlenie naturalne i elektryczne, możliwość ogrzewania, niezawilgocone przegrody budowlane oraz wyposażone lub obejmujące bezpośredni dostęp do aneksu wyposażonego w źródło zaopatrzenia w wodę, ustęp oraz urządzenie do gotowania posiłków. | AA1: TAK | AC1: Pieczęć i podpis beneficjenta wsparcia | AO1: Przewidywana data rozpoczęcia realizacji przedsięwzięcia / Data rozpoczęcia realizacji przedsięwzięcia (dzień, miesiąc (słownie) i rok). | AP1: Data zakończenia realizacji przedsięwzięcia (dzień, miesiąc (słownie) i rok). | AQ1: 39083
A2: Związek międzygminny | B2: podstawowa jednostka samorządu terytorialnego, o której mowa w art. 1 ust. 2 ustawy z dnia 8 marca 1990 r. o samorządzie gminnym (Dz. U. z 2017 r. poz. 1875 z późn. zm.). | D2: A. Budowa budynku. | F2: A. Liczba lokali wchodzących w skład mieszkaniowego zasobu gminy, w tym liczba lokali, które zostaną utworzone i liczba lokali, które zostaną zmodernizowane. | H2: A. Charakterystyka przedsięwzięcia określonego w art. 3 ustawy | I2: A. Charakterystyka przedsięwzięcia określonego w art. 3 ustawy | J2: A. W przypadku budowy budynku, remontu, przebudowy lub zmiany sposobu użytkowania budynku lub jego części: | M2: V. B. Charakterystyka przedsięwzięcia określonego w art. 4 ustawy | O2: 1) w przypadku gminy - wójta (burmistrza, prezydenta miasta); | P2: Nie dotyczy realizowanego przedsięwzięcia | Q2: Nie dotyczy realizowanego przedsięwzięcia | U2: Przedsięwzięcie nie jest realizowane zgodnie z zasadami określonymi w art. 7 ustawy. | W2: Beneficjentowi wsparcia przysługuje prawo do obniżenia kwoty podatku należnego o kwotę podatku naliczonego związanego z tym przedsięwzięciem lub zwrot tego podatku. | X2: Inwestorowi przysługuje prawo do obniżenia kwoty podatku należnego o kwotę podatku naliczonego związanego z tym przedsięwzięciem lub zwrot tego podatku | Y2: Informuję, że pomieszczenia służące zaspokajaniu potrzeb mieszkaniowych studentów i doktorantów, pozyskanych przy udziale finansowego wsparcia na podstawie ustawy, nie będą wyposażone w oświetlenie naturalne i elektryczne, możliwość ogrzewania, niezawilgocone przegrody budowlane oraz wyposażone lub obejmujące bezpośredni dostęp do aneksu wyposażonego w źródło zaopatrzenia w wodę, ustęp oraz urządzenie do gotowania posiłków. | AA2: NIE | AC2: Pieczęć i podpis inwestora | AE2: Z. Informacja, czy beneficjent wsparcia lub inwestor posiada prawo własności lub użytkowania wieczystego lub dzierżawy lub użyczenia gruntu, na którym realizowane jest przedsięwzięcie, albo prawo własności budynku lub części budynku (w tym lokali), w którym realizowane jest przedsięwzięcie, albo o posiadanym prawie własności lub użytkowania wieczystego gruntu (dla przedsięwzięć, o których mowa w art. 3 ust. 1, art. 4, art. 5 ust. 1 oraz art. 5c ustawy). | AO2: Przewidywana data rozpoczęcia realizacji przedsięwzięcia (dzień, miesiąc (słownie) i rok). | AP2: Przewidywana data zakończenia realizacji przedsięwzięcia / Data zakończenia realizacji przedsięwzięcia (dzień, miesiąc (słownie) i rok).
A3: Gmina | B3: jednostka samorządu terytorialnego II stopnia, o którejh mowa w art. 1 ust. 2 ustawy z dnia 5 czerwca 1998 r. o samorządzie powiatowym (Dz. U. z 2017 r. poz. 1868 z późn. zm.) | C3: NIE | D3: B. Remont budynku albo jego części. | E3: B. Remont budynku albo jego części (remont budynku mieszkalnego będącego własnością gminy lub jednoosobowej spółki gminnej albo części takiego budynku, jeżeli ten remont nie dotyczy lokalu mieszkalnego zajmowanego przez lokatora na podstawie obowiązującej umowy najmu). | F3: Nie dotyczy | H3: A. Charakterystyka przedsięwzięcia określonego w art. 5 ustawy | I3: A. Charakterystyka przedsięwzięcia określonego w art. 3 ustawy | J3: B. W przypadku kupna lokali mieszkalnych, budynku mieszkalnego albo udziału we współwłasności budynku mieszkalnego w tym kupna połączonego z remontem tych lokali lub budynku mieszkalnego: | M3: A. Budowa budynku: | O3: 2) w przypadku związku międzygminnego - zarząd związku; | P3: Pieczęć i podpis inwestora | Q3: Nie dotyczy realizowanego przedsięwzięcia | U3: W lokalach mieszkalnych pozyskanych przy udziale finansowego wsparcia na podstawie ustawy zostanie zainstalowane wyposażenie, o którym mowa w art. 6b ustawy. | V3: W lokalach mieszkalnych pozyskanych przy udziale finansowego wsparcia na podstawie ustawy zostanie zainstalowane wyposażenie, o którym mowa w art. 6b ustawy. | W3: Przedsięwzięcie jest objęte gminnym programem rewitalizacji w rozumieniu przepisu art. 15 ustawy z dnia 9 października 2015 r. o rewitalizacji (Dz. U. z 2024 r. poz. 278). | X3: Informuję, że przedsięwzięcie jest realizowane przy udziale finansowania zwrotnego, o którym mowa w art. 15a ust. 1 ustawy z dnia 26 października 1995 r. o społecznych formach rozwoju mieszkalnictwa oraz wysokość środków publicznych przekazanych inwestorowi na tworzenie lokali mieszkalnych na wynajem z udziałem gminy albo związku międzygminnego z tytułu finansowego wsparcia udzielanego na zasadach określonych w ustawie oraz finansowania zwrotnego nie przekracza dopuszczalnej wysokości rekompensaty, o której mowa w art. 5 ust 5 ustawy – w przypadku gdy z realizacją przedsięwzięcia jest związane zawarcie umowy, o której mowa w art. 5 ust. 2 pkt 1 ustawy. | Y3: Informuję, że minimalna powierzchnia pomieszczenia służącego zaspokajaniu potrzeb mieszkaniowych studentów i doktorantów wynosi przynajmniej 8 m² powierzchni mieszkalnej na jedną osobę. | AA3: 0 | AC3: Budowa -> zasób lokale mieskzlane mzg, mieszkania chronione | AD3: Przebudowa lub remont, zmiana sposobu użytkowania -> zasób lokale mieskzlane mzg, mieszkania chronione | AE3: Art.. 5 | AF3: Art.. 5 - SAN
A4: Powiat | B4: związki międzygminne, o których mowa w art. 64 ustawy z dnia 8 marca 1990 r. o samorządzie gminnym (Dz. U. z 2017 r. poz. 1875 z późn. zm.) Związki międzygminne tworzone są przez gminy w celu wspólnego wykonywania zadań publicznych | C4: TAK | D4: C. Przebudowa budynku albo jego części. | E4: C. Przebudowa budynku albo jego części (przebudowa budynku mieszkalnego będącego własnością gminy lub jednoosobowej spółki gminnej albo części takiego budynku, jeżeli ta przebudowa nie dotyczy lokalu mieszkalnego zajmowanego przez lokatora na podstawie obowiązującej umowy najmu). | F4: B. Liczba mieszkań wspomaganych. | H4: B. Charakterystyka przedsięwzięcia określonego w art. 4 ustawy | I4: A. Charakterystyka przedsięwzięcia określonego w art. 3 ustawy | J4: C. W przypadku tworzenia lokali mieszkalnych na wynajem, powstających w wyniku realizacji przez inwestora innego niż gmina albo związek międzygminny budowy budynku, remontu lub przebudowy budynku lub jego części: | M4: 1. Noclegownia: | O4: 3) w przypadku powiatu - starostę; | Q4: Załącznik nr | U4: W lokalach mieszkalnych pozyskanych przy udziale finansowego wsparcia na podstawie ustawy niezostanie zainstalowane wyposażenie, o którym mowa w art. 6b ustawy. Wskaż w opisie poniżej przyczyny braku instalacji wyposażenia, o którym mowa w art. 6b ustawy. | V4: W lokalach mieszkalnych pozyskanych przy udziale finansowego wsparcia na podstawie ustawy niezostanie zainstalowane wyposażenie, o którym mowa w art. 6b ustawy. Wskaż w opisie poniżej przyczyny braku instalacji wyposażenia, o którym mowa w art. 6b ustawy. | W4: Przedsięwzięcie nie jest objęte gminnym programem rewitalizacji w rozumieniu przepisu art. 15 ustawy z dnia 9 października 2015 r. o rewitalizacji (Dz. U. z 2024 r. poz. 278). | X4: Informuję, że przedsięwzięcie nie jest realizowane przy udziale finansowania zwrotnego, o którym mowa w art. 15a ust. 1 ustawy z dnia 26 października 1995 r. o społecznych formach rozwoju mieszkalnictwa, a wysokość środków publicznych przekazanych inwestorowi na tworzenie lokali mieszkalnych na wynajem z udziałem gminy albo związku międzygminnego z tytułu finansowego wsparcia udzielanego na zasadach określonych w ustawie nie przekracza dopuszczalnej wysokości rekompensaty, o której mowa w art. 5 ust 5 ustawy – w przypadku gdy z realizacją przedsięwzięcia jest związane zawarcie umowy, o której mowa w art. 5 ust. 2 pkt 1 ustawy. | Y4: Informuję, że minimalna powierzchnia pomieszczenia służącego zaspokajaniu potrzeb mieszkaniowych studentów i doktorantów wynosi jest mniejsza niż 8 m² powierzchni mieszkalnej na jedną osobę. | AC4: Informuję, (informacja beneficjenta wsparcia) że posiadam prawo własności lub prawo użytkowania wieczystego gruntu, na którym jest realizowane przedsięwzięcie. | AD4: Informuję, że posiadam prawo własności budynku lub części budynku (w tym lokali), w którym realizowane jest przedsięwzięcie. | AE4: Informuję, że (inwestor) posiada prawo własności lub użytkowania wieczystego gruntu, na którym realizowane jest przedsięwzięcie. | AF4: Informuję, że (inwestor) posiada prawo własności lokalu mieszkalnego, budynku mieszkalnego jednorodzinnego, budynku innego niż mieszkalny albo części takiego budynku, w którym realizowane jest przedsięwzięcie.
A5: Organizacja pozarządowa | B5: organizację pozarządową, o której mowa w art. 3 ust. 2 ustawy z dnia 24 kwietnia 2003 r. o działalności pożytku publicznego i o wolontariacie (Dz. U. z 2020 r. poz. 1057), zwanej dalej „organizacją pozarządową”, | C5: NIE DOTYCZY | D5: D. Zmiana sposobu użytkowania budynku albo jego części. | E5: B. Remont budynku albo jego części (udziela się również gdy remont dotyczy lokalu mieszkalnego zajmowanego przez lokatora na podstawie obowiązującej umowy najmu, jeżeli beneficjent wsparcia uzyskał premię, o której mowa w art. 11g ust. 1 ustawy z dnia 21 listopada 2008 r. o wspieraniu termomodernizacji i remontów oraz o centralnej ewidencji emisyjności budynków (Dz. U. z 2023 r. poz. 2496), z tytułu realizacji przedsięwzięcia termomodernizacyjnego lub remontowego w budynku, w którym znajdują się te lokale mieszkalne, i realizuje to przedsięwzięcie łącznie z remontem lub przebudową tego lokalu). | F5: B. Liczba mieszkań treningowych. | I5: A. Charakterystyka przedsięwzięcia określonego w art. 3 ustawy | M5: 1) adres nieruchomości; | O5: 4) w przypadku jednoosobowej spółki gminnej, organizacji pozarządowej albo podmiotów, o których mowa w art. 3 ust. 3 ustawy z dnia 24 kwietnia 2003 r. o działalności pożytku publicznego i o wolontariacie- osobę lub osoby uprawnione do składania oświadczeń woli w imieniu spółki i organizacji (należy dołączyć aktualny dokument potwierdzający uprawnienia) | U5: Przedsięwzięcie zostało zakończone przed dniem złożenia wniosku, o którym mowa w art. 8 ust. 1 ustawy. | V5: Nie dotyczy w przypadku przedsięwzięć, o których mowa w art. 3 ust. 2-3 ustawy | W5: Część lokali będzie przeznaczona dla rodzin z dziećmi posiadającymi zaświadczenie, o którym mowa w art. 4 ust. 3 ustawy z dnia 4 listopada 2016 r. o wsparciu kobiet w ciąży i rodzin „Za życiem” (Dz. U. z 2023 r. poz. 1923). | Y5: Informuję, że na realizację przedsięwzięcia nie została udzielona dotacja celowa na podstawie art. 365 pkt 4 lit. a ustawy z dnia 20 lipca 2018 r. – Prawo o szkolnictwie wyższym i nauce (Dz. U. z 2024 r. poz. 1571, z późn. zm. )). | AD5: Informuję, że nie posiadam prawa własności budynku lub części budynku (w tym lokali), w którym realizowane jest przedsięwzięcie.
A6: Podmiot, o którym mowa w art. 3 ust. 3 ustawy z dnia 24 kwietnia 2003 r. o działalności pożytku publicznego i o wolontariacie | B6: podmioty, o których mowa w art. 3 ust. 3 ustawy z dnia 24 kwietnia 2003 r. o działalności pożytku publicznego i o wolontariacie;”, | D6: E. Kupno lokalu mieszkalnego, budynku mieszkalnego albo udziału we współwłasności budynku mieszkalnego. | E6: C. Przebudowa budynku albo jego części (udziela się również gdy przebudowa dotyczy lokalu mieszkalnego zajmowanego przez lokatora na podstawie obowiązującej umowy najmu, jeżeli beneficjent wsparcia uzyskał premię, o której mowa w art. 11g ust. 1 ustawy z dnia 21 listopada 2008 r. o wspieraniu termomodernizacji i remontów oraz o centralnej ewidencji emisyjności budynków (Dz. U. z 2023 r. poz. 2496), z tytułu realizacji przedsięwzięcia termomodernizacyjnego lub remontowego w budynku, w którym znajdują się te lokale mieszkalne, i realizuje to przedsięwzięcie łącznie z remontem lub przebudową tego lokalu). | F6: C. Liczba tymczasowych pomieszczeń. | I6: A. Charakterystyka przedsięwzięcia określonego w art. 3 ustawy | J6: A. W przypadku budowy budynku, jego remontu, przebudowy lub zmiany sposobu jego użytkowania: | M6: 2) nowa powierzchnia użytkowa noclegowni w m2, w tym w sypialniach w m2; | O6: 1) w przypadku gminy - wójta (burmistrza, prezydenta miasta); | U6: Przedsięwzięcie nie zostało zakończone przed dniem złożenia wniosku, o którym mowa w art. 8 ust. 1 ustawy. | W6: Żaden lokal nie będzie przeznaczony dla rodzin z dziećmi posiadającymi zaświadczenie, o którym mowa w art. 4 ust. 3 ustawy z dnia 4 listopada 2016 r. o wsparciu kobiet w ciąży i rodzin „Za życiem” (Dz. U. z 2023 r. poz. 1923). | X6: Gmina została dotknięta skutkami powodzi. | Y6: Informuję, że na realizację przedsięwzięcia została udzielona dotacja celowa na podstawie art. 365 pkt 4 lit. a ustawy z dnia 20 lipca 2018 r. – Prawo o szkolnictwie wyższym i nauce (Dz. U. z 2024 r. poz. 1571, z późn. zm. )).
A7: Jednoosobowa spółka gminna | B7: spółki z ograniczoną odpowiedzialnością lub spółki akcyjne, niedziałające w formie towarzystwa budownictwa społecznego, których wszystkie udziały albo akcje należą do jednego wspólnika albo akcjonariusza, a tym wspólnikiem albo akcjonariuszem jest gmina i którym gmina powierzyła realizację zadania własnego w zakresie zaspokajania potrzeb mieszkaniowych wspólnoty samorządowej | C7: B. Remont budynku albo jego części. | D7: F. Kupno lokalu mieszkalnego, budynku mieszkalnego albo udziału we współwłasności budynku mieszkalnego połączone z remontem tego lokalu lub budynku mieszkalnego. | E7: D. Zmiana sposobu użytkowania budynku albo jego części. | F7: D. Liczba mieszkań pozyskiwanych w wyniku realizacji inwestycji przez społeczną inicjatywę mieszkaniową albo spółkę gminną, gdy z realizacją przedsięwzięcia jest związane zawarcie umowy, o której mowa w art. 5 ust. 2 pkt 1 ustawy, w przypadku, o którym mowa w art. 5a ust. 1 ustawy: 1) mieszkania przeznaczone do podnajmowania osobom spełniającym warunki otrzymania lokalu wchodzącego w skład mieszkaniowego zasobu gminy. | H7: 2) mieszkania treningowe lub wspomagane. | I7: A. Charakterystyka przedsięwzięcia określonego w art. 3 ustawy | J7: B. Remont, przebudowa, rozbudowa lub nadbudowa istniejącej noclegowni, istniejącego schroniska dla osób bezdomnych lub istniejącej ogrzewalni, w wyniku których nastąpi dostosowanie noclegowni, schroniska dla osób bezdomnych lub ogrzewalni do standardów, o których mowa w przepisach wydanych na podstawie art. 48a ust. 14 ustawy z dnia 12 marca 2004 r. o pomocy społecznej – zakres informacji taki jak w lit. A. | M7: 3) nowa powierzchnia użytkowa niestanowiąca noclegowni; | O7: 2) w przypadku powiatu - starostę; | W7: Inwestorowi nie przysługuje prawo do obniżenia kwoty podatku należnego o kwotę podatku naliczonego związanego z tym przedsięwzięciem lub zwrot tego podatku. | X7: Nie dotyczy realizowanego przedsięwzięwzięcia | Y7: Informuję, że wartość wskaźnika rocznego zapotrzebowania na nieodnawialną energię pierwotną EP w budynku powstałym w ramach przedsięwzięcia nie przekracza 52 kWh/(m²×rok). | AC7: Informuję, (informacja beneficjenta wsparcia będącego powiatem albo organizacją pożytku publicznego) że prawo własności lub prawo użytkowania wieczystego gruntu, na którym jest realizowane przedsięwzięcie, posiada gmina lub jednoosobowa spółka gminna lub Skarb Państwa, w związku z art. 6 ust. 1 ustawy. Jednocześnie informuję, że (informacja beneficjenta wsparcia) że posiadam prawo dzierżawy lub prawo użyczenia gruntu, na którym jest realizowane przedsięwzięcie. | AD7: Informuję, (informacja beneficjenta wsparcia będącego powiatem albo organizacją pożytku publicznego) że prawo własności lub prawo użytkowania wieczystego gruntu na którym jest realizowane przedsięwzięcie, posiada gmina lub jednoosobowa spółka gminna lub Skarb Państwa, w związku z art. 6 ust. 1 ustawy. Jednocześnie informuję, że posiadam prawo dzierżawy lub prawo użyczenia gruntu, na którym jest realizowane przedsięwzięcie.
A8: Uczelnia publiczna | C8: C. Przebudowa budynku albo jego części. | D8: G. Budowa infrastruktury technicznej lub infrastruktury społecznej. | E8: NIE DOTYCZY | F8: E. Liczba lokali mieszkalnych na wynajem tworzonych z udziałem gminy albo związku międzygminnego w wyniku realizacji inwestycji przez inwestora, w przypadku gdy z realizacją przedsięwzięcia jest związane zawarcie umowy, o której mowa w art. 5 ust. 2 pkt 1 ustawy. | M8: 4) nowa liczba miejsc w sypialniach; | O8: 3) w przypadku jednoosobowej spółki gminnej, organizacji pozarządowej albo podmiotów, o których mowa w art. 3 ust. 3 ustawy z dnia 24 kwietnia 2003 r. o działalności pożytku publicznego i o wolontariacie- osobę lub osoby uprawnione do składania oświadczeń woli w imieniu spółki i organizacji (należy dołączyć aktualny dokument potwierdzający uprawnienia) | W8: Inwestorowi przysługuje prawo do obniżenia kwoty podatku należnego o kwotę podatku naliczonego związanego z tym przedsięwzięciem lub zwrot tego podatku. | X8: Informuję, że przedsięwzięcie nie jest realizowane przy udziale finansowania zwrotnego, o którym mowa w art. 15a ust. 1 ustawy z dnia 26 października 1995 r. o społecznych formach rozwoju mieszkalnictwa. | Y8: Informuję, że wartość wskaźnika rocznego zapotrzebowania na nieodnawialną energię pierwotną EP w budynku powstałym w ramach przedsięwzięcia przekracza n 52 kWh/(m²×rok). | AC8: Informuję, (informacja inwestora) że posiadam prawo własności lub prawo użytkowania wieczystego gruntu, na którym jest realizowane przedsięwzięcie.
B9: Nie posiadam adresu do doręczeń elektronicznych | C9: NIE DOTYCZY | D9: H. Przebudowa infrastruktury technicznej lub infrastruktury społecznej. | F9: F. Liczba mieszkań pozyskiwanych w wyniku realizacji inwestycji przez społeczną agencję najmu, w przypadku gdy z realizacją przedsięwzięcia związane jest zawarcie umowy, o której mowa w art. 22b ustawy z dnia 26 października 1995 r. o społecznych formach rozwoju mieszkalnictwa. | M9: 5) dotychczasowa powierzchnia użytkowa noclegowni w m2, w tym w sypialniach w m2; | W9: Nie dotyczy realizowanego przedsięwzięwzięcia | X9: Informuję, że przedsięwzięcie jest realizowane przy udziale finansowania zwrotnego, o którym mowa w art. 15a ust. 1 ustawy z dnia 26 października 1995 r. o społecznych formach rozwoju mieszkalnictwa. | Y9: Informuję, że koszty przedsięwzięcia nie obejmują kosztów związanych z zakupem, montażem i uruchomieniem indywidualnego kotła zasilanego paliwami kopalnymi. | AC9: Informuję, (informacja inwestora) że posiadam prawo dzierżawy lub użyczenia gruntu, na którym jest realizowane przedsięwzięcie. | AD9: Informuję, że posiadam prawo własności budynku lub części budynku (w tym lokali), w którym realizowane jest przedsięwzięcie.
A10: Rodzaj przedsięwzięcia | C10: NIE DOTYCZY | F10: G. Liczba miejsc w noclegowniach. | M10: 6) całkowita liczba miejsc w sypialniach, po zakończeniu realizacji przedsięwzięcia, w podziale na poszczególne sypialnie; | W10: Informuję, że przedsięwzięcie spełnia standardy, o których mowa w przepisach wydanych na podstawie art. 53 ust. 24 ustawy z dnia 12 marca 2004 r. o pomocy społecznej – w przypadku przedsięwzięcia, o którym mowa w art. 6 ustawy. | X10: Nie dotyczy realizowanego przedsięwzięwzięcia | Y10: Informuję, że koszty przedsięwzięcia obejmują kosztów związanych z zakupem, montażem i uruchomieniem indywidualnego kotła zasilanego paliwami kopalnymi. | AD10: Nie dotyczy realizowanego przedsięwzięwzięcia
A11: BB - budowa budynku | C11: B. Remont budynku albo jego części (remont budynku mieszkalnego będącego własnością gminy lub jednoosobowej spółki gminnej albo części takiego budynku, jeżeli ten remont nie dotyczy lokalu mieszkalnego zajmowanego przez lokatora na podstawie obowiązującej umowy najmu). | F11: H. Liczba miejsc w schroniskach dla osób bezdomnych. | I11: A. Charakterystyka przedsięwzięcia określonego w art. 5 ustawy | M11: 7) całkowita liczba natrysków, kabin WC, pisuarów i umywalek po zakończeniu realizacji przedsięwzięcia. | W11: Nie dotyczy realizowanego przedsięwzięwzięcia | X11: Informuję, że tworzone lokale mieszkalne na wynajem będą wynajmowane i użytkowane na zasadach wskazanych w art. 7a–7f ustawy. | Y11: Informauję, że tworzone lokale mieszkalne będą wynajmowane i użytkowane na zasadach wskazanych w art. 7a ust. 1 pkt 1 i art.7c ust. 3a ustawy. | AE11: Z. Informacja, czy beneficjent wsparcia lub inwestor posiada prawo własności lub użytkowania wieczystego lub dzierżawy lub użyczenia gruntu, na którym realizowane jest przedsięwzięcie, albo prawo własności budynku lub części budynku (w tym lokali), w którym realizowane jest przedsięwzięcie, albo o posiadanym prawie własności lub użytkowania wieczystego gruntu (dla przedsięwzięć, o których mowa w art. 3 ust. 1, art. 4, art. 5 ust. 1 oraz art. 5c ustawy).
A12: BB-TBS - budowa budynku przez TBS lub SG | C12: C. Przebudowa budynku albo jego części (przebudowa budynku mieszkalnego będącego własnością gminy lub jednoosobowej spółki gminnej albo części takiego budynku, jeżeli ta przebudowa nie dotyczy lokalu mieszkalnego zajmowanego przez lokatora na podstawie obowiązującej umowy najmu). | F12: I. Liczba miejsc w ogrzewalniach. | I12: A. Charakterystyka przedsięwzięcia określonego w art. 5 ustawy | K12: K. Tworzenie lokali mieszkalnych na wynajem, powstających w wyniku realizacji przez inwestora innego niż gmina albo związek międzygminny budowy budynku, w przypadku gdy beneficjent wsparcia ubiega się jednocześnie o grant OZE, o którym mowa w art. 13c ustawy – zakres informacji taki jak w lit. J. | M12: 2. Schronisko dla bezdomnych: | W12: Informuję, że przed złożeniem wniosku o finansowe wsparcie, budynek lub jego część, które są aktualnie przedmiotem przedsięwzięcia, nie podlegał finansowaniu ze środków Funduszu Dopłat lub rozliczenie to nastąpiło na więcej niż 25 lat przez złożeniem niniejszego wniosku. | X12: Informuję, że tworzone lokale mieszkalne na wynajem nie będą wynajmowane i użytkowane na zasadach wskazanych w art. 7a–7f ustawy. | Y12: Informauję, że tworzone lokale mieszkalne nie będą wynajmowane i użytkowane na zasadach wskazanych w art. 7a ust. 1 pkt 1 i art.7c ust. 3a ustawy.
A13: K - kupno lub kupno połączone z remontem | B13: I. Kupno budynku mieszkalnego albo udziału we własności budynku mieszkalnego, w tym kupno połączone z remontem lub przebudową tego budynku, w wyniku którego zostaną utworzone lub zmodernizowane pomieszczenia służące zaspokajaniu potrzeb mieszkaniowych studentów i doktorantów. | C13: NIE DOTYCZY | F13: F. Liczba miejsc w noclegowniach. | I13: A. Charakterystyka przedsięwzięcia określonego w art. 5 ustawy | K13: L. Tworzenie lokali mieszkalnych na wynajem, powstających w wyniku realizacji przez inwestora innego niż gmina albo związek międzygminny budowy budynku, w przypadku, o którym mowa w art. 22a ustawy – zakres informacji taki jak w lit. J. | M13: 1) adres nieruchomości; | W13: Informuję, że przed złożeniem wniosku o finansowe wsparcie, budynek lub jego część, które są aktualnie przedmiotem przedsięwzięcia, podlegał finansowaniu ze środków Funduszu Dopłat. Jednocześnie informuję, że przedsięwzięcie, w ramach którego finansowany był ten budynek nie zostało rozliczone lub zostało rozliczone, a rozliczenie to nastąpiło na mniej niż 25 lat przed złożeniem niniejszego wniosku. | X13: Informuję, że inwestor, któremu powierzy się świadczenie usługi publicznej w ogólnym interesie gospodarczym, świadczyć będzie usługę polegającą na najmie lokali mieszkalnych na warunkach określonych w art. 7a–7f ustawy.
A14: RPB - remont lub przebudowa budynku niemieszkalnego lub mieszkalnego z decyzją PINB (art. 66 ust. 2 lub art. 68 pkt 1 Prawa budowlanego) | C14: B. Remont budynku albo jego części. | F14: G. Liczba miejsc w schroniskach dla osób bezdomnych. | M14: 2) nowa powierzchnia użytkowa schroniska dla bezdomnych w m2, w tym powierzchnia mieszkalna w m2, w tym w pomieszczeniach mieszkalnych w m2; | W14: Informuję, że przed złożeniem wniosku o finansowe wsparcie, budynek lub jego część, które są aktualnie przedmiotem przedsięwzięcia, podlegał finansowaniu ze środków Funduszu Dopłat. Jednocześnie informuję, że przedsięwzięcie, w ramach którego finansowany był ten budynek lub ta część nie zostało rozliczone lub rozliczenie to nastąpiło na mniej niż 25 lat przez złożeniem niniejszego wniosku. | X14: Informuję, że inwestor, któremu powierzy się świadczenie usługi publicznej w ogólnym interesie gospodarczym, nie będzie świadczyć usługi polegającej na najmie lokali mieszkalnych na warunkach określonych w art. 7a–7f ustawy.
A15: RPBn - remont lub przebudowa budynku niemieszkalnego | C15: C. Przebudowa budynku albo jego części. | F15: IV. Rodzaj i wielkość zasobu powstającego lub zmodernizowanego w wyniku przedsięwzięcia | M15: 3) nowa powierzchnia użytkowa niestanowiąca schroniska dla bezdomnych; | W15: Informuję, że przedsięwzięcie jest realizowane na podstawie dokumentacji projektowej opracowanej z wykorzystaniem zasobu projektów, o którym mowa w art. 7g ustawy. | X15: Informuję, że tworzone lokale mieszkalne na wynajem będą wynajmowane i użytkowane na zasadach wskazanych w art. 7a–7d oraz 7f ustawy.
A16: RPBn/ZSUB –TBS/SG - remont lub przebudowa budynku niemieszkalnego przez TBS lub SG | C16: ZH. W przypadku przedsięwzięcia, o którym mowa w art. 5 ust. 1 albo art. 5c ust. 2 ustawy, informacja o dacie bądź planowanej dacie zawarcia umowy, o której mowa w art. 5 ust. 2 pkt 1 albo pkt 2 lit. a albo art. 5c ust. 3 ustawy, oraz okresie, na jaki została bądź zostanie zawarta ta umowa. | W16: Nie dotyczy realizowanego przedsięwzięcia
A17: ZSUB - zmiana sposobu użytkowania budynku | C17: Informacja o dacie bądź planowanej dacie zawarcia umowy, o której mowa w art. 5 ust. 2 pkt 1 albo pkt 2 lit. a albo art. 5c ust. 3 ustawy | D17: Okres, na jaki została zawarta ta umowa. | F17: C. Liczba tymczasowych pomieszczeń. | M17: 5) dotychczasowa powierzchnia użytkowa schroniska dla bezdomnych w m2, w tym powierzchnia mieszkalna w m2, w tym w pomieszczeniach mieszkalnych w m2; | X17: Informacja, że inwestor, któremu powierzy się świadczenie usługi publicznej w ogólnym interesie gospodarczym, świadczyć będzie usługę polegającą na najmie lokali mieszkalnych na warunkach określonych w art. 7a–7d oraz 7f ustawy.
C18: Informacja o dacie bądź planowanej dacie zawarcia umowy, o której mowa w art. 5 ust. 2 pkt 1 albo pkt 2 lit. a albo art. 5c ust. 3 ustawy | D18: Okres, na jaki zostanie zawarta ta umowa. | E18: Q. Tworzenie lokali mieszkalnych na wynajem, powstających w wyniku realizacji przez inwestora innego niż gmina albo związek międzygminny budowy budynku (art. 5 ust. 1 pkt 1 ustawy), na podstawie umowy, o której mowa w art. 5 ust. 2 ustawy, w przypadku gdy beneficjent wsparcia ubiega się jednocześnie o grant OZE. | F18: Nie dotyczy | M18: 6) całkowita liczba miejsc w pomieszczeniach mieszkalnych, po zakończeniu realizacji przedsięwzięcia, w podziale na poszczególne pomieszczenia mieszkalne; | X18: Informacja, że inwestor, któremu powierzy się świadczenie usługi publicznej w ogólnym interesie gospodarczym, nie będzie świadczyć usługi polegającej na najmie lokali mieszkalnych na warunkach określonych w art. 7a–7d oraz 7f ustawy.
E19: R. Tworzenie lokali mieszkalnych na wynajem, powstających w wyniku realizacji przez inwestora innego niż gmina albo związek międzygminny budowy budynku (art. 5 ust. 1 pkt 1 ustawy), na podstawie umowy, o której mowa w art. 5 ust. 2 ustawy, w przypadku, o którym mowa w art. 22a ustawy. | M19: 7) całkowita liczba natrysków, kabin WC, pisuarów i umywalek po zakończeniu realizacji przedsięwzięcia. | X19: Informuję, że (beneficjent wsparcia) ubiegam się o finansowe wsparcie na przedsięwzięcie, o którym mowa w art. 3 ust. 1 pkt 5 i 6 ustawy, którego przedmiotem zakupu są byłe mieszkania zakładowe, wraz z ich wykazem, których lokatorami są: 1) osoby, które przed dniem 7 lutego 2001 r. były pracownikami przedsiębiorstwa państwowego lub spółki handlowej, w których Skarb Państwa był podmiotem dominującym w rozumieniu ustawy z dnia 29 lipca 2005 r. o ofercie publicznej i warunkach wprowadzania instrumentów finansowych do zorganizowanego systemu obrotu oraz o spółkach publicznych (Dz. U. z 2021 r. poz. 1983 i 2140 oraz z 2022 r. poz. 872 i 1488); 2) zstępni, wstępni, małżonek lokatora, osoby przysposabiające lokatora i przysposobione przez niego oraz osoby, które pozostawały z lokatorem w faktycznym wspólnym pożyciu, zamieszkujące z lokatorem w chwili jego śmierci, którzy wstąpili w stosunek najmu po śmierci osób wskazanych w pkt 1.
A20: Rodzaj przedsięwzięcia | C20: Informuję, że gmina określiła kryteria, o których mowa w art. 22e ust. 1 pkt 1 ustawy z dnia 26 października 1995 r. o społecznych formach rozwoju mieszkalnictwa. | F20: J. Wskazanie, które z zadań własnych gminy, o których mowa w art. 7 ust. 1 pkt 2, 3, 4–6, 8–10 i 12 ustawy z dnia 8 marca 1990 r. o samorządzie gminnym, lub zadań publicznych powiatu, o których mowa w art. 4 ust. 1 pkt 1–3, 6–8 i 12 ustawy z dnia 5 czerwca 1998 r. o samorządzie powiatowym, jest realizowane w ramach przedsięwzięcia, o którym mowa w art. 5c ust. 1 lub 2 ustawy. | H20: C. Liczba tymczasowych pomieszczeń. | M20: 3. Ogrzewalnia: | W20: Beneficjentowi wsparcia nie przysługuje prawo do obniżenia kwoty podatku należnego o kwotę podatku naliczonego związanego z tym przedsięwzięciem lub zwrot tego podatku. | X20: Nie dotyczy realizowanego przedsięwzięwzięcia
A21: Budowa budynku | C21: Informuję, że gmina nieokreśliła kryteriów, o których mowa w art. 22e ust. 1 pkt 1 ustawy z dnia 26 października 1995 r. o społecznych formach rozwoju mieszkalnictwa. | F21: E. Liczba lokali mieszkalnych na wynajem tworzonych z udziałem gminy albo związku międzygminnego w wyniku reali zacji inwestycji przez inwestora, w przypadku gdy z realizacją przedsięwzięcia jest związane zawarcie umowy, o której mowa w art. 5 ust. 2 ustawy. | W21: Beneficjentowi wsparcia przysługuje prawo do obniżenia kwoty podatku należnego o kwotę podatku naliczonego związanego z tym przedsięwzięciem lub zwrot tego podatku.
A22: Remont lub przebudowa budynku niemieszkalnego lub mieszkalnego | F22: Nie dotyczy | M22: 2) nowa powierzchnia użytkowa ogrzewalni w m2; | W22: Nie dotyczy realizowanego przedsięwzięwzięcia
A23: Zmiana sposobu użytkowania budynku | M23: 3) nowa powierzchnia użytkowa niestanowiąca ogrzewalni;
A24: Kupno lub kupno połączone z remontem | E24: X. Tworzenie lokali mieszkalnych powstających w wyniku realizacji przez społeczną inicjatywę mieszkaniową albo spółkę gminną budowy budynku (art. 5 ust. 1 pkt 1 ustawy) na podstawie umowy, o której mowa w art. 5 ust. 2 ustawy, w przypadku, o którym mowa w art. 5a ust. 1 ustawy, w przypadku gdy beneficjent wsparcia ubiega się jednocześnie o grant OZE. | F24: A. Liczba lokali wchodzących w skład mieszkaniowego zasobu gminy, w tym liczba lokali, które zostaną utworzone i liczba lokali, które zostaną zmodernizowane. | M24: 4) nowa liczba miejsc w ogrzewalni;
A25: Remont lub przebudowa budynku niemieszkalnego | E25: Y. Tworzenie lokali mieszkalnych powstających w wyniku realizacji przez społeczną inicjatywę mieszkaniową albo spółkę gminną budowy budynku (art. 5 ust. 1 pkt 1 ustawy) na podstawie umowy, o której mowa w art. 5 ust. 2 ustawy, w przypadku, o którym mowa w art. 5a ust. 1 ustawy, w przypadku, o którym mowa w art. 22a ustawy. | F25: B. Liczba mieszkań chronionych. | M25: 5) dotychczasowa powierzchnia użytkowa ogrzewalni w m2;
F26: Nie dotyczy | M26: 4. Charakterystyka noclegowni (czy dana cecha występuje):
M27: 1) liczba miejsc nie większa niż 100;
A28: Inwestor inny | M28: 2) nie więcej niż 20 osób w jednej sypialni;
A29: Inwestor - TBS albo spółka gmina - art. 5a | M29: 3) powierzchnia przypadająca na osobę w sypialni - nie mniej niż 3 m2/osobę, w pomieszczeniach z łóżkami piętrowymi nie mniej niż 2 m2/osobę;
A30: Społeczna agencja najmu | F30: J. Liczba lokali mieszkalnych zrealizowanych w ramach programu „Za życiem”. | M30: 4) sypialnie z co najmniej 1 otwieranym oknem na pomieszczenie lub wentylacją przewidzianą dla pomieszczeń mieszkalnych bez otwieranych okien;
F31: K. Liczba lokali mieszkalnych dla seniorów, o których mowa w art. 5b ustawy. | M31: 5) sanitariaty (urządzenie natryskowe - 1 dla 15 osób, miska ustępowa - 1 dla 10 kobiet oraz 1 dla 20 mężczyzn, pisuar - 1 dla 20 mężczyzn, umywalka - 1 dla 5 osób, dostęp do bieżącej ciepłej i zimnej wody oraz możliwość przeprowadzenia zabiegów higienicznych);
M32: 6) jadalnia/świetlica (pomieszczenie do spożywania posiłków, które poza porami posiłków może pełnić funkcję świetlicy lub sali spotkań grupowych);
D33: [1]) | E33: Zmiany tekstu jednolitego wymienionej ustawy zostały ogłoszone w Dz. U. z 2021 r. poz. 2270 oraz z 2022 r. poz. 1, 66, 1079, 1692, 1700, 1812, 1967, 2127 i 2140. | M33: 7) pomieszczenie biurowe (wydzielone pomieszczenie do prac biurowych oraz indywidualnych rozmów z osobami bezdomnymi);
A34: Umowa | J34: 6) Obliczona zgodnie z art. 2 ust. 2 ustawy z dnia 21 czerwca 2001 r. o ochronie praw lokatorów, mieszkaniowym zasobie gminy i o zmianie Kodeksu cywilnego (Dz. U. z 2016 r. poz. 1610, z 2017 r. poz. 1442 i 1529 oraz z 2018 r. poz. 374 i 756). | M34: 8) magazyn odzieży, bielizny, pościeli (pomieszczenia wyposażone w regały, szafy i inne meble umożliwiające wymianę rzeczy brudnych i czystych);
A35: Faktura VAT | J35: 6) Obliczona zgodnie z art. 2 ust. 2 ustawy z dnia 21 czerwca 2001 r. o ochronie praw lokatorów, mieszkaniowym zasobie gminy i o zmianie Kodeksu cywilnego (Dz. U. z 2016 r. poz. 1610, z 2017 r. poz. 1442 i 1529 oraz z 2018 r. poz. 374 i 756). | M35: 9) magazyn środków chemicznych (wydzielone pomieszczenie na środki czystości i higieny);
A36: Kosztorys | J36: 6) Obliczona zgodnie z art. 2 ust. 2 ustawy z dnia 21 czerwca 2001 r. o ochronie praw lokatorów, mieszkaniowym zasobie gminy i o zmianie Kodeksu cywilnego (Dz. U. z 2016 r. poz. 1610, z 2017 r. poz. 1442 i 1529 oraz z 2018 r. poz. 374 i 756). | M36: 10) pralnia (wydzielone pomieszczenie wyposażone co najmniej w 1 pralkę dla 30 osób).
A37: Kalkulacja własna | J37: 7) Nie wlicza się wartości lub kosztu nabycia gruntu. Wlicza się koszt wyposażenia lokalu, o którym mowa w art. 6b ustawy. | M37: 5. Charakterystyka schroniska dla bezdomnych (czy dana cecha występuje):
A38: Rachunek | D38: U. Tworzenie lokali mieszkalnych na wynajem, powstających w wyniku realizacji przez inwestora innego niż gmina albo związek międzygminny remontu lub przebudowy całości albo części budynku mieszkalnego będącego własnością społecznej inicjatywy mieszkaniowej, której jedynym albo większościowym właścicielem jest gmina, jeżeli ten remont lub ta przebudowa nie dotyczy lokalu mieszkalnego zajmowanego przez lokatora na podstawie obowiązującej umowy najmu (art. 5 ust. 1 pkt 4 ustawy), na podstawie umowy, o której mowa w art. 5 ust. 2 ustawy. | F38: A. Liczba lokali wchodzących w skład mieszkaniowego zasobu gminy, w tym liczba lokali, które zostaną utworzone i liczba lokali, które zostaną zmodernizowane. | J38: 6) Obliczona zgodnie z art. 2 ust. 2 ustawy z dnia 21 czerwca 2001 r. o ochronie praw lokatorów, mieszkaniowym zasobie gminy i o zmianie Kodeksu cywilnego (Dz. U. z 2016 r. poz. 1610, z 2017 r. poz. 1442 i 1529 oraz z 2018 r. poz. 374 i 756). | M38: 1) liczba miejsc nie większa niż 80;
A39: Zlecenie | D39: ZB. Tworzenie lokali mieszkalnych na wynajem, powstających w wyniku realizacji przez społeczną inicjatywę mieszkaniową albo spółkę gminną remontu lub przebudowy całości albo części budynku mieszkalnego, będącego własnością społecznej inicjatywy mieszkaniowej, której jedynym albo większościowym właścicielem jest gmina, jeżeli ten remont lub ta przebudowa nie dotyczy lokalu mieszkalnego zajmowanego przez lokatora na podstawie obowiązującej umowy najmu (art. 5 ust. 1 pkt 4 ustawy), na podstawie umowy, o której mowa w art. 5 ust. 2 ustawy, w przypadku, o którym mowa w art. 5a ust. 1 ustawy. | F39: C. Liczba tymczasowych pomieszczeń. | J39: 6) Obliczona zgodnie z art. 2 ust. 2 ustawy z dnia 21 czerwca 2001 r. o ochronie praw lokatorów, mieszkaniowym zasobie gminy i o zmianie Kodeksu cywilnego (Dz. U. z 2016 r. poz. 1610, z 2017 r. poz. 1442 i 1529 oraz z 2018 r. poz. 374 i 756). | M39: 2) nie więcej niż 10 osób w jednym pomieszczeniu mieszkalnym;
A40: operat szacunkowy | F40: Nie dotyczy | J40: 6) Obliczona zgodnie z art. 2 ust. 2 ustawy z dnia 21 czerwca 2001 r. o ochronie praw lokatorów, mieszkaniowym zasobie gminy i o zmianie Kodeksu cywilnego (Dz. U. z 2016 r. poz. 1610, z 2017 r. poz. 1442 i 1529 oraz z 2018 r. poz. 374 i 756). | M40: 3) powierzchnia przypadająca na osobę w pomieszczeniu mieszkalnym - nie mniej niż 4 m2/osobę, w pomieszczeniach z łóżkami piętrowymi nie mniej niż 3 m2/osobę;
...

Sheet Słownik N_S_O
A1: III. Rodzaj przedsięwzięcia (należy wskazać właściwe) | B1: V. B. Charakterystyka przedsięwzięcia określonego w art. 4 ustawy | C1: 0.8 | F1: Beneficjent wsparcia | G1: Doprecyzowanie beneficjenta wsparcia | O1: Przedsięwzięcie spełnia standardy, o których mowa w przepisach wydanych na podstawie art. 48a ust. 14 ustawy z dnia 12 marca 2004 r. o pomocy społecznej. | Q1: Budowa, Przebudowa lub remont, zmiana sposobu użytkowania -> schroniska dla osób bezdomnych, noclegownie i ogrzewalnie
A2: K. Budowa budynku na nieruchomości stanowiącej własność albo będącej w użytkowaniu wieczystym gminy, jednoosobowej spółki gminnej, związku międzygminnego, organizacji pozarządowej albo podmiotów, o których mowa w art. 3 ust. 3 ustawy z dnia 24 kwietnia 2003 r. o działalności pożytku publicznego i o wolontariacie (art. 4 ust. 1 pkt 1 i ust. 3 ustawy), w wyniku której powstaną noclegownie lub schroniska dla osób bezdomnych lub nastąpi zwiększenie powierzchni użytkowej pomieszczeń noclegowych w istniejącej noclegowni lub pomieszczeń mieszkalnych w istniejącym schronisku dla osób bezdomnych, albo powstanie ogrzewalnia, z zastrzeżeniem że w tym samym budynku powstanie również noclegownia lub schronisko dla osób bezdomnych. | B2: A. Budowa budynku na nieruchomości stanowiącej własność albo będącej w użytkowaniu wieczystym gminy, jednoosobowej spółki gminnej, związku międzygminnego, organizacji pozarządowej albo podmiotów, o których mowa w art. 3 ust. 3 ustawy z dnia 24 kwietnia 2003 r. o działalności pożytku publicznego i o wolontariacie: | D2: 1. Noclegownia: | E2: TAK | F2: Gmina | G2: podstawowa jednostka samorządu terytorialnego, o której mowa w art. 1 ust. 2 ustawy z dnia 8 marca 1990 r. o samorządzie gminnym (Dz. U. z 2017 r. poz. 1875 z późn. zm.). | H2: Data rozpoczęcia realizacji przedsięwzięcia (miesiąc słownie i rok) | I2: Data zakończenia realizacji przedsięwzięcia (miesiąc słownie i rok) | O2: Przedsięwzięcie niespełnia standardów, o których mowa w przepisach wydanych na podstawie art. 48a ust. 14 ustawy z dnia 12 marca 2004 r. o pomocy społecznej. | Q2: Informuję, (informacja beneficjenta wsparcia) że posiadam prawo własności lub prawo użytkowania wieczystego gruntu, na którym jest realizowane przedsięwzięcie.
A3: L. Remont lub przebudowa budynku niemieszkalnego przeznaczonego na pobyt ludzi, będącego własnością gminy, jednoosobowej spółki gminnej, związku międzygminnego, organizacji pozarządowej albo podmiotów, o których mowa w art. 3 ust. 3 ustawy z dnia 24 kwietnia 2003 r. o działalności pożytku publicznego i o wolontariacie, albo części takiego budynku (art. 4 ust. 1 pkt 2 i ust. 3 ustawy), w wyniku których powstaną noclegownie, schroniska dla osób bezdomnych lub ogrzewalnia lub nastąpi zwiększenie powierzchni użytkowej pomieszczeń noclegowych w istniejącej noclegowni lub pomieszczeń mieszkalnych w istniejącym schronisku dla osób bezdomnych. | B3: B. Remont lub przebudowa budynku niemieszkalnego przeznaczonego na pobyt ludzi, będącego własnością gminy, jednoosobowej spółki gminnej, związku międzygminnego, organizacji pozarządowej albo podmiotów, o których mowa w art. 3 ust. 3 ustawy z dnia 24 kwietnia 2003 r. o działalności pożytku publicznego i o wolontariacie, albo części takiego budynku – zakres informacji taki jak w lit. A. | E3: NIE | F3: Związek międzygminny | G3: związki międzygminne, o których mowa w art. 64 ustawy z dnia 8 marca 1990 r. o samorządzie gminnym (Dz. U. z 2017 r. poz. 1875 z późn. zm.) Związki międzygminne tworzone są przez gminy w celu wspólnego wykonywania zadań publicznych | H3: Przewidywana data rozpoczęcia realizacji przedsięwzięcia (miesiąc słownie i rok) | I3: Przewidywana data zakończenia realizacji przedsięwzięcia (miesiąc słownie i rok) | Q3: Informuję, że posiadam prawo własności budynku lub części budynku (w tym lokali), w którym realizowane jest przedsięwzięcie.
A4: M. Remont lub przebudowa budynku mieszkalnego będącego własnością gminy lub jednoosobowej spółki gminnej, związku międzygminnego, organizacji pozarządowej albo podmiotów, o których mowa w art. 3 ust. 3 ustawy z dnia 24 kwietnia 2003 r. o działalności pożytku publicznego i o wolontariacie, albo części takiego budynku, jeżeli budynek mieszkalny albo jego część nie są zamieszkane (art. 4 ust. 1 pkt 3 i ust. 3 ustawy), w wyniku których powstaną noclegownie, schroniska dla osób bezdomnych lub ogrzewalnia lub nastąpi zwiększenie powierzchni użytkowej pomieszczeń noclegowych w istniejącej noclegowni lub pomieszczeń mieszkalnych w istniejącym schronisku dla osób bezdomnych. | B4: C. Remont lub przebudowa budynku mieszkalnego, będącego własnością gminy, jednoosobowej spółki gminnej, związku międzygminnego, organizacji pozarządowej albo podmiotów, o których mowa w art. 3 ust. 3 ustawy z dnia 24 kwietnia 2003 r. o działalności pożytku publicznego i o wolontariacie, albo części takiego budynku, jeżeli budynek mieszkalny albo jego część nie są zamieszkane – zakres informacji taki jak w lit. A. | F4: Jednoosobowa spółka gminna | G4: podmiot, któremu przysługuje status organizacji pożytku publicznego w rozumieniu ustawy z dnia 24 kwietnia 2003 r. o działalności pożytku publicznego i o wolontariacie (Dz. U. z 2018 r. poz. 450) | Q4: Informuję, (informacja beneficjenta wsparcia będącego organizacją pozarządową lub podmiotu, o którym mowa w art. 3 ust. 3 ustawy z dnia 24 kwietnia 2003 r. o działalności pożytku publicznego i o wolontariacie) że przedsięwzięcie realizowane jest na nieruchomościach stanowiących własność gminy, jednoosobowej spółki gminnej, związku międzygminnego lub Skarbu Państwa.
